2026-05-11 12:54:45,293 INFO org.apache.hadoop.yarn.server.resourcemanager.ResourceManager: STARTUP_MSG: 
/************************************************************
STARTUP_MSG: Starting ResourceManager
STARTUP_MSG:   host = ubuntu/127.0.1.1
STARTUP_MSG:   args = []
STARTUP_MSG:   version = 3.3.5
STARTUP_MSG:   build = https://github.com/apache/hadoop.git -r 706d88266abcee09ed78fbaa0ad5f74d818ab0e9; compiled by 'stevel' on 2023-03-15T15:56Z
STARTUP_MSG:   java = 1.8.0_371
************************************************************/
2026-05-11 12:54:45,297 INFO org.apache.hadoop.yarn.server.resourcemanager.ResourceManager: registered UNIX signal handlers for [TERM, HUP, INT]
2026-05-11 12:54:45,486 INFO org.apache.hadoop.yarn.server.resourcemanager.RMNMInfo: Registered RMInfo MBean
2026-05-11 12:54:45,491 INFO org.apache.hadoop.conf.Configuration: found resource core-site.xml at file:/usr/local/hadoop/etc/hadoop/core-site.xml
2026-05-11 12:54:45,516 INFO org.apache.hadoop.conf.Configuration: resource-types.xml not found
2026-05-11 12:54:45,516 INFO org.apache.hadoop.yarn.util.resource.ResourceUtils: Unable to find 'resource-types.xml'.
2026-05-11 12:54:45,568 INFO org.apache.hadoop.conf.Configuration: found resource yarn-site.xml at file:/usr/local/hadoop/etc/hadoop/yarn-site.xml
2026-05-11 12:54:45,575 INFO org.apache.hadoop.yarn.metrics.GenericEventTypeMetrics: Registering GenericEventTypeMetrics
2026-05-11 12:54:45,577 INFO org.apache.hadoop.yarn.event.AsyncDispatcher: Registering class org.apache.hadoop.yarn.server.resourcemanager.RMFatalEventType for class org.apache.hadoop.yarn.server.resourcemanager.ResourceManager$RMFatalEventDispatcher
2026-05-11 12:54:45,693 INFO org.apache.hadoop.yarn.server.resourcemanager.security.NMTokenSecretManagerInRM: NMTokenKeyRollingInterval: 86400000ms and NMTokenKeyActivationDelay: 900000ms
2026-05-11 12:54:45,697 INFO org.apache.hadoop.yarn.server.resourcemanager.security.RMContainerTokenSecretManager: ContainerTokenKeyRollingInterval: 86400000ms and ContainerTokenKeyActivationDelay: 900000ms
2026-05-11 12:54:45,700 INFO org.apache.hadoop.yarn.server.resourcemanager.security.AMRMTokenSecretManager: AMRMTokenKeyRollingInterval: 86400000ms and AMRMTokenKeyActivationDelay: 900000 ms
2026-05-11 12:54:45,741 INFO org.apache.hadoop.yarn.event.AsyncDispatcher: Registering class org.apache.hadoop.yarn.server.resourcemanager.recovery.RMStateStoreEventType for class org.apache.hadoop.yarn.server.resourcemanager.recovery.RMStateStore$ForwardingEventHandler
2026-05-11 12:54:45,744 INFO org.apache.hadoop.yarn.event.AsyncDispatcher: Registering class org.apache.hadoop.yarn.server.resourcemanager.NodesListManagerEventType for class org.apache.hadoop.yarn.server.resourcemanager.NodesListManager
2026-05-11 12:54:45,744 INFO org.apache.hadoop.yarn.server.resourcemanager.ResourceManager: Using Scheduler: org.apache.hadoop.yarn.server.resourcemanager.scheduler.capacity.CapacityScheduler
2026-05-11 12:54:45,788 INFO org.apache.hadoop.yarn.event.AsyncDispatcher: Registering class org.apache.hadoop.yarn.server.resourcemanager.scheduler.event.SchedulerEventType for class org.apache.hadoop.yarn.server.resourcemanager.ResourceManager$SchedulerEventDispatcher
2026-05-11 12:54:45,789 INFO org.apache.hadoop.yarn.event.AsyncDispatcher: Registering class org.apache.hadoop.yarn.server.resourcemanager.rmapp.RMAppEventType for class org.apache.hadoop.yarn.server.resourcemanager.ResourceManager$ApplicationEventDispatcher
2026-05-11 12:54:45,790 INFO org.apache.hadoop.yarn.event.AsyncDispatcher: Registering class org.apache.hadoop.yarn.server.resourcemanager.rmapp.attempt.RMAppAttemptEventType for class org.apache.hadoop.yarn.server.resourcemanager.ResourceManager$ApplicationAttemptEventDispatcher
2026-05-11 12:54:45,791 INFO org.apache.hadoop.yarn.event.AsyncDispatcher: Registering class org.apache.hadoop.yarn.server.resourcemanager.rmnode.RMNodeEventType for class org.apache.hadoop.yarn.server.resourcemanager.ResourceManager$NodeEventDispatcher
2026-05-11 12:54:45,828 INFO org.apache.hadoop.metrics2.impl.MetricsConfig: Loaded properties from hadoop-metrics2.properties
2026-05-11 12:54:45,835 INFO org.apache.hadoop.metrics2.impl.MetricsSystemImpl: Scheduled Metric snapshot period at 10 second(s).
2026-05-11 12:54:45,835 INFO org.apache.hadoop.metrics2.impl.MetricsSystemImpl: ResourceManager metrics system started
2026-05-11 12:54:45,850 INFO org.apache.hadoop.yarn.security.YarnAuthorizationProvider: org.apache.hadoop.yarn.security.ConfiguredYarnAuthorizer is instantiated.
2026-05-11 12:54:45,852 INFO org.apache.hadoop.yarn.event.AsyncDispatcher: Registering class org.apache.hadoop.yarn.server.resourcemanager.RMAppManagerEventType for class org.apache.hadoop.yarn.server.resourcemanager.RMAppManager
2026-05-11 12:54:45,856 INFO org.apache.hadoop.yarn.event.AsyncDispatcher: Registering class org.apache.hadoop.yarn.server.resourcemanager.amlauncher.AMLauncherEventType for class org.apache.hadoop.yarn.server.resourcemanager.amlauncher.ApplicationMasterLauncher
2026-05-11 12:54:46,107 INFO org.apache.hadoop.yarn.server.resourcemanager.RMNMInfo: Registered RMNMInfo MBean
2026-05-11 12:54:46,108 INFO org.apache.hadoop.yarn.server.resourcemanager.rmapp.monitor.RMAppLifetimeMonitor: Application lifelime monitor interval set to 3000 ms.
2026-05-11 12:54:46,117 INFO org.apache.hadoop.yarn.server.resourcemanager.scheduler.placement.MultiNodeSortingManager: Initializing NodeSortingService=MultiNodeSortingManager
2026-05-11 12:54:46,118 INFO org.apache.hadoop.util.HostsFileReader: Refreshing hosts (include/exclude) list
2026-05-11 12:54:46,125 INFO org.apache.hadoop.conf.Configuration: found resource capacity-scheduler.xml at file:/usr/local/hadoop/etc/hadoop/capacity-scheduler.xml
2026-05-11 12:54:46,134 INFO org.apache.hadoop.yarn.server.resourcemanager.scheduler.AbstractYarnScheduler: Minimum allocation = <memory:1024, vCores:1>
2026-05-11 12:54:46,134 INFO org.apache.hadoop.yarn.server.resourcemanager.scheduler.AbstractYarnScheduler: Maximum allocation = <memory:8192, vCores:4>
2026-05-11 12:54:46,168 INFO org.apache.hadoop.yarn.server.resourcemanager.scheduler.capacity.ParentQueue: root, capacity=1.0, absoluteCapacity=1.0, maxCapacity=1.0, absoluteMaxCapacity=1.0, state=RUNNING, acls=SUBMIT_APP:*ADMINISTER_QUEUE:*, labels=*,
, reservationsContinueLooking=true, orderingPolicy=utilization, priority=0
2026-05-11 12:54:46,169 INFO org.apache.hadoop.yarn.server.resourcemanager.scheduler.capacity.ParentQueue: Initialized parent-queue root name=root, fullname=root
2026-05-11 12:54:46,181 INFO org.apache.hadoop.yarn.server.resourcemanager.scheduler.capacity.LeafQueue: Initializing root.default
capacity = 1.0 [= (float) configuredCapacity / 100 ]
absoluteCapacity = 1.0 [= parentAbsoluteCapacity * capacity ]
maxCapacity = 1.0 [= configuredMaxCapacity ]
absoluteMaxCapacity = 1.0 [= 1.0 maximumCapacity undefined, (parentAbsoluteMaxCapacity * maximumCapacity) / 100 otherwise ]
effectiveMinResource=<memory:0, vCores:0>
 , effectiveMaxResource=<memory:0, vCores:0>
userLimit = 100 [= configuredUserLimit ]
userLimitFactor = 1.0 [= configuredUserLimitFactor ]
maxApplications = 10000 [= configuredMaximumSystemApplicationsPerQueue or (int)(configuredMaximumSystemApplications * absoluteCapacity)]
maxApplicationsPerUser = 10000 [= (int)(maxApplications * (userLimit / 100.0f) * userLimitFactor) ]
maxParallelApps = 2147483647
usedCapacity = 0.0 [= usedResourcesMemory / (clusterResourceMemory * absoluteCapacity)]
absoluteUsedCapacity = 0.0 [= usedResourcesMemory / clusterResourceMemory]
maxAMResourcePerQueuePercent = 0.1 [= configuredMaximumAMResourcePercent ]
minimumAllocationFactor = 0.875 [= (float)(maximumAllocationMemory - minimumAllocationMemory) / maximumAllocationMemory ]
maximumAllocation = <memory:8192, vCores:4> [= configuredMaxAllocation ]
numContainers = 0 [= currentNumContainers ]
state = RUNNING [= configuredState ]
acls = SUBMIT_APP:*ADMINISTER_QUEUE:* [= configuredAcls ]
nodeLocalityDelay = 40
rackLocalityAdditionalDelay = -1
labels=*,
reservationsContinueLooking = true
preemptionDisabled = true
defaultAppPriorityPerQueue = 0
priority = 0
maxLifetime = -1 seconds
defaultLifetime = -1 seconds
2026-05-11 12:54:46,181 INFO org.apache.hadoop.yarn.server.resourcemanager.scheduler.capacity.CapacitySchedulerQueueManager: Initialized queue: root.default
2026-05-11 12:54:46,181 INFO org.apache.hadoop.yarn.server.resourcemanager.scheduler.capacity.CapacitySchedulerQueueManager: Initialized queue: root
2026-05-11 12:54:46,182 INFO org.apache.hadoop.yarn.server.resourcemanager.scheduler.capacity.CapacitySchedulerQueueManager: Initialized root queue root: numChildQueue= 1, capacity=1.0, absoluteCapacity=1.0, usedResources=<memory:0, vCores:0>usedCapacity=0.0, numApps=0, numContainers=0
2026-05-11 12:54:46,183 INFO org.apache.hadoop.yarn.server.resourcemanager.placement.UserGroupMappingPlacementRule: Initialized queue mappings, override: false
2026-05-11 12:54:46,183 INFO org.apache.hadoop.yarn.server.resourcemanager.scheduler.capacity.WorkflowPriorityMappingsManager: Initialized workflow priority mappings, override: false
2026-05-11 12:54:46,183 INFO org.apache.hadoop.yarn.server.resourcemanager.scheduler.placement.MultiNodeSortingManager: MultiNode scheduling is 'false', and configured policies are 
2026-05-11 12:54:46,183 INFO org.apache.hadoop.yarn.server.resourcemanager.scheduler.capacity.CapacityScheduler: Initialized CapacityScheduler with calculator=class org.apache.hadoop.yarn.util.resource.DefaultResourceCalculator, minimumAllocation=<<memory:1024, vCores:1>>, maximumAllocation=<<memory:8192, vCores:4>>, asynchronousScheduling=false, asyncScheduleInterval=5ms,multiNodePlacementEnabled=false, assignMultipleEnabled=true, maxAssignPerHeartbeat=100, offswitchPerHeartbeatLimit=1
2026-05-11 12:54:46,185 INFO org.apache.hadoop.conf.Configuration: dynamic-resources.xml not found
2026-05-11 12:54:46,187 INFO org.apache.hadoop.yarn.server.resourcemanager.AMSProcessingChain: Initializing AMS Processing chain. Root Processor=[org.apache.hadoop.yarn.server.resourcemanager.DefaultAMSProcessor].
2026-05-11 12:54:46,187 INFO org.apache.hadoop.yarn.server.resourcemanager.ApplicationMasterService: disabled placement handler will be used, all scheduling requests will be rejected.
2026-05-11 12:54:46,188 INFO org.apache.hadoop.yarn.server.resourcemanager.AMSProcessingChain: Adding [org.apache.hadoop.yarn.server.resourcemanager.scheduler.constraint.processor.DisabledPlacementProcessor] tp top of AMS Processing chain. 
2026-05-11 12:54:46,194 INFO org.apache.hadoop.yarn.server.resourcemanager.ResourceManager: TimelineServicePublisher is not configured
2026-05-11 12:54:46,269 INFO org.eclipse.jetty.util.log: Logging initialized @1321ms to org.eclipse.jetty.util.log.Slf4jLog
2026-05-11 12:54:46,327 WARN org.apache.hadoop.security.authentication.server.AuthenticationFilter: Unable to initialize FileSignerSecretProvider, falling back to use random secrets. Reason: Could not read signature secret file: /home/cty1576/hadoop-http-auth-signature-secret
2026-05-11 12:54:46,334 INFO org.apache.hadoop.http.HttpRequestLog: Http request log for http.requests.resourcemanager is not defined
2026-05-11 12:54:46,338 INFO org.apache.hadoop.http.HttpServer2: Added global filter 'safety' (class=org.apache.hadoop.http.HttpServer2$QuotingInputFilter)
2026-05-11 12:54:46,340 INFO org.apache.hadoop.http.HttpServer2: Added filter RMAuthenticationFilter (class=org.apache.hadoop.yarn.server.security.http.RMAuthenticationFilter) to context cluster
2026-05-11 12:54:46,340 INFO org.apache.hadoop.http.HttpServer2: Added filter RMAuthenticationFilter (class=org.apache.hadoop.yarn.server.security.http.RMAuthenticationFilter) to context logs
2026-05-11 12:54:46,340 INFO org.apache.hadoop.http.HttpServer2: Added filter RMAuthenticationFilter (class=org.apache.hadoop.yarn.server.security.http.RMAuthenticationFilter) to context static
2026-05-11 12:54:46,341 INFO org.apache.hadoop.http.HttpServer2: Added filter static_user_filter (class=org.apache.hadoop.http.lib.StaticUserWebFilter$StaticUserFilter) to context cluster
2026-05-11 12:54:46,341 INFO org.apache.hadoop.http.HttpServer2: Added filter static_user_filter (class=org.apache.hadoop.http.lib.StaticUserWebFilter$StaticUserFilter) to context logs
2026-05-11 12:54:46,341 INFO org.apache.hadoop.http.HttpServer2: Added filter static_user_filter (class=org.apache.hadoop.http.lib.StaticUserWebFilter$StaticUserFilter) to context static
2026-05-11 12:54:46,709 INFO org.apache.hadoop.yarn.webapp.WebApps: Registered webapp guice modules
2026-05-11 12:54:46,713 INFO org.apache.hadoop.http.HttpServer2: Jetty bound to port 8088
2026-05-11 12:54:46,713 INFO org.eclipse.jetty.server.Server: jetty-9.4.48.v20220622; built: 2022-06-21T20:42:25.880Z; git: 6b67c5719d1f4371b33655ff2d047d24e171e49a; jvm 1.8.0_371-b11
2026-05-11 12:54:46,730 INFO org.eclipse.jetty.server.session: DefaultSessionIdManager workerName=node0
2026-05-11 12:54:46,730 INFO org.eclipse.jetty.server.session: No SessionScavenger set, using defaults
2026-05-11 12:54:46,731 INFO org.eclipse.jetty.server.session: node0 Scavenging every 660000ms
2026-05-11 12:54:46,742 WARN org.apache.hadoop.security.authentication.server.AuthenticationFilter: Unable to initialize FileSignerSecretProvider, falling back to use random secrets. Reason: Could not read signature secret file: /home/cty1576/hadoop-http-auth-signature-secret
2026-05-11 12:54:46,750 INFO org.apache.hadoop.security.token.delegation.AbstractDelegationTokenSecretManager: Updating the current master key for generating delegation tokens
2026-05-11 12:54:46,751 INFO org.apache.hadoop.security.token.delegation.AbstractDelegationTokenSecretManager: Starting expired delegation token remover thread, tokenRemoverScanInterval=60 min(s)
2026-05-11 12:54:46,752 INFO org.apache.hadoop.security.token.delegation.AbstractDelegationTokenSecretManager: Updating the current master key for generating delegation tokens
2026-05-11 12:54:46,771 INFO org.eclipse.jetty.server.handler.ContextHandler: Started o.e.j.s.ServletContextHandler@14f5da2c{logs,/logs,file:///usr/local/hadoop/logs/,AVAILABLE}
2026-05-11 12:54:46,772 INFO org.eclipse.jetty.server.handler.ContextHandler: Started o.e.j.s.ServletContextHandler@5b057c8c{static,/static,jar:file:/usr/local/hadoop/share/hadoop/yarn/hadoop-yarn-common-3.3.5.jar!/webapps/static,AVAILABLE}
2026-05-11 12:54:47,841 INFO org.eclipse.jetty.server.handler.ContextHandler: Started o.e.j.w.WebAppContext@4364712f{cluster,/,file:///tmp/jetty-0_0_0_0-8088-hadoop-yarn-common-3_3_5_jar-_-any-5352195848829132075/webapp/,AVAILABLE}{jar:file:/usr/local/hadoop/share/hadoop/yarn/hadoop-yarn-common-3.3.5.jar!/webapps/cluster}
2026-05-11 12:54:47,853 INFO org.eclipse.jetty.server.AbstractConnector: Started ServerConnector@5b080f3a{HTTP/1.1, (http/1.1)}{0.0.0.0:8088}
2026-05-11 12:54:47,853 INFO org.eclipse.jetty.server.Server: Started @2905ms
2026-05-11 12:54:47,853 INFO org.apache.hadoop.yarn.webapp.WebApps: Web app cluster started at 8088
2026-05-11 12:54:47,952 INFO org.apache.hadoop.ipc.CallQueueManager: Using callQueue: class java.util.concurrent.LinkedBlockingQueue, queueCapacity: 100, scheduler: class org.apache.hadoop.ipc.DefaultRpcScheduler, ipcBackoff: false.
2026-05-11 12:54:47,965 INFO org.apache.hadoop.ipc.Server: Starting Socket Reader #1 for port 8033
2026-05-11 12:54:48,178 INFO org.apache.hadoop.yarn.factories.impl.pb.RpcServerFactoryPBImpl: Adding protocol org.apache.hadoop.yarn.server.api.ResourceManagerAdministrationProtocolPB to the server
2026-05-11 12:54:48,178 INFO org.apache.hadoop.ipc.Server: IPC Server Responder: starting
2026-05-11 12:54:48,185 INFO org.apache.hadoop.ipc.Server: IPC Server listener on 8033: starting
2026-05-11 12:54:48,187 INFO org.apache.hadoop.yarn.server.resourcemanager.ResourceManager: Transitioning to active state
2026-05-11 12:54:48,211 INFO org.apache.hadoop.yarn.server.resourcemanager.recovery.RMStateStore: Updating AMRMToken
2026-05-11 12:54:48,211 INFO org.apache.hadoop.yarn.server.resourcemanager.security.RMContainerTokenSecretManager: Rolling master-key for container-tokens
2026-05-11 12:54:48,211 INFO org.apache.hadoop.yarn.server.resourcemanager.security.NMTokenSecretManagerInRM: Rolling master-key for nm-tokens
2026-05-11 12:54:48,211 INFO org.apache.hadoop.security.token.delegation.AbstractDelegationTokenSecretManager: Updating the current master key for generating delegation tokens
2026-05-11 12:54:48,211 INFO org.apache.hadoop.yarn.server.resourcemanager.security.RMDelegationTokenSecretManager: storing master key with keyID 1
2026-05-11 12:54:48,211 INFO org.apache.hadoop.yarn.server.resourcemanager.recovery.RMStateStore: Storing RMDTMasterKey.
2026-05-11 12:54:48,212 INFO org.apache.hadoop.security.token.delegation.AbstractDelegationTokenSecretManager: Starting expired delegation token remover thread, tokenRemoverScanInterval=60 min(s)
2026-05-11 12:54:48,212 INFO org.apache.hadoop.security.token.delegation.AbstractDelegationTokenSecretManager: Updating the current master key for generating delegation tokens
2026-05-11 12:54:48,212 INFO org.apache.hadoop.yarn.server.resourcemanager.security.RMDelegationTokenSecretManager: storing master key with keyID 2
2026-05-11 12:54:48,212 INFO org.apache.hadoop.yarn.server.resourcemanager.recovery.RMStateStore: Storing RMDTMasterKey.
2026-05-11 12:54:48,214 INFO org.apache.hadoop.yarn.event.AsyncDispatcher: Registering class org.apache.hadoop.yarn.nodelabels.event.NodeLabelsStoreEventType for class org.apache.hadoop.yarn.nodelabels.CommonNodeLabelsManager$ForwardingEventHandler
2026-05-11 12:54:48,378 INFO org.apache.hadoop.yarn.nodelabels.store.AbstractFSNodeStore: Created store directory :file:/tmp/hadoop-yarn-cty1576/node-attribute
2026-05-11 12:54:48,458 INFO org.apache.hadoop.yarn.nodelabels.store.AbstractFSNodeStore: Finished write mirror at:file:/tmp/hadoop-yarn-cty1576/node-attribute/nodeattribute.mirror
2026-05-11 12:54:48,458 INFO org.apache.hadoop.yarn.nodelabels.store.AbstractFSNodeStore: Finished create editlog file at:file:/tmp/hadoop-yarn-cty1576/node-attribute/nodeattribute.editlog
2026-05-11 12:54:48,477 INFO org.apache.hadoop.yarn.event.AsyncDispatcher: Registering class org.apache.hadoop.yarn.server.resourcemanager.nodelabels.NodeAttributesStoreEventType for class org.apache.hadoop.yarn.server.resourcemanager.nodelabels.NodeAttributesManagerImpl$ForwardingEventHandler
2026-05-11 12:54:48,478 INFO org.apache.hadoop.yarn.server.resourcemanager.scheduler.placement.MultiNodeSortingManager: Starting NodeSortingService=MultiNodeSortingManager
2026-05-11 12:54:48,497 INFO org.apache.hadoop.ipc.CallQueueManager: Using callQueue: class java.util.concurrent.LinkedBlockingQueue, queueCapacity: 5000, scheduler: class org.apache.hadoop.ipc.DefaultRpcScheduler, ipcBackoff: false.
2026-05-11 12:54:48,503 INFO org.apache.hadoop.ipc.Server: Starting Socket Reader #1 for port 8031
2026-05-11 12:54:48,510 INFO org.apache.hadoop.yarn.factories.impl.pb.RpcServerFactoryPBImpl: Adding protocol org.apache.hadoop.yarn.server.api.ResourceTrackerPB to the server
2026-05-11 12:54:48,512 INFO org.apache.hadoop.ipc.Server: IPC Server Responder: starting
2026-05-11 12:54:48,512 INFO org.apache.hadoop.ipc.Server: IPC Server listener on 8031: starting
2026-05-11 12:54:48,572 INFO org.apache.hadoop.util.JvmPauseMonitor: Starting JVM pause monitor
2026-05-11 12:54:48,618 INFO org.apache.hadoop.ipc.CallQueueManager: Using callQueue: class java.util.concurrent.LinkedBlockingQueue, queueCapacity: 5000, scheduler: class org.apache.hadoop.ipc.DefaultRpcScheduler, ipcBackoff: false.
2026-05-11 12:54:48,634 INFO org.apache.hadoop.ipc.Server: Starting Socket Reader #1 for port 8030
2026-05-11 12:54:48,643 INFO org.apache.hadoop.yarn.factories.impl.pb.RpcServerFactoryPBImpl: Adding protocol org.apache.hadoop.yarn.api.ApplicationMasterProtocolPB to the server
2026-05-11 12:54:48,644 INFO org.apache.hadoop.ipc.Server: IPC Server Responder: starting
2026-05-11 12:54:48,645 INFO org.apache.hadoop.ipc.Server: IPC Server listener on 8030: starting
2026-05-11 12:54:48,777 INFO org.apache.hadoop.ipc.CallQueueManager: Using callQueue: class java.util.concurrent.LinkedBlockingQueue, queueCapacity: 5000, scheduler: class org.apache.hadoop.ipc.DefaultRpcScheduler, ipcBackoff: false.
2026-05-11 12:54:48,780 INFO org.apache.hadoop.ipc.Server: Starting Socket Reader #1 for port 8032
2026-05-11 12:54:48,792 INFO org.apache.hadoop.yarn.factories.impl.pb.RpcServerFactoryPBImpl: Adding protocol org.apache.hadoop.yarn.api.ApplicationClientProtocolPB to the server
2026-05-11 12:54:48,792 INFO org.apache.hadoop.ipc.Server: IPC Server Responder: starting
2026-05-11 12:54:48,793 INFO org.apache.hadoop.ipc.Server: IPC Server listener on 8032: starting
2026-05-11 12:54:49,456 INFO org.apache.hadoop.yarn.server.webproxy.ProxyCA: Created Certificate for OU=YARN-afff28ad-3ecf-460f-881c-704cd76963a8
2026-05-11 12:54:49,656 INFO org.apache.hadoop.yarn.server.resourcemanager.recovery.RMStateStore: Storing CA Certificate and Private Key
2026-05-11 12:54:49,659 INFO org.apache.hadoop.yarn.server.resourcemanager.ResourceManager: Transitioned to active state
2026-05-11 12:54:52,423 INFO org.apache.hadoop.yarn.server.resourcemanager.ResourceTrackerService: NodeManager from node ubuntu(cmPort: 45565 httpPort: 8042) registered with capability: <memory:8192, vCores:8>, assigned nodeId ubuntu:45565
2026-05-11 12:54:52,425 INFO org.apache.hadoop.yarn.server.resourcemanager.rmnode.RMNodeImpl: ubuntu:45565 Node Transitioned from NEW to RUNNING
2026-05-11 12:54:52,458 INFO org.apache.hadoop.yarn.server.resourcemanager.scheduler.capacity.CapacityScheduler: Added node ubuntu:45565 clusterResource: <memory:8192, vCores:8>
2026-05-11 13:04:48,486 INFO org.apache.hadoop.yarn.server.resourcemanager.scheduler.AbstractYarnScheduler: Release request cache is cleaned up
2026-05-11 13:42:18,484 INFO org.apache.hadoop.yarn.server.resourcemanager.ClientRMService: Allocated new applicationId: 1
2026-05-11 13:42:20,150 INFO org.apache.hadoop.yarn.server.resourcemanager.scheduler.capacity.CapacityScheduler: Application 'application_1778475288188_0001' is submitted without priority hence considering default queue/cluster priority: 0
2026-05-11 13:42:20,150 INFO org.apache.hadoop.yarn.server.resourcemanager.scheduler.capacity.CapacityScheduler: Priority '0' is acceptable in queue : default for application: application_1778475288188_0001
2026-05-11 13:42:20,246 INFO org.apache.hadoop.yarn.server.resourcemanager.ClientRMService: Application with id 1 submitted by user cty1576
2026-05-11 13:42:20,250 INFO org.apache.hadoop.yarn.server.resourcemanager.rmapp.RMAppImpl: Storing application with id application_1778475288188_0001
2026-05-11 13:42:20,283 INFO org.apache.hadoop.yarn.server.resourcemanager.rmapp.RMAppImpl: application_1778475288188_0001 State change from NEW to NEW_SAVING on event = START
2026-05-11 13:42:20,285 INFO org.apache.hadoop.yarn.server.resourcemanager.recovery.RMStateStore: Storing info for app: application_1778475288188_0001
2026-05-11 13:42:20,354 INFO org.apache.hadoop.yarn.server.resourcemanager.rmapp.RMAppImpl: application_1778475288188_0001 State change from NEW_SAVING to SUBMITTED on event = APP_NEW_SAVED
2026-05-11 13:42:20,366 INFO org.apache.hadoop.yarn.server.resourcemanager.scheduler.capacity.ParentQueue: Application added - appId: application_1778475288188_0001 user: cty1576 leaf-queue of parent: root #applications: 1
2026-05-11 13:42:20,369 INFO org.apache.hadoop.yarn.server.resourcemanager.scheduler.capacity.CapacityScheduler: Accepted application application_1778475288188_0001 from user: cty1576, in queue: default
2026-05-11 13:42:20,399 INFO org.apache.hadoop.yarn.server.resourcemanager.rmapp.RMAppImpl: application_1778475288188_0001 State change from SUBMITTED to ACCEPTED on event = APP_ACCEPTED
2026-05-11 13:42:20,460 INFO org.apache.hadoop.yarn.server.resourcemanager.ApplicationMasterService: Registering app attempt : appattempt_1778475288188_0001_000001
2026-05-11 13:42:20,464 INFO org.apache.hadoop.yarn.server.resourcemanager.rmapp.attempt.RMAppAttemptImpl: appattempt_1778475288188_0001_000001 State change from NEW to SUBMITTED on event = START
2026-05-11 13:42:20,637 WARN org.apache.hadoop.yarn.server.resourcemanager.scheduler.capacity.LeafQueue: maximum-am-resource-percent is insufficient to start a single application in queue, it is likely set too low. skipping enforcement to allow at least one application to start
2026-05-11 13:42:20,637 WARN org.apache.hadoop.yarn.server.resourcemanager.scheduler.capacity.LeafQueue: maximum-am-resource-percent is insufficient to start a single application in queue for user, it is likely set too low. skipping enforcement to allow at least one application to start
2026-05-11 13:42:20,646 INFO org.apache.hadoop.yarn.server.resourcemanager.scheduler.capacity.LeafQueue: Application application_1778475288188_0001 from user: cty1576 activated in queue: root.default
2026-05-11 13:42:20,646 INFO org.apache.hadoop.yarn.server.resourcemanager.scheduler.capacity.LeafQueue: Application added - appId: application_1778475288188_0001 user: cty1576, leaf-queue: root.default #user-pending-applications: 0 #user-active-applications: 1 #queue-pending-applications: 0 #queue-active-applications: 1 #queue-nonrunnable-applications: 0
2026-05-11 13:42:20,646 INFO org.apache.hadoop.yarn.server.resourcemanager.scheduler.capacity.CapacityScheduler: Added Application Attempt appattempt_1778475288188_0001_000001 to scheduler from user cty1576 in queue root.default
2026-05-11 13:42:20,675 INFO org.apache.hadoop.yarn.server.resourcemanager.rmapp.attempt.RMAppAttemptImpl: appattempt_1778475288188_0001_000001 State change from SUBMITTED to SCHEDULED on event = ATTEMPT_ADDED
2026-05-11 13:42:21,219 INFO org.apache.hadoop.yarn.server.resourcemanager.scheduler.capacity.allocator.AbstractContainerAllocator: assignedContainer application attempt=appattempt_1778475288188_0001_000001 container=null queue=default clusterResource=<memory:8192, vCores:8> type=OFF_SWITCH requestedPartition=
2026-05-11 13:42:21,275 INFO org.apache.hadoop.yarn.server.resourcemanager.rmcontainer.RMContainerImpl: container_1778475288188_0001_01_000001 Container Transitioned from NEW to ALLOCATED
2026-05-11 13:42:21,286 INFO org.apache.hadoop.yarn.server.resourcemanager.scheduler.common.fica.FiCaSchedulerNode: Assigned container container_1778475288188_0001_01_000001 of capacity <memory:2048, vCores:1> on host ubuntu:45565, which has 1 containers, <memory:2048, vCores:1> used and <memory:6144, vCores:7> available after allocation
2026-05-11 13:42:21,287 INFO org.apache.hadoop.yarn.server.resourcemanager.scheduler.capacity.ParentQueue: assignedContainer queue=root usedCapacity=0.25 absoluteUsedCapacity=0.25 used=<memory:2048, vCores:1> cluster=<memory:8192, vCores:8>
2026-05-11 13:42:21,383 INFO org.apache.hadoop.yarn.server.resourcemanager.rmcontainer.RMContainerImpl: container_1778475288188_0001_01_000001 Container Transitioned from ALLOCATED to ACQUIRED
2026-05-11 13:42:21,384 INFO org.apache.hadoop.yarn.server.resourcemanager.security.NMTokenSecretManagerInRM: Clear node set for appattempt_1778475288188_0001_000001
2026-05-11 13:42:21,385 INFO org.apache.hadoop.yarn.server.resourcemanager.rmapp.attempt.RMAppAttemptImpl: Storing attempt: AppId: application_1778475288188_0001 AttemptId: appattempt_1778475288188_0001_000001 MasterContainer: Container: [ContainerId: container_1778475288188_0001_01_000001, AllocationRequestId: -1, Version: 0, NodeId: ubuntu:45565, NodeHttpAddress: ubuntu:8042, Resource: <memory:2048, vCores:1>, Priority: 0, Token: Token { kind: ContainerToken, service: 127.0.1.1:45565 }, ExecutionType: GUARANTEED, ]
2026-05-11 13:42:21,416 INFO org.apache.hadoop.yarn.server.resourcemanager.rmapp.attempt.RMAppAttemptImpl: appattempt_1778475288188_0001_000001 State change from SCHEDULED to ALLOCATED_SAVING on event = CONTAINER_ALLOCATED
2026-05-11 13:42:21,433 INFO org.apache.hadoop.yarn.server.resourcemanager.rmapp.attempt.RMAppAttemptImpl: appattempt_1778475288188_0001_000001 State change from ALLOCATED_SAVING to ALLOCATED on event = ATTEMPT_NEW_SAVED
2026-05-11 13:42:21,489 INFO org.apache.hadoop.yarn.server.resourcemanager.amlauncher.AMLauncher: Launching masterappattempt_1778475288188_0001_000001
2026-05-11 13:42:21,682 INFO org.apache.hadoop.yarn.server.resourcemanager.amlauncher.AMLauncher: Setting up container Container: [ContainerId: container_1778475288188_0001_01_000001, AllocationRequestId: -1, Version: 0, NodeId: ubuntu:45565, NodeHttpAddress: ubuntu:8042, Resource: <memory:2048, vCores:1>, Priority: 0, Token: Token { kind: ContainerToken, service: 127.0.1.1:45565 }, ExecutionType: GUARANTEED, ] for AM appattempt_1778475288188_0001_000001
2026-05-11 13:42:21,684 INFO org.apache.hadoop.yarn.server.resourcemanager.security.AMRMTokenSecretManager: Create AMRMToken for ApplicationAttempt: appattempt_1778475288188_0001_000001
2026-05-11 13:42:21,691 INFO org.apache.hadoop.yarn.server.resourcemanager.security.AMRMTokenSecretManager: Creating password for appattempt_1778475288188_0001_000001
2026-05-11 13:42:22,355 INFO org.apache.hadoop.yarn.server.resourcemanager.amlauncher.AMLauncher: Done launching container Container: [ContainerId: container_1778475288188_0001_01_000001, AllocationRequestId: -1, Version: 0, NodeId: ubuntu:45565, NodeHttpAddress: ubuntu:8042, Resource: <memory:2048, vCores:1>, Priority: 0, Token: Token { kind: ContainerToken, service: 127.0.1.1:45565 }, ExecutionType: GUARANTEED, ] for AM appattempt_1778475288188_0001_000001
2026-05-11 13:42:22,356 INFO org.apache.hadoop.yarn.server.resourcemanager.rmapp.attempt.RMAppAttemptImpl: appattempt_1778475288188_0001_000001 State change from ALLOCATED to LAUNCHED on event = LAUNCHED
2026-05-11 13:42:22,356 INFO org.apache.hadoop.yarn.server.resourcemanager.rmapp.RMAppImpl: update the launch time for applicationId: application_1778475288188_0001, attemptId: appattempt_1778475288188_0001_000001launchTime: 1778478142355
2026-05-11 13:42:22,359 INFO org.apache.hadoop.yarn.server.resourcemanager.recovery.RMStateStore: Updating info for app: application_1778475288188_0001
2026-05-11 13:42:23,143 INFO org.apache.hadoop.yarn.server.resourcemanager.rmcontainer.RMContainerImpl: container_1778475288188_0001_01_000001 Container Transitioned from ACQUIRED to RUNNING
2026-05-11 13:42:28,740 INFO SecurityLogger.org.apache.hadoop.ipc.Server: Auth successful for appattempt_1778475288188_0001_000001 (auth:SIMPLE) from 127.0.0.1:37584
2026-05-11 13:42:28,833 INFO org.apache.hadoop.yarn.server.resourcemanager.DefaultAMSProcessor: AM registration appattempt_1778475288188_0001_000001
2026-05-11 13:42:28,835 INFO org.apache.hadoop.yarn.server.resourcemanager.rmapp.attempt.RMAppAttemptImpl: appattempt_1778475288188_0001_000001 State change from LAUNCHED to RUNNING on event = REGISTERED
2026-05-11 13:42:28,837 INFO org.apache.hadoop.yarn.server.resourcemanager.rmapp.RMAppImpl: application_1778475288188_0001 State change from ACCEPTED to RUNNING on event = ATTEMPT_REGISTERED
2026-05-11 13:42:30,172 INFO org.apache.hadoop.yarn.server.resourcemanager.scheduler.capacity.allocator.AbstractContainerAllocator: assignedContainer application attempt=appattempt_1778475288188_0001_000001 container=null queue=default clusterResource=<memory:8192, vCores:8> type=NODE_LOCAL requestedPartition=
2026-05-11 13:42:30,172 INFO org.apache.hadoop.yarn.server.resourcemanager.rmcontainer.RMContainerImpl: container_1778475288188_0001_01_000002 Container Transitioned from NEW to ALLOCATED
2026-05-11 13:42:30,172 INFO org.apache.hadoop.yarn.server.resourcemanager.scheduler.common.fica.FiCaSchedulerNode: Assigned container container_1778475288188_0001_01_000002 of capacity <memory:1024, vCores:1> on host ubuntu:45565, which has 2 containers, <memory:3072, vCores:2> used and <memory:5120, vCores:6> available after allocation
2026-05-11 13:42:30,172 INFO org.apache.hadoop.yarn.server.resourcemanager.scheduler.capacity.ParentQueue: assignedContainer queue=root usedCapacity=0.375 absoluteUsedCapacity=0.375 used=<memory:3072, vCores:2> cluster=<memory:8192, vCores:8>
2026-05-11 13:42:30,173 INFO org.apache.hadoop.yarn.server.resourcemanager.scheduler.capacity.allocator.AbstractContainerAllocator: assignedContainer application attempt=appattempt_1778475288188_0001_000001 container=null queue=default clusterResource=<memory:8192, vCores:8> type=OFF_SWITCH requestedPartition=
2026-05-11 13:42:30,173 INFO org.apache.hadoop.yarn.server.resourcemanager.rmcontainer.RMContainerImpl: container_1778475288188_0001_01_000003 Container Transitioned from NEW to ALLOCATED
2026-05-11 13:42:30,173 INFO org.apache.hadoop.yarn.server.resourcemanager.scheduler.common.fica.FiCaSchedulerNode: Assigned container container_1778475288188_0001_01_000003 of capacity <memory:1024, vCores:1> on host ubuntu:45565, which has 3 containers, <memory:4096, vCores:3> used and <memory:4096, vCores:5> available after allocation
2026-05-11 13:42:30,173 INFO org.apache.hadoop.yarn.server.resourcemanager.scheduler.capacity.ParentQueue: assignedContainer queue=root usedCapacity=0.5 absoluteUsedCapacity=0.5 used=<memory:4096, vCores:3> cluster=<memory:8192, vCores:8>
2026-05-11 13:42:31,021 INFO org.apache.hadoop.yarn.server.resourcemanager.rmcontainer.RMContainerImpl: container_1778475288188_0001_01_000002 Container Transitioned from ALLOCATED to ACQUIRED
2026-05-11 13:42:31,022 INFO org.apache.hadoop.yarn.server.resourcemanager.rmcontainer.RMContainerImpl: container_1778475288188_0001_01_000003 Container Transitioned from ALLOCATED to ACQUIRED
2026-05-11 13:42:32,045 INFO org.apache.hadoop.yarn.server.resourcemanager.scheduler.AppSchedulingInfo: checking for deactivate of application :application_1778475288188_0001
2026-05-11 13:42:32,183 INFO org.apache.hadoop.yarn.server.resourcemanager.rmcontainer.RMContainerImpl: container_1778475288188_0001_01_000002 Container Transitioned from ACQUIRED to RUNNING
2026-05-11 13:42:32,183 INFO org.apache.hadoop.yarn.server.resourcemanager.rmcontainer.RMContainerImpl: container_1778475288188_0001_01_000003 Container Transitioned from ACQUIRED to RUNNING
2026-05-11 13:42:38,149 INFO org.apache.hadoop.yarn.server.resourcemanager.rmcontainer.RMContainerImpl: container_1778475288188_0001_01_000003 Container Transitioned from RUNNING to COMPLETED
2026-05-11 13:42:38,910 INFO org.apache.hadoop.yarn.server.resourcemanager.rmcontainer.RMContainerImpl: container_1778475288188_0001_01_000002 Container Transitioned from RUNNING to COMPLETED
2026-05-11 13:42:39,917 INFO org.apache.hadoop.yarn.server.resourcemanager.scheduler.capacity.allocator.AbstractContainerAllocator: assignedContainer application attempt=appattempt_1778475288188_0001_000001 container=null queue=default clusterResource=<memory:8192, vCores:8> type=OFF_SWITCH requestedPartition=
2026-05-11 13:42:39,917 INFO org.apache.hadoop.yarn.server.resourcemanager.rmcontainer.RMContainerImpl: container_1778475288188_0001_01_000004 Container Transitioned from NEW to ALLOCATED
2026-05-11 13:42:39,917 INFO org.apache.hadoop.yarn.server.resourcemanager.scheduler.common.fica.FiCaSchedulerNode: Assigned container container_1778475288188_0001_01_000004 of capacity <memory:1024, vCores:1> on host ubuntu:45565, which has 2 containers, <memory:3072, vCores:2> used and <memory:5120, vCores:6> available after allocation
2026-05-11 13:42:39,918 INFO org.apache.hadoop.yarn.server.resourcemanager.scheduler.capacity.ParentQueue: assignedContainer queue=root usedCapacity=0.375 absoluteUsedCapacity=0.375 used=<memory:3072, vCores:2> cluster=<memory:8192, vCores:8>
2026-05-11 13:42:40,124 INFO org.apache.hadoop.yarn.server.resourcemanager.rmcontainer.RMContainerImpl: container_1778475288188_0001_01_000004 Container Transitioned from ALLOCATED to ACQUIRED
2026-05-11 13:42:40,920 INFO org.apache.hadoop.yarn.server.resourcemanager.rmcontainer.RMContainerImpl: container_1778475288188_0001_01_000004 Container Transitioned from ACQUIRED to RUNNING
2026-05-11 13:42:41,136 INFO org.apache.hadoop.yarn.server.resourcemanager.scheduler.AppSchedulingInfo: checking for deactivate of application :application_1778475288188_0001
2026-05-11 13:42:43,166 INFO org.apache.hadoop.yarn.server.resourcemanager.rmcontainer.RMContainerImpl: container_1778475288188_0001_01_000004 Container Transitioned from RUNNING to COMPLETED
2026-05-11 13:42:43,360 INFO org.apache.hadoop.yarn.server.resourcemanager.rmapp.attempt.RMAppAttemptImpl: Updating application attempt appattempt_1778475288188_0001_000001 with final state: FINISHING, and exit status: -1000
2026-05-11 13:42:43,362 INFO org.apache.hadoop.yarn.server.resourcemanager.rmapp.attempt.RMAppAttemptImpl: appattempt_1778475288188_0001_000001 State change from RUNNING to FINAL_SAVING on event = UNREGISTERED
2026-05-11 13:42:43,362 INFO org.apache.hadoop.yarn.server.resourcemanager.rmapp.RMAppImpl: Updating application application_1778475288188_0001 with final state: FINISHING
2026-05-11 13:42:43,363 INFO org.apache.hadoop.yarn.server.resourcemanager.rmapp.RMAppImpl: application_1778475288188_0001 State change from RUNNING to FINAL_SAVING on event = ATTEMPT_UNREGISTERED
2026-05-11 13:42:43,364 INFO org.apache.hadoop.yarn.server.resourcemanager.rmapp.attempt.RMAppAttemptImpl: appattempt_1778475288188_0001_000001 State change from FINAL_SAVING to FINISHING on event = ATTEMPT_UPDATE_SAVED
2026-05-11 13:42:43,364 INFO org.apache.hadoop.yarn.server.resourcemanager.recovery.RMStateStore: Updating info for app: application_1778475288188_0001
2026-05-11 13:42:43,364 INFO org.apache.hadoop.yarn.server.resourcemanager.rmapp.RMAppImpl: application_1778475288188_0001 State change from FINAL_SAVING to FINISHING on event = APP_UPDATE_SAVED
2026-05-11 13:42:44,361 INFO org.apache.hadoop.yarn.server.resourcemanager.ApplicationMasterService: application_1778475288188_0001 unregistered successfully. 
2026-05-11 13:42:49,801 INFO org.apache.hadoop.yarn.server.resourcemanager.rmcontainer.RMContainerImpl: container_1778475288188_0001_01_000001 Container Transitioned from RUNNING to COMPLETED
2026-05-11 13:42:49,801 INFO org.apache.hadoop.yarn.server.resourcemanager.ApplicationMasterService: Unregistering app attempt : appattempt_1778475288188_0001_000001
2026-05-11 13:42:49,806 INFO org.apache.hadoop.yarn.server.resourcemanager.security.AMRMTokenSecretManager: Application finished, removing password for appattempt_1778475288188_0001_000001
2026-05-11 13:42:49,818 INFO org.apache.hadoop.yarn.server.resourcemanager.rmapp.attempt.RMAppAttemptImpl: appattempt_1778475288188_0001_000001 State change from FINISHING to FINISHED on event = CONTAINER_FINISHED
2026-05-11 13:42:49,823 INFO org.apache.hadoop.yarn.server.resourcemanager.rmapp.RMAppImpl: application_1778475288188_0001 State change from FINISHING to FINISHED on event = ATTEMPT_FINISHED
2026-05-11 13:42:49,824 INFO org.apache.hadoop.yarn.server.resourcemanager.scheduler.capacity.CapacityScheduler: Application Attempt appattempt_1778475288188_0001_000001 is done. finalState=FINISHED
2026-05-11 13:42:49,824 INFO org.apache.hadoop.yarn.server.resourcemanager.scheduler.AppSchedulingInfo: Application application_1778475288188_0001 requests cleared
2026-05-11 13:42:49,824 INFO org.apache.hadoop.yarn.server.resourcemanager.scheduler.capacity.LeafQueue: Application removed - appId: application_1778475288188_0001 user: cty1576 queue: root.default #user-pending-applications: 0 #user-active-applications: 0 #queue-pending-applications: 0 #queue-active-applications: 0
2026-05-11 13:42:49,830 INFO org.apache.hadoop.yarn.server.resourcemanager.amlauncher.AMLauncher: Cleaning master appattempt_1778475288188_0001_000001
2026-05-11 13:42:49,836 INFO org.apache.hadoop.yarn.server.resourcemanager.scheduler.capacity.ParentQueue: Application removed - appId: application_1778475288188_0001 user: cty1576 leaf-queue of parent: root #applications: 0
2026-05-11 13:42:49,841 INFO org.apache.hadoop.yarn.server.resourcemanager.RMAppManager$ApplicationSummary: appId=application_1778475288188_0001,name=SELECT COUNT(*) AS total...ods.user_behavior (Stage-1),user=cty1576,queue=default,state=FINISHED,trackingUrl=http://ubuntu:8088/proxy/application_1778475288188_0001/,appMasterHost=ubuntu,submitTime=1778478139933,startTime=1778478140241,launchTime=1778478142355,finishTime=1778478163362,finalStatus=SUCCEEDED,memorySeconds=78983,vcoreSeconds=46,preemptedMemorySeconds=0,preemptedVcoreSeconds=0,preemptedAMContainers=0,preemptedNonAMContainers=0,preemptedResources=<memory:0\, vCores:0>,applicationType=MAPREDUCE,resourceSeconds=78983 MB-seconds\, 46 vcore-seconds,preemptedResourceSeconds=0 MB-seconds\, 0 vcore-seconds,applicationTags=,applicationNodeLabel=,diagnostics=,totalAllocatedContainers=4
2026-05-11 13:42:52,020 INFO org.apache.hadoop.yarn.server.resourcemanager.ClientRMService: Allocated new applicationId: 2
2026-05-11 13:42:53,427 INFO org.apache.hadoop.yarn.server.resourcemanager.scheduler.capacity.CapacityScheduler: Application 'application_1778475288188_0002' is submitted without priority hence considering default queue/cluster priority: 0
2026-05-11 13:42:53,427 INFO org.apache.hadoop.yarn.server.resourcemanager.scheduler.capacity.CapacityScheduler: Priority '0' is acceptable in queue : default for application: application_1778475288188_0002
2026-05-11 13:42:53,427 INFO org.apache.hadoop.yarn.server.resourcemanager.ClientRMService: Application with id 2 submitted by user cty1576
2026-05-11 13:42:53,429 INFO org.apache.hadoop.yarn.server.resourcemanager.rmapp.RMAppImpl: Storing application with id application_1778475288188_0002
2026-05-11 13:42:53,429 INFO org.apache.hadoop.yarn.server.resourcemanager.rmapp.RMAppImpl: application_1778475288188_0002 State change from NEW to NEW_SAVING on event = START
2026-05-11 13:42:53,429 INFO org.apache.hadoop.yarn.server.resourcemanager.recovery.RMStateStore: Storing info for app: application_1778475288188_0002
2026-05-11 13:42:53,430 INFO org.apache.hadoop.yarn.server.resourcemanager.rmapp.RMAppImpl: application_1778475288188_0002 State change from NEW_SAVING to SUBMITTED on event = APP_NEW_SAVED
2026-05-11 13:42:53,430 INFO org.apache.hadoop.yarn.server.resourcemanager.scheduler.capacity.ParentQueue: Application added - appId: application_1778475288188_0002 user: cty1576 leaf-queue of parent: root #applications: 1
2026-05-11 13:42:53,430 INFO org.apache.hadoop.yarn.server.resourcemanager.scheduler.capacity.CapacityScheduler: Accepted application application_1778475288188_0002 from user: cty1576, in queue: default
2026-05-11 13:42:53,431 INFO org.apache.hadoop.yarn.server.resourcemanager.rmapp.RMAppImpl: application_1778475288188_0002 State change from SUBMITTED to ACCEPTED on event = APP_ACCEPTED
2026-05-11 13:42:53,433 INFO org.apache.hadoop.yarn.server.resourcemanager.ApplicationMasterService: Registering app attempt : appattempt_1778475288188_0002_000001
2026-05-11 13:42:53,433 INFO org.apache.hadoop.yarn.server.resourcemanager.rmapp.attempt.RMAppAttemptImpl: appattempt_1778475288188_0002_000001 State change from NEW to SUBMITTED on event = START
2026-05-11 13:42:53,433 WARN org.apache.hadoop.yarn.server.resourcemanager.scheduler.capacity.LeafQueue: maximum-am-resource-percent is insufficient to start a single application in queue, it is likely set too low. skipping enforcement to allow at least one application to start
2026-05-11 13:42:53,433 WARN org.apache.hadoop.yarn.server.resourcemanager.scheduler.capacity.LeafQueue: maximum-am-resource-percent is insufficient to start a single application in queue for user, it is likely set too low. skipping enforcement to allow at least one application to start
2026-05-11 13:42:53,433 INFO org.apache.hadoop.yarn.server.resourcemanager.scheduler.capacity.LeafQueue: Application application_1778475288188_0002 from user: cty1576 activated in queue: root.default
2026-05-11 13:42:53,433 INFO org.apache.hadoop.yarn.server.resourcemanager.scheduler.capacity.LeafQueue: Application added - appId: application_1778475288188_0002 user: cty1576, leaf-queue: root.default #user-pending-applications: 0 #user-active-applications: 1 #queue-pending-applications: 0 #queue-active-applications: 1 #queue-nonrunnable-applications: 0
2026-05-11 13:42:53,433 INFO org.apache.hadoop.yarn.server.resourcemanager.scheduler.capacity.CapacityScheduler: Added Application Attempt appattempt_1778475288188_0002_000001 to scheduler from user cty1576 in queue root.default
2026-05-11 13:42:53,435 INFO org.apache.hadoop.yarn.server.resourcemanager.rmapp.attempt.RMAppAttemptImpl: appattempt_1778475288188_0002_000001 State change from SUBMITTED to SCHEDULED on event = ATTEMPT_ADDED
2026-05-11 13:42:53,813 INFO org.apache.hadoop.yarn.server.resourcemanager.scheduler.capacity.allocator.AbstractContainerAllocator: assignedContainer application attempt=appattempt_1778475288188_0002_000001 container=null queue=default clusterResource=<memory:8192, vCores:8> type=OFF_SWITCH requestedPartition=
2026-05-11 13:42:53,815 INFO org.apache.hadoop.yarn.server.resourcemanager.rmcontainer.RMContainerImpl: container_1778475288188_0002_01_000001 Container Transitioned from NEW to ALLOCATED
2026-05-11 13:42:53,815 INFO org.apache.hadoop.yarn.server.resourcemanager.scheduler.common.fica.FiCaSchedulerNode: Assigned container container_1778475288188_0002_01_000001 of capacity <memory:2048, vCores:1> on host ubuntu:45565, which has 1 containers, <memory:2048, vCores:1> used and <memory:6144, vCores:7> available after allocation
2026-05-11 13:42:53,816 INFO org.apache.hadoop.yarn.server.resourcemanager.scheduler.capacity.ParentQueue: assignedContainer queue=root usedCapacity=0.25 absoluteUsedCapacity=0.25 used=<memory:2048, vCores:1> cluster=<memory:8192, vCores:8>
2026-05-11 13:42:53,820 INFO org.apache.hadoop.yarn.server.resourcemanager.rmcontainer.RMContainerImpl: container_1778475288188_0002_01_000001 Container Transitioned from ALLOCATED to ACQUIRED
2026-05-11 13:42:53,820 INFO org.apache.hadoop.yarn.server.resourcemanager.security.NMTokenSecretManagerInRM: Clear node set for appattempt_1778475288188_0002_000001
2026-05-11 13:42:53,820 INFO org.apache.hadoop.yarn.server.resourcemanager.rmapp.attempt.RMAppAttemptImpl: Storing attempt: AppId: application_1778475288188_0002 AttemptId: appattempt_1778475288188_0002_000001 MasterContainer: Container: [ContainerId: container_1778475288188_0002_01_000001, AllocationRequestId: -1, Version: 0, NodeId: ubuntu:45565, NodeHttpAddress: ubuntu:8042, Resource: <memory:2048, vCores:1>, Priority: 0, Token: Token { kind: ContainerToken, service: 127.0.1.1:45565 }, ExecutionType: GUARANTEED, ]
2026-05-11 13:42:53,821 INFO org.apache.hadoop.yarn.server.resourcemanager.rmapp.attempt.RMAppAttemptImpl: appattempt_1778475288188_0002_000001 State change from SCHEDULED to ALLOCATED_SAVING on event = CONTAINER_ALLOCATED
2026-05-11 13:42:53,821 INFO org.apache.hadoop.yarn.server.resourcemanager.rmapp.attempt.RMAppAttemptImpl: appattempt_1778475288188_0002_000001 State change from ALLOCATED_SAVING to ALLOCATED on event = ATTEMPT_NEW_SAVED
2026-05-11 13:42:53,822 INFO org.apache.hadoop.yarn.server.resourcemanager.amlauncher.AMLauncher: Launching masterappattempt_1778475288188_0002_000001
2026-05-11 13:42:53,825 INFO org.apache.hadoop.yarn.server.resourcemanager.amlauncher.AMLauncher: Setting up container Container: [ContainerId: container_1778475288188_0002_01_000001, AllocationRequestId: -1, Version: 0, NodeId: ubuntu:45565, NodeHttpAddress: ubuntu:8042, Resource: <memory:2048, vCores:1>, Priority: 0, Token: Token { kind: ContainerToken, service: 127.0.1.1:45565 }, ExecutionType: GUARANTEED, ] for AM appattempt_1778475288188_0002_000001
2026-05-11 13:42:53,825 INFO org.apache.hadoop.yarn.server.resourcemanager.security.AMRMTokenSecretManager: Create AMRMToken for ApplicationAttempt: appattempt_1778475288188_0002_000001
2026-05-11 13:42:53,825 INFO org.apache.hadoop.yarn.server.resourcemanager.security.AMRMTokenSecretManager: Creating password for appattempt_1778475288188_0002_000001
2026-05-11 13:42:53,840 INFO org.apache.hadoop.yarn.server.resourcemanager.amlauncher.AMLauncher: Done launching container Container: [ContainerId: container_1778475288188_0002_01_000001, AllocationRequestId: -1, Version: 0, NodeId: ubuntu:45565, NodeHttpAddress: ubuntu:8042, Resource: <memory:2048, vCores:1>, Priority: 0, Token: Token { kind: ContainerToken, service: 127.0.1.1:45565 }, ExecutionType: GUARANTEED, ] for AM appattempt_1778475288188_0002_000001
2026-05-11 13:42:53,840 INFO org.apache.hadoop.yarn.server.resourcemanager.rmapp.attempt.RMAppAttemptImpl: appattempt_1778475288188_0002_000001 State change from ALLOCATED to LAUNCHED on event = LAUNCHED
2026-05-11 13:42:53,840 INFO org.apache.hadoop.yarn.server.resourcemanager.rmapp.RMAppImpl: update the launch time for applicationId: application_1778475288188_0002, attemptId: appattempt_1778475288188_0002_000001launchTime: 1778478173840
2026-05-11 13:42:53,840 INFO org.apache.hadoop.yarn.server.resourcemanager.recovery.RMStateStore: Updating info for app: application_1778475288188_0002
2026-05-11 13:42:54,814 INFO org.apache.hadoop.yarn.server.resourcemanager.rmcontainer.RMContainerImpl: container_1778475288188_0002_01_000001 Container Transitioned from ACQUIRED to RUNNING
2026-05-11 13:42:57,801 INFO SecurityLogger.org.apache.hadoop.ipc.Server: Auth successful for appattempt_1778475288188_0002_000001 (auth:SIMPLE) from 127.0.0.1:41412
2026-05-11 13:42:57,804 INFO org.apache.hadoop.yarn.server.resourcemanager.DefaultAMSProcessor: AM registration appattempt_1778475288188_0002_000001
2026-05-11 13:42:57,804 INFO org.apache.hadoop.yarn.server.resourcemanager.rmapp.attempt.RMAppAttemptImpl: appattempt_1778475288188_0002_000001 State change from LAUNCHED to RUNNING on event = REGISTERED
2026-05-11 13:42:57,805 INFO org.apache.hadoop.yarn.server.resourcemanager.rmapp.RMAppImpl: application_1778475288188_0002 State change from ACCEPTED to RUNNING on event = ATTEMPT_REGISTERED
2026-05-11 13:42:59,830 INFO org.apache.hadoop.yarn.server.resourcemanager.scheduler.capacity.allocator.AbstractContainerAllocator: assignedContainer application attempt=appattempt_1778475288188_0002_000001 container=null queue=default clusterResource=<memory:8192, vCores:8> type=NODE_LOCAL requestedPartition=
2026-05-11 13:42:59,830 INFO org.apache.hadoop.yarn.server.resourcemanager.rmcontainer.RMContainerImpl: container_1778475288188_0002_01_000002 Container Transitioned from NEW to ALLOCATED
2026-05-11 13:42:59,830 INFO org.apache.hadoop.yarn.server.resourcemanager.scheduler.common.fica.FiCaSchedulerNode: Assigned container container_1778475288188_0002_01_000002 of capacity <memory:1024, vCores:1> on host ubuntu:45565, which has 2 containers, <memory:3072, vCores:2> used and <memory:5120, vCores:6> available after allocation
2026-05-11 13:42:59,830 INFO org.apache.hadoop.yarn.server.resourcemanager.scheduler.capacity.ParentQueue: assignedContainer queue=root usedCapacity=0.375 absoluteUsedCapacity=0.375 used=<memory:3072, vCores:2> cluster=<memory:8192, vCores:8>
2026-05-11 13:42:59,831 INFO org.apache.hadoop.yarn.server.resourcemanager.scheduler.capacity.allocator.AbstractContainerAllocator: assignedContainer application attempt=appattempt_1778475288188_0002_000001 container=null queue=default clusterResource=<memory:8192, vCores:8> type=NODE_LOCAL requestedPartition=
2026-05-11 13:42:59,832 INFO org.apache.hadoop.yarn.server.resourcemanager.rmcontainer.RMContainerImpl: container_1778475288188_0002_01_000003 Container Transitioned from NEW to ALLOCATED
2026-05-11 13:42:59,832 INFO org.apache.hadoop.yarn.server.resourcemanager.scheduler.common.fica.FiCaSchedulerNode: Assigned container container_1778475288188_0002_01_000003 of capacity <memory:1024, vCores:1> on host ubuntu:45565, which has 3 containers, <memory:4096, vCores:3> used and <memory:4096, vCores:5> available after allocation
2026-05-11 13:42:59,832 INFO org.apache.hadoop.yarn.server.resourcemanager.scheduler.capacity.ParentQueue: assignedContainer queue=root usedCapacity=0.5 absoluteUsedCapacity=0.5 used=<memory:4096, vCores:3> cluster=<memory:8192, vCores:8>
2026-05-11 13:42:59,832 INFO org.apache.hadoop.yarn.server.resourcemanager.scheduler.capacity.allocator.AbstractContainerAllocator: assignedContainer application attempt=appattempt_1778475288188_0002_000001 container=null queue=default clusterResource=<memory:8192, vCores:8> type=OFF_SWITCH requestedPartition=
2026-05-11 13:42:59,832 INFO org.apache.hadoop.yarn.server.resourcemanager.rmcontainer.RMContainerImpl: container_1778475288188_0002_01_000004 Container Transitioned from NEW to ALLOCATED
2026-05-11 13:42:59,832 INFO org.apache.hadoop.yarn.server.resourcemanager.scheduler.common.fica.FiCaSchedulerNode: Assigned container container_1778475288188_0002_01_000004 of capacity <memory:1024, vCores:1> on host ubuntu:45565, which has 4 containers, <memory:5120, vCores:4> used and <memory:3072, vCores:4> available after allocation
2026-05-11 13:42:59,833 INFO org.apache.hadoop.yarn.server.resourcemanager.scheduler.capacity.ParentQueue: assignedContainer queue=root usedCapacity=0.625 absoluteUsedCapacity=0.625 used=<memory:5120, vCores:4> cluster=<memory:8192, vCores:8>
2026-05-11 13:42:59,861 INFO org.apache.hadoop.yarn.server.resourcemanager.rmcontainer.RMContainerImpl: container_1778475288188_0002_01_000002 Container Transitioned from ALLOCATED to ACQUIRED
2026-05-11 13:42:59,862 INFO org.apache.hadoop.yarn.server.resourcemanager.rmcontainer.RMContainerImpl: container_1778475288188_0002_01_000003 Container Transitioned from ALLOCATED to ACQUIRED
2026-05-11 13:42:59,865 INFO org.apache.hadoop.yarn.server.resourcemanager.rmcontainer.RMContainerImpl: container_1778475288188_0002_01_000004 Container Transitioned from ALLOCATED to ACQUIRED
2026-05-11 13:43:00,834 INFO org.apache.hadoop.yarn.server.resourcemanager.rmcontainer.RMContainerImpl: container_1778475288188_0002_01_000002 Container Transitioned from ACQUIRED to RUNNING
2026-05-11 13:43:00,835 INFO org.apache.hadoop.yarn.server.resourcemanager.rmcontainer.RMContainerImpl: container_1778475288188_0002_01_000003 Container Transitioned from ACQUIRED to RUNNING
2026-05-11 13:43:00,835 INFO org.apache.hadoop.yarn.server.resourcemanager.rmcontainer.RMContainerImpl: container_1778475288188_0002_01_000004 Container Transitioned from ACQUIRED to RUNNING
2026-05-11 13:43:00,888 INFO org.apache.hadoop.yarn.server.resourcemanager.scheduler.AppSchedulingInfo: checking for deactivate of application :application_1778475288188_0002
2026-05-11 13:43:10,216 INFO org.apache.hadoop.yarn.server.resourcemanager.rmcontainer.RMContainerImpl: container_1778475288188_0002_01_000004 Container Transitioned from RUNNING to COMPLETED
2026-05-11 13:43:11,222 INFO org.apache.hadoop.yarn.server.resourcemanager.scheduler.capacity.allocator.AbstractContainerAllocator: assignedContainer application attempt=appattempt_1778475288188_0002_000001 container=null queue=default clusterResource=<memory:8192, vCores:8> type=OFF_SWITCH requestedPartition=
2026-05-11 13:43:11,222 INFO org.apache.hadoop.yarn.server.resourcemanager.rmcontainer.RMContainerImpl: container_1778475288188_0002_01_000005 Container Transitioned from NEW to ALLOCATED
2026-05-11 13:43:11,222 INFO org.apache.hadoop.yarn.server.resourcemanager.scheduler.common.fica.FiCaSchedulerNode: Assigned container container_1778475288188_0002_01_000005 of capacity <memory:1024, vCores:1> on host ubuntu:45565, which has 4 containers, <memory:5120, vCores:4> used and <memory:3072, vCores:4> available after allocation
2026-05-11 13:43:11,222 INFO org.apache.hadoop.yarn.server.resourcemanager.scheduler.capacity.ParentQueue: assignedContainer queue=root usedCapacity=0.625 absoluteUsedCapacity=0.625 used=<memory:5120, vCores:4> cluster=<memory:8192, vCores:8>
2026-05-11 13:43:12,027 INFO org.apache.hadoop.yarn.server.resourcemanager.rmcontainer.RMContainerImpl: container_1778475288188_0002_01_000005 Container Transitioned from ALLOCATED to ACQUIRED
2026-05-11 13:43:12,225 INFO org.apache.hadoop.yarn.server.resourcemanager.rmcontainer.RMContainerImpl: container_1778475288188_0002_01_000005 Container Transitioned from ACQUIRED to RUNNING
2026-05-11 13:43:13,033 INFO org.apache.hadoop.yarn.server.resourcemanager.scheduler.AppSchedulingInfo: checking for deactivate of application :application_1778475288188_0002
2026-05-11 13:43:13,755 INFO org.apache.hadoop.yarn.server.resourcemanager.rmcontainer.RMContainerImpl: container_1778475288188_0002_01_000002 Container Transitioned from RUNNING to COMPLETED
2026-05-11 13:43:15,190 INFO org.apache.hadoop.yarn.server.resourcemanager.rmcontainer.RMContainerImpl: container_1778475288188_0002_01_000003 Container Transitioned from RUNNING to COMPLETED
2026-05-11 13:43:16,119 INFO org.apache.hadoop.yarn.server.resourcemanager.rmapp.attempt.RMAppAttemptImpl: Updating application attempt appattempt_1778475288188_0002_000001 with final state: FINISHING, and exit status: -1000
2026-05-11 13:43:16,120 INFO org.apache.hadoop.yarn.server.resourcemanager.rmapp.attempt.RMAppAttemptImpl: appattempt_1778475288188_0002_000001 State change from RUNNING to FINAL_SAVING on event = UNREGISTERED
2026-05-11 13:43:16,120 INFO org.apache.hadoop.yarn.server.resourcemanager.rmapp.attempt.RMAppAttemptImpl: appattempt_1778475288188_0002_000001 State change from FINAL_SAVING to FINISHING on event = ATTEMPT_UPDATE_SAVED
2026-05-11 13:43:16,120 INFO org.apache.hadoop.yarn.server.resourcemanager.rmapp.RMAppImpl: Updating application application_1778475288188_0002 with final state: FINISHING
2026-05-11 13:43:16,120 INFO org.apache.hadoop.yarn.server.resourcemanager.recovery.RMStateStore: Updating info for app: application_1778475288188_0002
2026-05-11 13:43:16,121 INFO org.apache.hadoop.yarn.server.resourcemanager.rmapp.RMAppImpl: application_1778475288188_0002 State change from RUNNING to FINAL_SAVING on event = ATTEMPT_UNREGISTERED
2026-05-11 13:43:16,121 INFO org.apache.hadoop.yarn.server.resourcemanager.rmapp.RMAppImpl: application_1778475288188_0002 State change from FINAL_SAVING to FINISHING on event = APP_UPDATE_SAVED
2026-05-11 13:43:16,130 INFO org.apache.hadoop.yarn.server.resourcemanager.rmcontainer.RMContainerImpl: container_1778475288188_0002_01_000005 Container Transitioned from RUNNING to COMPLETED
2026-05-11 13:43:17,126 INFO org.apache.hadoop.yarn.server.resourcemanager.ApplicationMasterService: application_1778475288188_0002 unregistered successfully. 
2026-05-11 13:43:22,537 INFO org.apache.hadoop.yarn.server.resourcemanager.rmcontainer.RMContainerImpl: container_1778475288188_0002_01_000001 Container Transitioned from RUNNING to COMPLETED
2026-05-11 13:43:22,537 INFO org.apache.hadoop.yarn.server.resourcemanager.ApplicationMasterService: Unregistering app attempt : appattempt_1778475288188_0002_000001
2026-05-11 13:43:22,537 INFO org.apache.hadoop.yarn.server.resourcemanager.security.AMRMTokenSecretManager: Application finished, removing password for appattempt_1778475288188_0002_000001
2026-05-11 13:43:22,537 INFO org.apache.hadoop.yarn.server.resourcemanager.rmapp.attempt.RMAppAttemptImpl: appattempt_1778475288188_0002_000001 State change from FINISHING to FINISHED on event = CONTAINER_FINISHED
2026-05-11 13:43:22,541 INFO org.apache.hadoop.yarn.server.resourcemanager.rmapp.RMAppImpl: application_1778475288188_0002 State change from FINISHING to FINISHED on event = ATTEMPT_FINISHED
2026-05-11 13:43:22,543 INFO org.apache.hadoop.yarn.server.resourcemanager.scheduler.capacity.CapacityScheduler: Application Attempt appattempt_1778475288188_0002_000001 is done. finalState=FINISHED
2026-05-11 13:43:22,543 INFO org.apache.hadoop.yarn.server.resourcemanager.scheduler.AppSchedulingInfo: Application application_1778475288188_0002 requests cleared
2026-05-11 13:43:22,551 INFO org.apache.hadoop.yarn.server.resourcemanager.amlauncher.AMLauncher: Cleaning master appattempt_1778475288188_0002_000001
2026-05-11 13:43:22,553 INFO org.apache.hadoop.yarn.server.resourcemanager.RMAppManager$ApplicationSummary: appId=application_1778475288188_0002,name=SELECT COUNT(*) AS cl...user_behavior_detail (Stage-1),user=cty1576,queue=default,state=FINISHED,trackingUrl=http://ubuntu:8088/proxy/application_1778475288188_0002/,appMasterHost=ubuntu,submitTime=1778478173426,startTime=1778478173427,launchTime=1778478173840,finishTime=1778478196120,finalStatus=SUCCEEDED,memorySeconds=104470,vcoreSeconds=70,preemptedMemorySeconds=0,preemptedVcoreSeconds=0,preemptedAMContainers=0,preemptedNonAMContainers=0,preemptedResources=<memory:0\, vCores:0>,applicationType=MAPREDUCE,resourceSeconds=104470 MB-seconds\, 70 vcore-seconds,preemptedResourceSeconds=0 MB-seconds\, 0 vcore-seconds,applicationTags=,applicationNodeLabel=,diagnostics=,totalAllocatedContainers=5
2026-05-11 13:43:22,558 INFO org.apache.hadoop.yarn.server.resourcemanager.scheduler.capacity.LeafQueue: Application removed - appId: application_1778475288188_0002 user: cty1576 queue: root.default #user-pending-applications: 0 #user-active-applications: 0 #queue-pending-applications: 0 #queue-active-applications: 0
2026-05-11 13:43:22,559 INFO org.apache.hadoop.yarn.server.resourcemanager.scheduler.capacity.ParentQueue: Application removed - appId: application_1778475288188_0002 user: cty1576 leaf-queue of parent: root #applications: 0
2026-05-11 13:43:24,525 INFO org.apache.hadoop.yarn.server.resourcemanager.ClientRMService: Allocated new applicationId: 3
2026-05-11 13:43:25,381 INFO org.apache.hadoop.yarn.server.resourcemanager.scheduler.capacity.CapacityScheduler: Application 'application_1778475288188_0003' is submitted without priority hence considering default queue/cluster priority: 0
2026-05-11 13:43:25,381 INFO org.apache.hadoop.yarn.server.resourcemanager.scheduler.capacity.CapacityScheduler: Priority '0' is acceptable in queue : default for application: application_1778475288188_0003
2026-05-11 13:43:25,381 INFO org.apache.hadoop.yarn.server.resourcemanager.ClientRMService: Application with id 3 submitted by user cty1576
2026-05-11 13:43:25,381 INFO org.apache.hadoop.yarn.server.resourcemanager.rmapp.RMAppImpl: Storing application with id application_1778475288188_0003
2026-05-11 13:43:25,381 INFO org.apache.hadoop.yarn.server.resourcemanager.recovery.RMStateStore: Storing info for app: application_1778475288188_0003
2026-05-11 13:43:25,381 INFO org.apache.hadoop.yarn.server.resourcemanager.rmapp.RMAppImpl: application_1778475288188_0003 State change from NEW to NEW_SAVING on event = START
2026-05-11 13:43:25,381 INFO org.apache.hadoop.yarn.server.resourcemanager.rmapp.RMAppImpl: application_1778475288188_0003 State change from NEW_SAVING to SUBMITTED on event = APP_NEW_SAVED
2026-05-11 13:43:25,382 INFO org.apache.hadoop.yarn.server.resourcemanager.scheduler.capacity.ParentQueue: Application added - appId: application_1778475288188_0003 user: cty1576 leaf-queue of parent: root #applications: 1
2026-05-11 13:43:25,383 INFO org.apache.hadoop.yarn.server.resourcemanager.scheduler.capacity.CapacityScheduler: Accepted application application_1778475288188_0003 from user: cty1576, in queue: default
2026-05-11 13:43:25,383 INFO org.apache.hadoop.yarn.server.resourcemanager.rmapp.RMAppImpl: application_1778475288188_0003 State change from SUBMITTED to ACCEPTED on event = APP_ACCEPTED
2026-05-11 13:43:25,383 INFO org.apache.hadoop.yarn.server.resourcemanager.ApplicationMasterService: Registering app attempt : appattempt_1778475288188_0003_000001
2026-05-11 13:43:25,383 INFO org.apache.hadoop.yarn.server.resourcemanager.rmapp.attempt.RMAppAttemptImpl: appattempt_1778475288188_0003_000001 State change from NEW to SUBMITTED on event = START
2026-05-11 13:43:25,383 WARN org.apache.hadoop.yarn.server.resourcemanager.scheduler.capacity.LeafQueue: maximum-am-resource-percent is insufficient to start a single application in queue, it is likely set too low. skipping enforcement to allow at least one application to start
2026-05-11 13:43:25,383 WARN org.apache.hadoop.yarn.server.resourcemanager.scheduler.capacity.LeafQueue: maximum-am-resource-percent is insufficient to start a single application in queue for user, it is likely set too low. skipping enforcement to allow at least one application to start
2026-05-11 13:43:25,383 INFO org.apache.hadoop.yarn.server.resourcemanager.scheduler.capacity.LeafQueue: Application application_1778475288188_0003 from user: cty1576 activated in queue: root.default
2026-05-11 13:43:25,383 INFO org.apache.hadoop.yarn.server.resourcemanager.scheduler.capacity.LeafQueue: Application added - appId: application_1778475288188_0003 user: cty1576, leaf-queue: root.default #user-pending-applications: 0 #user-active-applications: 1 #queue-pending-applications: 0 #queue-active-applications: 1 #queue-nonrunnable-applications: 0
2026-05-11 13:43:25,383 INFO org.apache.hadoop.yarn.server.resourcemanager.scheduler.capacity.CapacityScheduler: Added Application Attempt appattempt_1778475288188_0003_000001 to scheduler from user cty1576 in queue root.default
2026-05-11 13:43:25,384 INFO org.apache.hadoop.yarn.server.resourcemanager.rmapp.attempt.RMAppAttemptImpl: appattempt_1778475288188_0003_000001 State change from SUBMITTED to SCHEDULED on event = ATTEMPT_ADDED
2026-05-11 13:43:25,556 INFO org.apache.hadoop.yarn.server.resourcemanager.scheduler.capacity.allocator.AbstractContainerAllocator: assignedContainer application attempt=appattempt_1778475288188_0003_000001 container=null queue=default clusterResource=<memory:8192, vCores:8> type=OFF_SWITCH requestedPartition=
2026-05-11 13:43:25,556 INFO org.apache.hadoop.yarn.server.resourcemanager.rmcontainer.RMContainerImpl: container_1778475288188_0003_01_000001 Container Transitioned from NEW to ALLOCATED
2026-05-11 13:43:25,556 INFO org.apache.hadoop.yarn.server.resourcemanager.scheduler.common.fica.FiCaSchedulerNode: Assigned container container_1778475288188_0003_01_000001 of capacity <memory:2048, vCores:1> on host ubuntu:45565, which has 1 containers, <memory:2048, vCores:1> used and <memory:6144, vCores:7> available after allocation
2026-05-11 13:43:25,556 INFO org.apache.hadoop.yarn.server.resourcemanager.scheduler.capacity.ParentQueue: assignedContainer queue=root usedCapacity=0.25 absoluteUsedCapacity=0.25 used=<memory:2048, vCores:1> cluster=<memory:8192, vCores:8>
2026-05-11 13:43:25,557 INFO org.apache.hadoop.yarn.server.resourcemanager.rmcontainer.RMContainerImpl: container_1778475288188_0003_01_000001 Container Transitioned from ALLOCATED to ACQUIRED
2026-05-11 13:43:25,558 INFO org.apache.hadoop.yarn.server.resourcemanager.security.NMTokenSecretManagerInRM: Clear node set for appattempt_1778475288188_0003_000001
2026-05-11 13:43:25,558 INFO org.apache.hadoop.yarn.server.resourcemanager.rmapp.attempt.RMAppAttemptImpl: Storing attempt: AppId: application_1778475288188_0003 AttemptId: appattempt_1778475288188_0003_000001 MasterContainer: Container: [ContainerId: container_1778475288188_0003_01_000001, AllocationRequestId: -1, Version: 0, NodeId: ubuntu:45565, NodeHttpAddress: ubuntu:8042, Resource: <memory:2048, vCores:1>, Priority: 0, Token: Token { kind: ContainerToken, service: 127.0.1.1:45565 }, ExecutionType: GUARANTEED, ]
2026-05-11 13:43:25,558 INFO org.apache.hadoop.yarn.server.resourcemanager.rmapp.attempt.RMAppAttemptImpl: appattempt_1778475288188_0003_000001 State change from SCHEDULED to ALLOCATED_SAVING on event = CONTAINER_ALLOCATED
2026-05-11 13:43:25,558 INFO org.apache.hadoop.yarn.server.resourcemanager.rmapp.attempt.RMAppAttemptImpl: appattempt_1778475288188_0003_000001 State change from ALLOCATED_SAVING to ALLOCATED on event = ATTEMPT_NEW_SAVED
2026-05-11 13:43:25,559 INFO org.apache.hadoop.yarn.server.resourcemanager.amlauncher.AMLauncher: Launching masterappattempt_1778475288188_0003_000001
2026-05-11 13:43:25,561 INFO org.apache.hadoop.yarn.server.resourcemanager.amlauncher.AMLauncher: Setting up container Container: [ContainerId: container_1778475288188_0003_01_000001, AllocationRequestId: -1, Version: 0, NodeId: ubuntu:45565, NodeHttpAddress: ubuntu:8042, Resource: <memory:2048, vCores:1>, Priority: 0, Token: Token { kind: ContainerToken, service: 127.0.1.1:45565 }, ExecutionType: GUARANTEED, ] for AM appattempt_1778475288188_0003_000001
2026-05-11 13:43:25,561 INFO org.apache.hadoop.yarn.server.resourcemanager.security.AMRMTokenSecretManager: Create AMRMToken for ApplicationAttempt: appattempt_1778475288188_0003_000001
2026-05-11 13:43:25,561 INFO org.apache.hadoop.yarn.server.resourcemanager.security.AMRMTokenSecretManager: Creating password for appattempt_1778475288188_0003_000001
2026-05-11 13:43:25,576 INFO org.apache.hadoop.yarn.server.resourcemanager.amlauncher.AMLauncher: Done launching container Container: [ContainerId: container_1778475288188_0003_01_000001, AllocationRequestId: -1, Version: 0, NodeId: ubuntu:45565, NodeHttpAddress: ubuntu:8042, Resource: <memory:2048, vCores:1>, Priority: 0, Token: Token { kind: ContainerToken, service: 127.0.1.1:45565 }, ExecutionType: GUARANTEED, ] for AM appattempt_1778475288188_0003_000001
2026-05-11 13:43:25,577 INFO org.apache.hadoop.yarn.server.resourcemanager.rmapp.attempt.RMAppAttemptImpl: appattempt_1778475288188_0003_000001 State change from ALLOCATED to LAUNCHED on event = LAUNCHED
2026-05-11 13:43:25,577 INFO org.apache.hadoop.yarn.server.resourcemanager.rmapp.RMAppImpl: update the launch time for applicationId: application_1778475288188_0003, attemptId: appattempt_1778475288188_0003_000001launchTime: 1778478205576
2026-05-11 13:43:25,578 INFO org.apache.hadoop.yarn.server.resourcemanager.recovery.RMStateStore: Updating info for app: application_1778475288188_0003
2026-05-11 13:43:26,560 INFO org.apache.hadoop.yarn.server.resourcemanager.rmcontainer.RMContainerImpl: container_1778475288188_0003_01_000001 Container Transitioned from ACQUIRED to RUNNING
2026-05-11 13:43:29,463 INFO SecurityLogger.org.apache.hadoop.ipc.Server: Auth successful for appattempt_1778475288188_0003_000001 (auth:SIMPLE) from 127.0.0.1:46450
2026-05-11 13:43:29,465 INFO org.apache.hadoop.yarn.server.resourcemanager.DefaultAMSProcessor: AM registration appattempt_1778475288188_0003_000001
2026-05-11 13:43:29,467 INFO org.apache.hadoop.yarn.server.resourcemanager.rmapp.attempt.RMAppAttemptImpl: appattempt_1778475288188_0003_000001 State change from LAUNCHED to RUNNING on event = REGISTERED
2026-05-11 13:43:29,467 INFO org.apache.hadoop.yarn.server.resourcemanager.rmapp.RMAppImpl: application_1778475288188_0003 State change from ACCEPTED to RUNNING on event = ATTEMPT_REGISTERED
2026-05-11 13:43:30,577 INFO org.apache.hadoop.yarn.server.resourcemanager.scheduler.capacity.allocator.AbstractContainerAllocator: assignedContainer application attempt=appattempt_1778475288188_0003_000001 container=null queue=default clusterResource=<memory:8192, vCores:8> type=NODE_LOCAL requestedPartition=
2026-05-11 13:43:30,577 INFO org.apache.hadoop.yarn.server.resourcemanager.rmcontainer.RMContainerImpl: container_1778475288188_0003_01_000002 Container Transitioned from NEW to ALLOCATED
2026-05-11 13:43:30,577 INFO org.apache.hadoop.yarn.server.resourcemanager.scheduler.common.fica.FiCaSchedulerNode: Assigned container container_1778475288188_0003_01_000002 of capacity <memory:1024, vCores:1> on host ubuntu:45565, which has 2 containers, <memory:3072, vCores:2> used and <memory:5120, vCores:6> available after allocation
2026-05-11 13:43:30,577 INFO org.apache.hadoop.yarn.server.resourcemanager.scheduler.capacity.ParentQueue: assignedContainer queue=root usedCapacity=0.375 absoluteUsedCapacity=0.375 used=<memory:3072, vCores:2> cluster=<memory:8192, vCores:8>
2026-05-11 13:43:30,578 INFO org.apache.hadoop.yarn.server.resourcemanager.scheduler.capacity.allocator.AbstractContainerAllocator: assignedContainer application attempt=appattempt_1778475288188_0003_000001 container=null queue=default clusterResource=<memory:8192, vCores:8> type=NODE_LOCAL requestedPartition=
2026-05-11 13:43:30,587 INFO org.apache.hadoop.yarn.server.resourcemanager.rmcontainer.RMContainerImpl: container_1778475288188_0003_01_000003 Container Transitioned from NEW to ALLOCATED
2026-05-11 13:43:30,587 INFO org.apache.hadoop.yarn.server.resourcemanager.scheduler.common.fica.FiCaSchedulerNode: Assigned container container_1778475288188_0003_01_000003 of capacity <memory:1024, vCores:1> on host ubuntu:45565, which has 3 containers, <memory:4096, vCores:3> used and <memory:4096, vCores:5> available after allocation
2026-05-11 13:43:30,587 INFO org.apache.hadoop.yarn.server.resourcemanager.scheduler.capacity.ParentQueue: assignedContainer queue=root usedCapacity=0.5 absoluteUsedCapacity=0.5 used=<memory:4096, vCores:3> cluster=<memory:8192, vCores:8>
2026-05-11 13:43:30,588 INFO org.apache.hadoop.yarn.server.resourcemanager.scheduler.capacity.allocator.AbstractContainerAllocator: assignedContainer application attempt=appattempt_1778475288188_0003_000001 container=null queue=default clusterResource=<memory:8192, vCores:8> type=OFF_SWITCH requestedPartition=
2026-05-11 13:43:30,589 INFO org.apache.hadoop.yarn.server.resourcemanager.rmcontainer.RMContainerImpl: container_1778475288188_0003_01_000004 Container Transitioned from NEW to ALLOCATED
2026-05-11 13:43:30,589 INFO org.apache.hadoop.yarn.server.resourcemanager.scheduler.common.fica.FiCaSchedulerNode: Assigned container container_1778475288188_0003_01_000004 of capacity <memory:1024, vCores:1> on host ubuntu:45565, which has 4 containers, <memory:5120, vCores:4> used and <memory:3072, vCores:4> available after allocation
2026-05-11 13:43:30,593 INFO org.apache.hadoop.yarn.server.resourcemanager.scheduler.capacity.ParentQueue: assignedContainer queue=root usedCapacity=0.625 absoluteUsedCapacity=0.625 used=<memory:5120, vCores:4> cluster=<memory:8192, vCores:8>
2026-05-11 13:43:31,594 INFO org.apache.hadoop.yarn.server.resourcemanager.rmcontainer.RMContainerImpl: container_1778475288188_0003_01_000002 Container Transitioned from ALLOCATED to ACQUIRED
2026-05-11 13:43:31,595 INFO org.apache.hadoop.yarn.server.resourcemanager.rmcontainer.RMContainerImpl: container_1778475288188_0003_01_000003 Container Transitioned from ALLOCATED to ACQUIRED
2026-05-11 13:43:31,595 INFO org.apache.hadoop.yarn.server.resourcemanager.rmcontainer.RMContainerImpl: container_1778475288188_0003_01_000004 Container Transitioned from ALLOCATED to ACQUIRED
2026-05-11 13:43:32,578 INFO org.apache.hadoop.yarn.server.resourcemanager.rmcontainer.RMContainerImpl: container_1778475288188_0003_01_000002 Container Transitioned from ACQUIRED to RUNNING
2026-05-11 13:43:32,578 INFO org.apache.hadoop.yarn.server.resourcemanager.rmcontainer.RMContainerImpl: container_1778475288188_0003_01_000003 Container Transitioned from ACQUIRED to RUNNING
2026-05-11 13:43:32,578 INFO org.apache.hadoop.yarn.server.resourcemanager.rmcontainer.RMContainerImpl: container_1778475288188_0003_01_000004 Container Transitioned from ACQUIRED to RUNNING
2026-05-11 13:43:32,607 INFO org.apache.hadoop.yarn.server.resourcemanager.scheduler.AppSchedulingInfo: checking for deactivate of application :application_1778475288188_0003
2026-05-11 13:43:41,784 INFO org.apache.hadoop.yarn.server.resourcemanager.rmcontainer.RMContainerImpl: container_1778475288188_0003_01_000004 Container Transitioned from RUNNING to COMPLETED
2026-05-11 13:43:42,796 INFO org.apache.hadoop.yarn.server.resourcemanager.scheduler.capacity.allocator.AbstractContainerAllocator: assignedContainer application attempt=appattempt_1778475288188_0003_000001 container=null queue=default clusterResource=<memory:8192, vCores:8> type=OFF_SWITCH requestedPartition=
2026-05-11 13:43:42,796 INFO org.apache.hadoop.yarn.server.resourcemanager.rmcontainer.RMContainerImpl: container_1778475288188_0003_01_000005 Container Transitioned from NEW to ALLOCATED
2026-05-11 13:43:42,796 INFO org.apache.hadoop.yarn.server.resourcemanager.scheduler.common.fica.FiCaSchedulerNode: Assigned container container_1778475288188_0003_01_000005 of capacity <memory:1024, vCores:1> on host ubuntu:45565, which has 4 containers, <memory:5120, vCores:4> used and <memory:3072, vCores:4> available after allocation
2026-05-11 13:43:42,798 INFO org.apache.hadoop.yarn.server.resourcemanager.scheduler.capacity.ParentQueue: assignedContainer queue=root usedCapacity=0.625 absoluteUsedCapacity=0.625 used=<memory:5120, vCores:4> cluster=<memory:8192, vCores:8>
2026-05-11 13:43:43,710 INFO org.apache.hadoop.yarn.server.resourcemanager.rmcontainer.RMContainerImpl: container_1778475288188_0003_01_000005 Container Transitioned from ALLOCATED to ACQUIRED
2026-05-11 13:43:43,802 INFO org.apache.hadoop.yarn.server.resourcemanager.rmcontainer.RMContainerImpl: container_1778475288188_0003_01_000005 Container Transitioned from ACQUIRED to RUNNING
2026-05-11 13:43:43,809 INFO org.apache.hadoop.yarn.server.resourcemanager.scheduler.capacity.allocator.AbstractContainerAllocator: assignedContainer application attempt=appattempt_1778475288188_0003_000001 container=null queue=default clusterResource=<memory:8192, vCores:8> type=OFF_SWITCH requestedPartition=
2026-05-11 13:43:43,823 INFO org.apache.hadoop.yarn.server.resourcemanager.rmcontainer.RMContainerImpl: container_1778475288188_0003_01_000006 Container Transitioned from NEW to ALLOCATED
2026-05-11 13:43:43,824 INFO org.apache.hadoop.yarn.server.resourcemanager.scheduler.common.fica.FiCaSchedulerNode: Assigned container container_1778475288188_0003_01_000006 of capacity <memory:1024, vCores:1> on host ubuntu:45565, which has 5 containers, <memory:6144, vCores:5> used and <memory:2048, vCores:3> available after allocation
2026-05-11 13:43:43,824 INFO org.apache.hadoop.yarn.server.resourcemanager.scheduler.capacity.ParentQueue: assignedContainer queue=root usedCapacity=0.75 absoluteUsedCapacity=0.75 used=<memory:6144, vCores:5> cluster=<memory:8192, vCores:8>
2026-05-11 13:43:44,729 INFO org.apache.hadoop.yarn.server.resourcemanager.rmcontainer.RMContainerImpl: container_1778475288188_0003_01_000006 Container Transitioned from ALLOCATED to ACQUIRED
2026-05-11 13:43:44,816 INFO org.apache.hadoop.yarn.server.resourcemanager.rmcontainer.RMContainerImpl: container_1778475288188_0003_01_000006 Container Transitioned from ACQUIRED to RUNNING
2026-05-11 13:43:44,820 INFO org.apache.hadoop.yarn.server.resourcemanager.scheduler.capacity.allocator.AbstractContainerAllocator: assignedContainer application attempt=appattempt_1778475288188_0003_000001 container=null queue=default clusterResource=<memory:8192, vCores:8> type=OFF_SWITCH requestedPartition=
2026-05-11 13:43:44,821 INFO org.apache.hadoop.yarn.server.resourcemanager.rmcontainer.RMContainerImpl: container_1778475288188_0003_01_000007 Container Transitioned from NEW to ALLOCATED
2026-05-11 13:43:44,821 INFO org.apache.hadoop.yarn.server.resourcemanager.scheduler.common.fica.FiCaSchedulerNode: Assigned container container_1778475288188_0003_01_000007 of capacity <memory:1024, vCores:1> on host ubuntu:45565, which has 6 containers, <memory:7168, vCores:6> used and <memory:1024, vCores:2> available after allocation
2026-05-11 13:43:44,824 INFO org.apache.hadoop.yarn.server.resourcemanager.scheduler.capacity.ParentQueue: assignedContainer queue=root usedCapacity=0.875 absoluteUsedCapacity=0.875 used=<memory:7168, vCores:6> cluster=<memory:8192, vCores:8>
2026-05-11 13:43:45,744 INFO org.apache.hadoop.yarn.server.resourcemanager.rmcontainer.RMContainerImpl: container_1778475288188_0003_01_000007 Container Transitioned from ALLOCATED to ACQUIRED
2026-05-11 13:43:45,852 INFO org.apache.hadoop.yarn.server.resourcemanager.rmcontainer.RMContainerImpl: container_1778475288188_0003_01_000007 Container Transitioned from ACQUIRED to RUNNING
2026-05-11 13:43:45,855 INFO org.apache.hadoop.yarn.server.resourcemanager.scheduler.capacity.allocator.AbstractContainerAllocator: assignedContainer application attempt=appattempt_1778475288188_0003_000001 container=null queue=default clusterResource=<memory:8192, vCores:8> type=OFF_SWITCH requestedPartition=
2026-05-11 13:43:45,855 INFO org.apache.hadoop.yarn.server.resourcemanager.rmcontainer.RMContainerImpl: container_1778475288188_0003_01_000008 Container Transitioned from NEW to ALLOCATED
2026-05-11 13:43:45,855 INFO org.apache.hadoop.yarn.server.resourcemanager.scheduler.common.fica.FiCaSchedulerNode: Assigned container container_1778475288188_0003_01_000008 of capacity <memory:1024, vCores:1> on host ubuntu:45565, which has 7 containers, <memory:8192, vCores:7> used and <memory:0, vCores:1> available after allocation
2026-05-11 13:43:45,856 INFO org.apache.hadoop.yarn.server.resourcemanager.scheduler.capacity.ParentQueue: assignedContainer queue=root usedCapacity=1.0 absoluteUsedCapacity=1.0 used=<memory:8192, vCores:7> cluster=<memory:8192, vCores:8>
2026-05-11 13:43:46,754 INFO org.apache.hadoop.yarn.server.resourcemanager.scheduler.AppSchedulingInfo: checking for deactivate of application :application_1778475288188_0003
2026-05-11 13:43:46,762 INFO org.apache.hadoop.yarn.server.resourcemanager.rmcontainer.RMContainerImpl: container_1778475288188_0003_01_000008 Container Transitioned from ALLOCATED to ACQUIRED
2026-05-11 13:43:47,718 INFO org.apache.hadoop.yarn.server.resourcemanager.rmcontainer.RMContainerImpl: container_1778475288188_0003_01_000002 Container Transitioned from RUNNING to COMPLETED
2026-05-11 13:43:47,785 INFO org.apache.hadoop.yarn.server.resourcemanager.rmcontainer.RMContainerImpl: container_1778475288188_0003_01_000008 Container Transitioned from ACQUIRED to RELEASED
2026-05-11 13:43:48,700 INFO org.apache.hadoop.yarn.server.resourcemanager.rmcontainer.RMContainerImpl: container_1778475288188_0003_01_000003 Container Transitioned from RUNNING to COMPLETED
2026-05-11 13:43:52,746 INFO org.apache.hadoop.yarn.server.resourcemanager.rmcontainer.RMContainerImpl: container_1778475288188_0003_01_000005 Container Transitioned from RUNNING to COMPLETED
2026-05-11 13:43:53,155 INFO org.apache.hadoop.yarn.server.resourcemanager.rmcontainer.RMContainerImpl: container_1778475288188_0003_01_000006 Container Transitioned from RUNNING to COMPLETED
2026-05-11 13:43:53,712 INFO org.apache.hadoop.yarn.server.resourcemanager.rmcontainer.RMContainerImpl: container_1778475288188_0003_01_000007 Container Transitioned from RUNNING to COMPLETED
2026-05-11 13:43:53,839 INFO org.apache.hadoop.yarn.server.resourcemanager.scheduler.AppSchedulingInfo: checking for deactivate of application :application_1778475288188_0003
2026-05-11 13:43:53,972 INFO org.apache.hadoop.yarn.server.resourcemanager.rmapp.attempt.RMAppAttemptImpl: Updating application attempt appattempt_1778475288188_0003_000001 with final state: FINISHING, and exit status: -1000
2026-05-11 13:43:53,972 INFO org.apache.hadoop.yarn.server.resourcemanager.rmapp.attempt.RMAppAttemptImpl: appattempt_1778475288188_0003_000001 State change from RUNNING to FINAL_SAVING on event = UNREGISTERED
2026-05-11 13:43:53,972 INFO org.apache.hadoop.yarn.server.resourcemanager.rmapp.RMAppImpl: Updating application application_1778475288188_0003 with final state: FINISHING
2026-05-11 13:43:53,972 INFO org.apache.hadoop.yarn.server.resourcemanager.recovery.RMStateStore: Updating info for app: application_1778475288188_0003
2026-05-11 13:43:53,972 INFO org.apache.hadoop.yarn.server.resourcemanager.rmapp.RMAppImpl: application_1778475288188_0003 State change from RUNNING to FINAL_SAVING on event = ATTEMPT_UNREGISTERED
2026-05-11 13:43:53,975 INFO org.apache.hadoop.yarn.server.resourcemanager.rmapp.attempt.RMAppAttemptImpl: appattempt_1778475288188_0003_000001 State change from FINAL_SAVING to FINISHING on event = ATTEMPT_UPDATE_SAVED
2026-05-11 13:43:53,975 INFO org.apache.hadoop.yarn.server.resourcemanager.rmapp.RMAppImpl: application_1778475288188_0003 State change from FINAL_SAVING to FINISHING on event = APP_UPDATE_SAVED
2026-05-11 13:43:54,978 INFO org.apache.hadoop.yarn.server.resourcemanager.ApplicationMasterService: application_1778475288188_0003 unregistered successfully. 
2026-05-11 13:43:56,569 INFO org.apache.hadoop.yarn.server.resourcemanager.ClientRMService: Allocated new applicationId: 4
2026-05-11 13:43:57,266 INFO org.apache.hadoop.yarn.server.resourcemanager.scheduler.capacity.CapacityScheduler: Application 'application_1778475288188_0004' is submitted without priority hence considering default queue/cluster priority: 0
2026-05-11 13:43:57,266 INFO org.apache.hadoop.yarn.server.resourcemanager.scheduler.capacity.CapacityScheduler: Priority '0' is acceptable in queue : default for application: application_1778475288188_0004
2026-05-11 13:43:57,266 INFO org.apache.hadoop.yarn.server.resourcemanager.ClientRMService: Application with id 4 submitted by user cty1576
2026-05-11 13:43:57,268 INFO org.apache.hadoop.yarn.server.resourcemanager.rmapp.RMAppImpl: Storing application with id application_1778475288188_0004
2026-05-11 13:43:57,268 INFO org.apache.hadoop.yarn.server.resourcemanager.rmapp.RMAppImpl: application_1778475288188_0004 State change from NEW to NEW_SAVING on event = START
2026-05-11 13:43:57,269 INFO org.apache.hadoop.yarn.server.resourcemanager.recovery.RMStateStore: Storing info for app: application_1778475288188_0004
2026-05-11 13:43:57,269 INFO org.apache.hadoop.yarn.server.resourcemanager.rmapp.RMAppImpl: application_1778475288188_0004 State change from NEW_SAVING to SUBMITTED on event = APP_NEW_SAVED
2026-05-11 13:43:57,269 INFO org.apache.hadoop.yarn.server.resourcemanager.scheduler.capacity.ParentQueue: Application added - appId: application_1778475288188_0004 user: cty1576 leaf-queue of parent: root #applications: 2
2026-05-11 13:43:57,269 INFO org.apache.hadoop.yarn.server.resourcemanager.scheduler.capacity.CapacityScheduler: Accepted application application_1778475288188_0004 from user: cty1576, in queue: default
2026-05-11 13:43:57,270 INFO org.apache.hadoop.yarn.server.resourcemanager.rmapp.RMAppImpl: application_1778475288188_0004 State change from SUBMITTED to ACCEPTED on event = APP_ACCEPTED
2026-05-11 13:43:57,270 INFO org.apache.hadoop.yarn.server.resourcemanager.ApplicationMasterService: Registering app attempt : appattempt_1778475288188_0004_000001
2026-05-11 13:43:57,270 INFO org.apache.hadoop.yarn.server.resourcemanager.rmapp.attempt.RMAppAttemptImpl: appattempt_1778475288188_0004_000001 State change from NEW to SUBMITTED on event = START
2026-05-11 13:43:57,271 INFO org.apache.hadoop.yarn.server.resourcemanager.scheduler.capacity.LeafQueue: Application added - appId: application_1778475288188_0004 user: cty1576, leaf-queue: root.default #user-pending-applications: 1 #user-active-applications: 1 #queue-pending-applications: 1 #queue-active-applications: 1 #queue-nonrunnable-applications: 0
2026-05-11 13:43:57,271 INFO org.apache.hadoop.yarn.server.resourcemanager.scheduler.capacity.CapacityScheduler: Added Application Attempt appattempt_1778475288188_0004_000001 to scheduler from user cty1576 in queue root.default
2026-05-11 13:43:57,273 INFO org.apache.hadoop.yarn.server.resourcemanager.rmapp.attempt.RMAppAttemptImpl: appattempt_1778475288188_0004_000001 State change from SUBMITTED to SCHEDULED on event = ATTEMPT_ADDED
2026-05-11 13:44:00,383 INFO org.apache.hadoop.yarn.server.resourcemanager.ApplicationMasterService: Unregistering app attempt : appattempt_1778475288188_0003_000001
2026-05-11 13:44:00,383 INFO org.apache.hadoop.yarn.server.resourcemanager.security.AMRMTokenSecretManager: Application finished, removing password for appattempt_1778475288188_0003_000001
2026-05-11 13:44:00,383 INFO org.apache.hadoop.yarn.server.resourcemanager.rmapp.attempt.RMAppAttemptImpl: appattempt_1778475288188_0003_000001 State change from FINISHING to FINISHED on event = CONTAINER_FINISHED
2026-05-11 13:44:00,384 INFO org.apache.hadoop.yarn.server.resourcemanager.rmapp.RMAppImpl: application_1778475288188_0003 State change from FINISHING to FINISHED on event = ATTEMPT_FINISHED
2026-05-11 13:44:00,384 INFO org.apache.hadoop.yarn.server.resourcemanager.rmcontainer.RMContainerImpl: container_1778475288188_0003_01_000001 Container Transitioned from RUNNING to COMPLETED
2026-05-11 13:44:00,384 INFO org.apache.hadoop.yarn.server.resourcemanager.scheduler.capacity.CapacityScheduler: Application Attempt appattempt_1778475288188_0003_000001 is done. finalState=FINISHED
2026-05-11 13:44:00,384 INFO org.apache.hadoop.yarn.server.resourcemanager.scheduler.AppSchedulingInfo: Application application_1778475288188_0003 requests cleared
2026-05-11 13:44:00,384 WARN org.apache.hadoop.yarn.server.resourcemanager.scheduler.capacity.LeafQueue: maximum-am-resource-percent is insufficient to start a single application in queue, it is likely set too low. skipping enforcement to allow at least one application to start
2026-05-11 13:44:00,384 WARN org.apache.hadoop.yarn.server.resourcemanager.scheduler.capacity.LeafQueue: maximum-am-resource-percent is insufficient to start a single application in queue for user, it is likely set too low. skipping enforcement to allow at least one application to start
2026-05-11 13:44:00,385 INFO org.apache.hadoop.yarn.server.resourcemanager.scheduler.capacity.LeafQueue: Application application_1778475288188_0004 from user: cty1576 activated in queue: root.default
2026-05-11 13:44:00,385 INFO org.apache.hadoop.yarn.server.resourcemanager.scheduler.capacity.LeafQueue: Application removed - appId: application_1778475288188_0003 user: cty1576 queue: root.default #user-pending-applications: 0 #user-active-applications: 1 #queue-pending-applications: 0 #queue-active-applications: 1
2026-05-11 13:44:00,388 INFO org.apache.hadoop.yarn.server.resourcemanager.amlauncher.AMLauncher: Cleaning master appattempt_1778475288188_0003_000001
2026-05-11 13:44:00,388 INFO org.apache.hadoop.yarn.server.resourcemanager.RMAppManager$ApplicationSummary: appId=application_1778475288188_0003,name=SELECT behavior\, COUNT(*) AS cnt FROM...DESC (Stage-1),user=cty1576,queue=default,state=FINISHED,trackingUrl=http://ubuntu:8088/proxy/application_1778475288188_0003/,appMasterHost=ubuntu,submitTime=1778478205380,startTime=1778478205381,launchTime=1778478205576,finishTime=1778478233972,finalStatus=SUCCEEDED,memorySeconds=149732,vcoreSeconds=107,preemptedMemorySeconds=0,preemptedVcoreSeconds=0,preemptedAMContainers=0,preemptedNonAMContainers=0,preemptedResources=<memory:0\, vCores:0>,applicationType=MAPREDUCE,resourceSeconds=149732 MB-seconds\, 107 vcore-seconds,preemptedResourceSeconds=0 MB-seconds\, 0 vcore-seconds,applicationTags=,applicationNodeLabel=,diagnostics=,totalAllocatedContainers=8
2026-05-11 13:44:00,390 INFO org.apache.hadoop.yarn.server.resourcemanager.scheduler.capacity.ParentQueue: Application removed - appId: application_1778475288188_0003 user: cty1576 leaf-queue of parent: root #applications: 1
2026-05-11 13:44:01,388 INFO org.apache.hadoop.yarn.server.resourcemanager.scheduler.capacity.allocator.AbstractContainerAllocator: assignedContainer application attempt=appattempt_1778475288188_0004_000001 container=null queue=default clusterResource=<memory:8192, vCores:8> type=OFF_SWITCH requestedPartition=
2026-05-11 13:44:01,391 INFO org.apache.hadoop.yarn.server.resourcemanager.rmcontainer.RMContainerImpl: container_1778475288188_0004_01_000001 Container Transitioned from NEW to ALLOCATED
2026-05-11 13:44:01,391 INFO org.apache.hadoop.yarn.server.resourcemanager.scheduler.common.fica.FiCaSchedulerNode: Assigned container container_1778475288188_0004_01_000001 of capacity <memory:2048, vCores:1> on host ubuntu:45565, which has 1 containers, <memory:2048, vCores:1> used and <memory:6144, vCores:7> available after allocation
2026-05-11 13:44:01,392 INFO org.apache.hadoop.yarn.server.resourcemanager.scheduler.capacity.ParentQueue: assignedContainer queue=root usedCapacity=0.25 absoluteUsedCapacity=0.25 used=<memory:2048, vCores:1> cluster=<memory:8192, vCores:8>
2026-05-11 13:44:01,396 INFO org.apache.hadoop.yarn.server.resourcemanager.rmcontainer.RMContainerImpl: container_1778475288188_0004_01_000001 Container Transitioned from ALLOCATED to ACQUIRED
2026-05-11 13:44:01,398 INFO org.apache.hadoop.yarn.server.resourcemanager.security.NMTokenSecretManagerInRM: Clear node set for appattempt_1778475288188_0004_000001
2026-05-11 13:44:01,399 INFO org.apache.hadoop.yarn.server.resourcemanager.rmapp.attempt.RMAppAttemptImpl: Storing attempt: AppId: application_1778475288188_0004 AttemptId: appattempt_1778475288188_0004_000001 MasterContainer: Container: [ContainerId: container_1778475288188_0004_01_000001, AllocationRequestId: -1, Version: 0, NodeId: ubuntu:45565, NodeHttpAddress: ubuntu:8042, Resource: <memory:2048, vCores:1>, Priority: 0, Token: Token { kind: ContainerToken, service: 127.0.1.1:45565 }, ExecutionType: GUARANTEED, ]
2026-05-11 13:44:01,399 INFO org.apache.hadoop.yarn.server.resourcemanager.rmapp.attempt.RMAppAttemptImpl: appattempt_1778475288188_0004_000001 State change from SCHEDULED to ALLOCATED_SAVING on event = CONTAINER_ALLOCATED
2026-05-11 13:44:01,406 INFO org.apache.hadoop.yarn.server.resourcemanager.rmapp.attempt.RMAppAttemptImpl: appattempt_1778475288188_0004_000001 State change from ALLOCATED_SAVING to ALLOCATED on event = ATTEMPT_NEW_SAVED
2026-05-11 13:44:01,407 INFO org.apache.hadoop.yarn.server.resourcemanager.amlauncher.AMLauncher: Launching masterappattempt_1778475288188_0004_000001
2026-05-11 13:44:01,412 INFO org.apache.hadoop.yarn.server.resourcemanager.amlauncher.AMLauncher: Setting up container Container: [ContainerId: container_1778475288188_0004_01_000001, AllocationRequestId: -1, Version: 0, NodeId: ubuntu:45565, NodeHttpAddress: ubuntu:8042, Resource: <memory:2048, vCores:1>, Priority: 0, Token: Token { kind: ContainerToken, service: 127.0.1.1:45565 }, ExecutionType: GUARANTEED, ] for AM appattempt_1778475288188_0004_000001
2026-05-11 13:44:01,413 INFO org.apache.hadoop.yarn.server.resourcemanager.security.AMRMTokenSecretManager: Create AMRMToken for ApplicationAttempt: appattempt_1778475288188_0004_000001
2026-05-11 13:44:01,413 INFO org.apache.hadoop.yarn.server.resourcemanager.security.AMRMTokenSecretManager: Creating password for appattempt_1778475288188_0004_000001
2026-05-11 13:44:01,451 INFO org.apache.hadoop.yarn.server.resourcemanager.amlauncher.AMLauncher: Done launching container Container: [ContainerId: container_1778475288188_0004_01_000001, AllocationRequestId: -1, Version: 0, NodeId: ubuntu:45565, NodeHttpAddress: ubuntu:8042, Resource: <memory:2048, vCores:1>, Priority: 0, Token: Token { kind: ContainerToken, service: 127.0.1.1:45565 }, ExecutionType: GUARANTEED, ] for AM appattempt_1778475288188_0004_000001
2026-05-11 13:44:01,451 INFO org.apache.hadoop.yarn.server.resourcemanager.rmapp.attempt.RMAppAttemptImpl: appattempt_1778475288188_0004_000001 State change from ALLOCATED to LAUNCHED on event = LAUNCHED
2026-05-11 13:44:01,451 INFO org.apache.hadoop.yarn.server.resourcemanager.rmapp.RMAppImpl: update the launch time for applicationId: application_1778475288188_0004, attemptId: appattempt_1778475288188_0004_000001launchTime: 1778478241451
2026-05-11 13:44:01,452 INFO org.apache.hadoop.yarn.server.resourcemanager.recovery.RMStateStore: Updating info for app: application_1778475288188_0004
2026-05-11 13:44:02,388 INFO org.apache.hadoop.yarn.server.resourcemanager.rmcontainer.RMContainerImpl: container_1778475288188_0004_01_000001 Container Transitioned from ACQUIRED to RUNNING
2026-05-11 13:44:05,354 INFO SecurityLogger.org.apache.hadoop.ipc.Server: Auth successful for appattempt_1778475288188_0004_000001 (auth:SIMPLE) from 127.0.0.1:52030
2026-05-11 13:44:05,356 INFO org.apache.hadoop.yarn.server.resourcemanager.DefaultAMSProcessor: AM registration appattempt_1778475288188_0004_000001
2026-05-11 13:44:05,356 INFO org.apache.hadoop.yarn.server.resourcemanager.rmapp.attempt.RMAppAttemptImpl: appattempt_1778475288188_0004_000001 State change from LAUNCHED to RUNNING on event = REGISTERED
2026-05-11 13:44:05,356 INFO org.apache.hadoop.yarn.server.resourcemanager.rmapp.RMAppImpl: application_1778475288188_0004 State change from ACCEPTED to RUNNING on event = ATTEMPT_REGISTERED
2026-05-11 13:44:06,400 INFO org.apache.hadoop.yarn.server.resourcemanager.scheduler.capacity.allocator.AbstractContainerAllocator: assignedContainer application attempt=appattempt_1778475288188_0004_000001 container=null queue=default clusterResource=<memory:8192, vCores:8> type=NODE_LOCAL requestedPartition=
2026-05-11 13:44:06,400 INFO org.apache.hadoop.yarn.server.resourcemanager.rmcontainer.RMContainerImpl: container_1778475288188_0004_01_000002 Container Transitioned from NEW to ALLOCATED
2026-05-11 13:44:06,400 INFO org.apache.hadoop.yarn.server.resourcemanager.scheduler.common.fica.FiCaSchedulerNode: Assigned container container_1778475288188_0004_01_000002 of capacity <memory:1024, vCores:1> on host ubuntu:45565, which has 2 containers, <memory:3072, vCores:2> used and <memory:5120, vCores:6> available after allocation
2026-05-11 13:44:06,400 INFO org.apache.hadoop.yarn.server.resourcemanager.scheduler.capacity.ParentQueue: assignedContainer queue=root usedCapacity=0.375 absoluteUsedCapacity=0.375 used=<memory:3072, vCores:2> cluster=<memory:8192, vCores:8>
2026-05-11 13:44:07,406 INFO org.apache.hadoop.yarn.server.resourcemanager.rmcontainer.RMContainerImpl: container_1778475288188_0004_01_000002 Container Transitioned from ALLOCATED to ACQUIRED
2026-05-11 13:44:08,433 INFO org.apache.hadoop.yarn.server.resourcemanager.rmcontainer.RMContainerImpl: container_1778475288188_0004_01_000002 Container Transitioned from ACQUIRED to RUNNING
2026-05-11 13:44:08,456 INFO org.apache.hadoop.yarn.server.resourcemanager.scheduler.AppSchedulingInfo: checking for deactivate of application :application_1778475288188_0004
2026-05-11 13:44:10,269 INFO org.apache.hadoop.yarn.server.resourcemanager.rmcontainer.RMContainerImpl: container_1778475288188_0004_01_000002 Container Transitioned from RUNNING to COMPLETED
2026-05-11 13:44:12,275 INFO org.apache.hadoop.yarn.server.resourcemanager.scheduler.capacity.allocator.AbstractContainerAllocator: assignedContainer application attempt=appattempt_1778475288188_0004_000001 container=null queue=default clusterResource=<memory:8192, vCores:8> type=OFF_SWITCH requestedPartition=
2026-05-11 13:44:12,275 INFO org.apache.hadoop.yarn.server.resourcemanager.rmcontainer.RMContainerImpl: container_1778475288188_0004_01_000003 Container Transitioned from NEW to ALLOCATED
2026-05-11 13:44:12,275 INFO org.apache.hadoop.yarn.server.resourcemanager.scheduler.common.fica.FiCaSchedulerNode: Assigned container container_1778475288188_0004_01_000003 of capacity <memory:1024, vCores:1> on host ubuntu:45565, which has 2 containers, <memory:3072, vCores:2> used and <memory:5120, vCores:6> available after allocation
2026-05-11 13:44:12,276 INFO org.apache.hadoop.yarn.server.resourcemanager.scheduler.capacity.ParentQueue: assignedContainer queue=root usedCapacity=0.375 absoluteUsedCapacity=0.375 used=<memory:3072, vCores:2> cluster=<memory:8192, vCores:8>
2026-05-11 13:44:12,491 INFO org.apache.hadoop.yarn.server.resourcemanager.rmcontainer.RMContainerImpl: container_1778475288188_0004_01_000003 Container Transitioned from ALLOCATED to ACQUIRED
2026-05-11 13:44:13,276 INFO org.apache.hadoop.yarn.server.resourcemanager.rmcontainer.RMContainerImpl: container_1778475288188_0004_01_000003 Container Transitioned from ACQUIRED to RUNNING
2026-05-11 13:44:13,496 INFO org.apache.hadoop.yarn.server.resourcemanager.scheduler.AppSchedulingInfo: checking for deactivate of application :application_1778475288188_0004
2026-05-11 13:44:15,094 INFO org.apache.hadoop.yarn.server.resourcemanager.rmcontainer.RMContainerImpl: container_1778475288188_0004_01_000003 Container Transitioned from RUNNING to COMPLETED
2026-05-11 13:44:15,287 INFO org.apache.hadoop.yarn.server.resourcemanager.rmapp.attempt.RMAppAttemptImpl: Updating application attempt appattempt_1778475288188_0004_000001 with final state: FINISHING, and exit status: -1000
2026-05-11 13:44:15,287 INFO org.apache.hadoop.yarn.server.resourcemanager.rmapp.attempt.RMAppAttemptImpl: appattempt_1778475288188_0004_000001 State change from RUNNING to FINAL_SAVING on event = UNREGISTERED
2026-05-11 13:44:15,287 INFO org.apache.hadoop.yarn.server.resourcemanager.rmapp.RMAppImpl: Updating application application_1778475288188_0004 with final state: FINISHING
2026-05-11 13:44:15,287 INFO org.apache.hadoop.yarn.server.resourcemanager.rmapp.RMAppImpl: application_1778475288188_0004 State change from RUNNING to FINAL_SAVING on event = ATTEMPT_UNREGISTERED
2026-05-11 13:44:15,289 INFO org.apache.hadoop.yarn.server.resourcemanager.recovery.RMStateStore: Updating info for app: application_1778475288188_0004
2026-05-11 13:44:15,289 INFO org.apache.hadoop.yarn.server.resourcemanager.rmapp.attempt.RMAppAttemptImpl: appattempt_1778475288188_0004_000001 State change from FINAL_SAVING to FINISHING on event = ATTEMPT_UPDATE_SAVED
2026-05-11 13:44:15,289 INFO org.apache.hadoop.yarn.server.resourcemanager.rmapp.RMAppImpl: application_1778475288188_0004 State change from FINAL_SAVING to FINISHING on event = APP_UPDATE_SAVED
2026-05-11 13:44:16,290 INFO org.apache.hadoop.yarn.server.resourcemanager.ApplicationMasterService: application_1778475288188_0004 unregistered successfully. 
2026-05-11 13:44:21,752 INFO org.apache.hadoop.yarn.server.resourcemanager.rmcontainer.RMContainerImpl: container_1778475288188_0004_01_000001 Container Transitioned from RUNNING to COMPLETED
2026-05-11 13:44:21,754 INFO org.apache.hadoop.yarn.server.resourcemanager.ApplicationMasterService: Unregistering app attempt : appattempt_1778475288188_0004_000001
2026-05-11 13:44:21,755 INFO org.apache.hadoop.yarn.server.resourcemanager.security.AMRMTokenSecretManager: Application finished, removing password for appattempt_1778475288188_0004_000001
2026-05-11 13:44:21,755 INFO org.apache.hadoop.yarn.server.resourcemanager.rmapp.attempt.RMAppAttemptImpl: appattempt_1778475288188_0004_000001 State change from FINISHING to FINISHED on event = CONTAINER_FINISHED
2026-05-11 13:44:21,756 INFO org.apache.hadoop.yarn.server.resourcemanager.rmapp.RMAppImpl: application_1778475288188_0004 State change from FINISHING to FINISHED on event = ATTEMPT_FINISHED
2026-05-11 13:44:21,757 INFO org.apache.hadoop.yarn.server.resourcemanager.RMAppManager$ApplicationSummary: appId=application_1778475288188_0004,name=SELECT behavior\, COUNT(*) AS cnt FROM...DESC (Stage-2),user=cty1576,queue=default,state=FINISHED,trackingUrl=http://ubuntu:8088/proxy/application_1778475288188_0004/,appMasterHost=ubuntu,submitTime=1778478237266,startTime=1778478237266,launchTime=1778478241451,finishTime=1778478255287,finalStatus=SUCCEEDED,memorySeconds=48553,vcoreSeconds=25,preemptedMemorySeconds=0,preemptedVcoreSeconds=0,preemptedAMContainers=0,preemptedNonAMContainers=0,preemptedResources=<memory:0\, vCores:0>,applicationType=MAPREDUCE,resourceSeconds=48553 MB-seconds\, 25 vcore-seconds,preemptedResourceSeconds=0 MB-seconds\, 0 vcore-seconds,applicationTags=,applicationNodeLabel=,diagnostics=,totalAllocatedContainers=3
2026-05-11 13:44:21,761 INFO org.apache.hadoop.yarn.server.resourcemanager.scheduler.capacity.CapacityScheduler: Application Attempt appattempt_1778475288188_0004_000001 is done. finalState=FINISHED
2026-05-11 13:44:21,762 INFO org.apache.hadoop.yarn.server.resourcemanager.scheduler.AppSchedulingInfo: Application application_1778475288188_0004 requests cleared
2026-05-11 13:44:21,762 INFO org.apache.hadoop.yarn.server.resourcemanager.scheduler.capacity.LeafQueue: Application removed - appId: application_1778475288188_0004 user: cty1576 queue: root.default #user-pending-applications: 0 #user-active-applications: 0 #queue-pending-applications: 0 #queue-active-applications: 0
2026-05-11 13:44:21,762 INFO org.apache.hadoop.yarn.server.resourcemanager.scheduler.capacity.ParentQueue: Application removed - appId: application_1778475288188_0004 user: cty1576 leaf-queue of parent: root #applications: 0
2026-05-11 13:44:21,762 INFO org.apache.hadoop.yarn.server.resourcemanager.amlauncher.AMLauncher: Cleaning master appattempt_1778475288188_0004_000001
2026-05-11 13:44:23,835 INFO org.apache.hadoop.yarn.server.resourcemanager.ClientRMService: Allocated new applicationId: 5
2026-05-11 13:44:25,251 INFO org.apache.hadoop.yarn.server.resourcemanager.scheduler.capacity.CapacityScheduler: Application 'application_1778475288188_0005' is submitted without priority hence considering default queue/cluster priority: 0
2026-05-11 13:44:25,251 INFO org.apache.hadoop.yarn.server.resourcemanager.scheduler.capacity.CapacityScheduler: Priority '0' is acceptable in queue : default for application: application_1778475288188_0005
2026-05-11 13:44:25,252 INFO org.apache.hadoop.yarn.server.resourcemanager.ClientRMService: Application with id 5 submitted by user cty1576
2026-05-11 13:44:25,253 INFO org.apache.hadoop.yarn.server.resourcemanager.rmapp.RMAppImpl: Storing application with id application_1778475288188_0005
2026-05-11 13:44:25,254 INFO org.apache.hadoop.yarn.server.resourcemanager.recovery.RMStateStore: Storing info for app: application_1778475288188_0005
2026-05-11 13:44:25,254 INFO org.apache.hadoop.yarn.server.resourcemanager.rmapp.RMAppImpl: application_1778475288188_0005 State change from NEW to NEW_SAVING on event = START
2026-05-11 13:44:25,254 INFO org.apache.hadoop.yarn.server.resourcemanager.rmapp.RMAppImpl: application_1778475288188_0005 State change from NEW_SAVING to SUBMITTED on event = APP_NEW_SAVED
2026-05-11 13:44:25,255 INFO org.apache.hadoop.yarn.server.resourcemanager.scheduler.capacity.ParentQueue: Application added - appId: application_1778475288188_0005 user: cty1576 leaf-queue of parent: root #applications: 1
2026-05-11 13:44:25,255 INFO org.apache.hadoop.yarn.server.resourcemanager.scheduler.capacity.CapacityScheduler: Accepted application application_1778475288188_0005 from user: cty1576, in queue: default
2026-05-11 13:44:25,258 INFO org.apache.hadoop.yarn.server.resourcemanager.rmapp.RMAppImpl: application_1778475288188_0005 State change from SUBMITTED to ACCEPTED on event = APP_ACCEPTED
2026-05-11 13:44:25,260 INFO org.apache.hadoop.yarn.server.resourcemanager.ApplicationMasterService: Registering app attempt : appattempt_1778475288188_0005_000001
2026-05-11 13:44:25,260 INFO org.apache.hadoop.yarn.server.resourcemanager.rmapp.attempt.RMAppAttemptImpl: appattempt_1778475288188_0005_000001 State change from NEW to SUBMITTED on event = START
2026-05-11 13:44:25,260 WARN org.apache.hadoop.yarn.server.resourcemanager.scheduler.capacity.LeafQueue: maximum-am-resource-percent is insufficient to start a single application in queue, it is likely set too low. skipping enforcement to allow at least one application to start
2026-05-11 13:44:25,261 WARN org.apache.hadoop.yarn.server.resourcemanager.scheduler.capacity.LeafQueue: maximum-am-resource-percent is insufficient to start a single application in queue for user, it is likely set too low. skipping enforcement to allow at least one application to start
2026-05-11 13:44:25,261 INFO org.apache.hadoop.yarn.server.resourcemanager.scheduler.capacity.LeafQueue: Application application_1778475288188_0005 from user: cty1576 activated in queue: root.default
2026-05-11 13:44:25,261 INFO org.apache.hadoop.yarn.server.resourcemanager.scheduler.capacity.LeafQueue: Application added - appId: application_1778475288188_0005 user: cty1576, leaf-queue: root.default #user-pending-applications: 0 #user-active-applications: 1 #queue-pending-applications: 0 #queue-active-applications: 1 #queue-nonrunnable-applications: 0
2026-05-11 13:44:25,261 INFO org.apache.hadoop.yarn.server.resourcemanager.scheduler.capacity.CapacityScheduler: Added Application Attempt appattempt_1778475288188_0005_000001 to scheduler from user cty1576 in queue root.default
2026-05-11 13:44:25,264 INFO org.apache.hadoop.yarn.server.resourcemanager.rmapp.attempt.RMAppAttemptImpl: appattempt_1778475288188_0005_000001 State change from SUBMITTED to SCHEDULED on event = ATTEMPT_ADDED
2026-05-11 13:44:25,765 INFO org.apache.hadoop.yarn.server.resourcemanager.scheduler.capacity.allocator.AbstractContainerAllocator: assignedContainer application attempt=appattempt_1778475288188_0005_000001 container=null queue=default clusterResource=<memory:8192, vCores:8> type=OFF_SWITCH requestedPartition=
2026-05-11 13:44:25,765 INFO org.apache.hadoop.yarn.server.resourcemanager.rmcontainer.RMContainerImpl: container_1778475288188_0005_01_000001 Container Transitioned from NEW to ALLOCATED
2026-05-11 13:44:25,765 INFO org.apache.hadoop.yarn.server.resourcemanager.scheduler.common.fica.FiCaSchedulerNode: Assigned container container_1778475288188_0005_01_000001 of capacity <memory:2048, vCores:1> on host ubuntu:45565, which has 1 containers, <memory:2048, vCores:1> used and <memory:6144, vCores:7> available after allocation
2026-05-11 13:44:25,766 INFO org.apache.hadoop.yarn.server.resourcemanager.scheduler.capacity.ParentQueue: assignedContainer queue=root usedCapacity=0.25 absoluteUsedCapacity=0.25 used=<memory:2048, vCores:1> cluster=<memory:8192, vCores:8>
2026-05-11 13:44:25,767 INFO org.apache.hadoop.yarn.server.resourcemanager.rmcontainer.RMContainerImpl: container_1778475288188_0005_01_000001 Container Transitioned from ALLOCATED to ACQUIRED
2026-05-11 13:44:25,767 INFO org.apache.hadoop.yarn.server.resourcemanager.security.NMTokenSecretManagerInRM: Clear node set for appattempt_1778475288188_0005_000001
2026-05-11 13:44:25,767 INFO org.apache.hadoop.yarn.server.resourcemanager.rmapp.attempt.RMAppAttemptImpl: Storing attempt: AppId: application_1778475288188_0005 AttemptId: appattempt_1778475288188_0005_000001 MasterContainer: Container: [ContainerId: container_1778475288188_0005_01_000001, AllocationRequestId: -1, Version: 0, NodeId: ubuntu:45565, NodeHttpAddress: ubuntu:8042, Resource: <memory:2048, vCores:1>, Priority: 0, Token: Token { kind: ContainerToken, service: 127.0.1.1:45565 }, ExecutionType: GUARANTEED, ]
2026-05-11 13:44:25,768 INFO org.apache.hadoop.yarn.server.resourcemanager.rmapp.attempt.RMAppAttemptImpl: appattempt_1778475288188_0005_000001 State change from SCHEDULED to ALLOCATED_SAVING on event = CONTAINER_ALLOCATED
2026-05-11 13:44:25,768 INFO org.apache.hadoop.yarn.server.resourcemanager.rmapp.attempt.RMAppAttemptImpl: appattempt_1778475288188_0005_000001 State change from ALLOCATED_SAVING to ALLOCATED on event = ATTEMPT_NEW_SAVED
2026-05-11 13:44:25,769 INFO org.apache.hadoop.yarn.server.resourcemanager.amlauncher.AMLauncher: Launching masterappattempt_1778475288188_0005_000001
2026-05-11 13:44:25,771 INFO org.apache.hadoop.yarn.server.resourcemanager.amlauncher.AMLauncher: Setting up container Container: [ContainerId: container_1778475288188_0005_01_000001, AllocationRequestId: -1, Version: 0, NodeId: ubuntu:45565, NodeHttpAddress: ubuntu:8042, Resource: <memory:2048, vCores:1>, Priority: 0, Token: Token { kind: ContainerToken, service: 127.0.1.1:45565 }, ExecutionType: GUARANTEED, ] for AM appattempt_1778475288188_0005_000001
2026-05-11 13:44:25,772 INFO org.apache.hadoop.yarn.server.resourcemanager.security.AMRMTokenSecretManager: Create AMRMToken for ApplicationAttempt: appattempt_1778475288188_0005_000001
2026-05-11 13:44:25,772 INFO org.apache.hadoop.yarn.server.resourcemanager.security.AMRMTokenSecretManager: Creating password for appattempt_1778475288188_0005_000001
2026-05-11 13:44:25,786 INFO org.apache.hadoop.yarn.server.resourcemanager.amlauncher.AMLauncher: Done launching container Container: [ContainerId: container_1778475288188_0005_01_000001, AllocationRequestId: -1, Version: 0, NodeId: ubuntu:45565, NodeHttpAddress: ubuntu:8042, Resource: <memory:2048, vCores:1>, Priority: 0, Token: Token { kind: ContainerToken, service: 127.0.1.1:45565 }, ExecutionType: GUARANTEED, ] for AM appattempt_1778475288188_0005_000001
2026-05-11 13:44:25,786 INFO org.apache.hadoop.yarn.server.resourcemanager.rmapp.attempt.RMAppAttemptImpl: appattempt_1778475288188_0005_000001 State change from ALLOCATED to LAUNCHED on event = LAUNCHED
2026-05-11 13:44:25,786 INFO org.apache.hadoop.yarn.server.resourcemanager.rmapp.RMAppImpl: update the launch time for applicationId: application_1778475288188_0005, attemptId: appattempt_1778475288188_0005_000001launchTime: 1778478265786
2026-05-11 13:44:25,787 INFO org.apache.hadoop.yarn.server.resourcemanager.recovery.RMStateStore: Updating info for app: application_1778475288188_0005
2026-05-11 13:44:26,767 INFO org.apache.hadoop.yarn.server.resourcemanager.rmcontainer.RMContainerImpl: container_1778475288188_0005_01_000001 Container Transitioned from ACQUIRED to RUNNING
2026-05-11 13:44:30,318 INFO SecurityLogger.org.apache.hadoop.ipc.Server: Auth successful for appattempt_1778475288188_0005_000001 (auth:SIMPLE) from 127.0.0.1:60178
2026-05-11 13:44:30,320 INFO org.apache.hadoop.yarn.server.resourcemanager.DefaultAMSProcessor: AM registration appattempt_1778475288188_0005_000001
2026-05-11 13:44:30,321 INFO org.apache.hadoop.yarn.server.resourcemanager.rmapp.attempt.RMAppAttemptImpl: appattempt_1778475288188_0005_000001 State change from LAUNCHED to RUNNING on event = REGISTERED
2026-05-11 13:44:30,321 INFO org.apache.hadoop.yarn.server.resourcemanager.rmapp.RMAppImpl: application_1778475288188_0005 State change from ACCEPTED to RUNNING on event = ATTEMPT_REGISTERED
2026-05-11 13:44:31,780 INFO org.apache.hadoop.yarn.server.resourcemanager.scheduler.capacity.allocator.AbstractContainerAllocator: assignedContainer application attempt=appattempt_1778475288188_0005_000001 container=null queue=default clusterResource=<memory:8192, vCores:8> type=NODE_LOCAL requestedPartition=
2026-05-11 13:44:31,780 INFO org.apache.hadoop.yarn.server.resourcemanager.rmcontainer.RMContainerImpl: container_1778475288188_0005_01_000002 Container Transitioned from NEW to ALLOCATED
2026-05-11 13:44:31,780 INFO org.apache.hadoop.yarn.server.resourcemanager.scheduler.common.fica.FiCaSchedulerNode: Assigned container container_1778475288188_0005_01_000002 of capacity <memory:1024, vCores:1> on host ubuntu:45565, which has 2 containers, <memory:3072, vCores:2> used and <memory:5120, vCores:6> available after allocation
2026-05-11 13:44:31,780 INFO org.apache.hadoop.yarn.server.resourcemanager.scheduler.capacity.ParentQueue: assignedContainer queue=root usedCapacity=0.375 absoluteUsedCapacity=0.375 used=<memory:3072, vCores:2> cluster=<memory:8192, vCores:8>
2026-05-11 13:44:31,780 INFO org.apache.hadoop.yarn.server.resourcemanager.scheduler.capacity.allocator.AbstractContainerAllocator: assignedContainer application attempt=appattempt_1778475288188_0005_000001 container=null queue=default clusterResource=<memory:8192, vCores:8> type=NODE_LOCAL requestedPartition=
2026-05-11 13:44:31,781 INFO org.apache.hadoop.yarn.server.resourcemanager.rmcontainer.RMContainerImpl: container_1778475288188_0005_01_000003 Container Transitioned from NEW to ALLOCATED
2026-05-11 13:44:31,781 INFO org.apache.hadoop.yarn.server.resourcemanager.scheduler.common.fica.FiCaSchedulerNode: Assigned container container_1778475288188_0005_01_000003 of capacity <memory:1024, vCores:1> on host ubuntu:45565, which has 3 containers, <memory:4096, vCores:3> used and <memory:4096, vCores:5> available after allocation
2026-05-11 13:44:31,781 INFO org.apache.hadoop.yarn.server.resourcemanager.scheduler.capacity.ParentQueue: assignedContainer queue=root usedCapacity=0.5 absoluteUsedCapacity=0.5 used=<memory:4096, vCores:3> cluster=<memory:8192, vCores:8>
2026-05-11 13:44:31,781 INFO org.apache.hadoop.yarn.server.resourcemanager.scheduler.capacity.allocator.AbstractContainerAllocator: assignedContainer application attempt=appattempt_1778475288188_0005_000001 container=null queue=default clusterResource=<memory:8192, vCores:8> type=OFF_SWITCH requestedPartition=
2026-05-11 13:44:31,781 INFO org.apache.hadoop.yarn.server.resourcemanager.rmcontainer.RMContainerImpl: container_1778475288188_0005_01_000004 Container Transitioned from NEW to ALLOCATED
2026-05-11 13:44:31,781 INFO org.apache.hadoop.yarn.server.resourcemanager.scheduler.common.fica.FiCaSchedulerNode: Assigned container container_1778475288188_0005_01_000004 of capacity <memory:1024, vCores:1> on host ubuntu:45565, which has 4 containers, <memory:5120, vCores:4> used and <memory:3072, vCores:4> available after allocation
2026-05-11 13:44:31,781 INFO org.apache.hadoop.yarn.server.resourcemanager.scheduler.capacity.ParentQueue: assignedContainer queue=root usedCapacity=0.625 absoluteUsedCapacity=0.625 used=<memory:5120, vCores:4> cluster=<memory:8192, vCores:8>
2026-05-11 13:44:32,381 INFO org.apache.hadoop.yarn.server.resourcemanager.rmcontainer.RMContainerImpl: container_1778475288188_0005_01_000002 Container Transitioned from ALLOCATED to ACQUIRED
2026-05-11 13:44:32,388 INFO org.apache.hadoop.yarn.server.resourcemanager.rmcontainer.RMContainerImpl: container_1778475288188_0005_01_000003 Container Transitioned from ALLOCATED to ACQUIRED
2026-05-11 13:44:32,390 INFO org.apache.hadoop.yarn.server.resourcemanager.rmcontainer.RMContainerImpl: container_1778475288188_0005_01_000004 Container Transitioned from ALLOCATED to ACQUIRED
2026-05-11 13:44:32,780 INFO org.apache.hadoop.yarn.server.resourcemanager.rmcontainer.RMContainerImpl: container_1778475288188_0005_01_000002 Container Transitioned from ACQUIRED to RUNNING
2026-05-11 13:44:32,783 INFO org.apache.hadoop.yarn.server.resourcemanager.rmcontainer.RMContainerImpl: container_1778475288188_0005_01_000003 Container Transitioned from ACQUIRED to RUNNING
2026-05-11 13:44:32,785 INFO org.apache.hadoop.yarn.server.resourcemanager.rmcontainer.RMContainerImpl: container_1778475288188_0005_01_000004 Container Transitioned from ACQUIRED to RUNNING
2026-05-11 13:44:33,423 INFO org.apache.hadoop.yarn.server.resourcemanager.scheduler.AppSchedulingInfo: checking for deactivate of application :application_1778475288188_0005
2026-05-11 13:44:47,347 INFO org.apache.hadoop.yarn.server.resourcemanager.rmcontainer.RMContainerImpl: container_1778475288188_0005_01_000004 Container Transitioned from RUNNING to COMPLETED
2026-05-11 13:44:49,354 INFO org.apache.hadoop.yarn.server.resourcemanager.scheduler.capacity.allocator.AbstractContainerAllocator: assignedContainer application attempt=appattempt_1778475288188_0005_000001 container=null queue=default clusterResource=<memory:8192, vCores:8> type=OFF_SWITCH requestedPartition=
2026-05-11 13:44:49,357 INFO org.apache.hadoop.yarn.server.resourcemanager.rmcontainer.RMContainerImpl: container_1778475288188_0005_01_000005 Container Transitioned from NEW to ALLOCATED
2026-05-11 13:44:49,357 INFO org.apache.hadoop.yarn.server.resourcemanager.scheduler.common.fica.FiCaSchedulerNode: Assigned container container_1778475288188_0005_01_000005 of capacity <memory:1024, vCores:1> on host ubuntu:45565, which has 4 containers, <memory:5120, vCores:4> used and <memory:3072, vCores:4> available after allocation
2026-05-11 13:44:49,357 INFO org.apache.hadoop.yarn.server.resourcemanager.scheduler.capacity.ParentQueue: assignedContainer queue=root usedCapacity=0.625 absoluteUsedCapacity=0.625 used=<memory:5120, vCores:4> cluster=<memory:8192, vCores:8>
2026-05-11 13:44:49,598 INFO org.apache.hadoop.yarn.server.resourcemanager.rmcontainer.RMContainerImpl: container_1778475288188_0005_01_000005 Container Transitioned from ALLOCATED to ACQUIRED
2026-05-11 13:44:50,355 INFO org.apache.hadoop.yarn.server.resourcemanager.rmcontainer.RMContainerImpl: container_1778475288188_0005_01_000005 Container Transitioned from ACQUIRED to RUNNING
2026-05-11 13:44:50,356 INFO org.apache.hadoop.yarn.server.resourcemanager.scheduler.capacity.allocator.AbstractContainerAllocator: assignedContainer application attempt=appattempt_1778475288188_0005_000001 container=null queue=default clusterResource=<memory:8192, vCores:8> type=NODE_LOCAL requestedPartition=
2026-05-11 13:44:50,356 INFO org.apache.hadoop.yarn.server.resourcemanager.rmcontainer.RMContainerImpl: container_1778475288188_0005_01_000006 Container Transitioned from NEW to ALLOCATED
2026-05-11 13:44:50,356 INFO org.apache.hadoop.yarn.server.resourcemanager.scheduler.common.fica.FiCaSchedulerNode: Assigned container container_1778475288188_0005_01_000006 of capacity <memory:1024, vCores:1> on host ubuntu:45565, which has 5 containers, <memory:6144, vCores:5> used and <memory:2048, vCores:3> available after allocation
2026-05-11 13:44:50,356 INFO org.apache.hadoop.yarn.server.resourcemanager.scheduler.capacity.ParentQueue: assignedContainer queue=root usedCapacity=0.75 absoluteUsedCapacity=0.75 used=<memory:6144, vCores:5> cluster=<memory:8192, vCores:8>
2026-05-11 13:44:50,607 INFO org.apache.hadoop.yarn.server.resourcemanager.scheduler.AppSchedulingInfo: checking for deactivate of application :application_1778475288188_0005
2026-05-11 13:44:50,611 INFO org.apache.hadoop.yarn.server.resourcemanager.rmcontainer.RMContainerImpl: container_1778475288188_0005_01_000006 Container Transitioned from ALLOCATED to ACQUIRED
2026-05-11 13:44:51,358 INFO org.apache.hadoop.yarn.server.resourcemanager.rmcontainer.RMContainerImpl: container_1778475288188_0005_01_000006 Container Transitioned from ACQUIRED to RUNNING
2026-05-11 13:44:51,617 INFO org.apache.hadoop.yarn.server.resourcemanager.scheduler.AppSchedulingInfo: checking for deactivate of application :application_1778475288188_0005
2026-05-11 13:45:05,434 INFO org.apache.hadoop.yarn.server.resourcemanager.scheduler.capacity.allocator.AbstractContainerAllocator: assignedContainer application attempt=appattempt_1778475288188_0005_000001 container=null queue=default clusterResource=<memory:8192, vCores:8> type=NODE_LOCAL requestedPartition=
2026-05-11 13:45:05,435 INFO org.apache.hadoop.yarn.server.resourcemanager.rmcontainer.RMContainerImpl: container_1778475288188_0005_01_000007 Container Transitioned from NEW to ALLOCATED
2026-05-11 13:45:05,437 INFO org.apache.hadoop.yarn.server.resourcemanager.scheduler.common.fica.FiCaSchedulerNode: Assigned container container_1778475288188_0005_01_000007 of capacity <memory:1024, vCores:1> on host ubuntu:45565, which has 6 containers, <memory:7168, vCores:6> used and <memory:1024, vCores:2> available after allocation
2026-05-11 13:45:05,440 INFO org.apache.hadoop.yarn.server.resourcemanager.scheduler.capacity.ParentQueue: assignedContainer queue=root usedCapacity=0.875 absoluteUsedCapacity=0.875 used=<memory:7168, vCores:6> cluster=<memory:8192, vCores:8>
2026-05-11 13:45:05,727 INFO org.apache.hadoop.yarn.server.resourcemanager.rmcontainer.RMContainerImpl: container_1778475288188_0005_01_000007 Container Transitioned from ALLOCATED to ACQUIRED
2026-05-11 13:45:06,430 INFO org.apache.hadoop.yarn.server.resourcemanager.rmcontainer.RMContainerImpl: container_1778475288188_0005_01_000007 Container Transitioned from ACQUIRED to RUNNING
2026-05-11 13:45:06,737 INFO org.apache.hadoop.yarn.server.resourcemanager.scheduler.AppSchedulingInfo: checking for deactivate of application :application_1778475288188_0005
2026-05-11 13:45:18,763 INFO org.apache.hadoop.yarn.server.resourcemanager.rmcontainer.RMContainerImpl: container_1778475288188_0005_01_000006 Container Transitioned from RUNNING to COMPLETED
2026-05-11 13:45:19,204 INFO org.apache.hadoop.yarn.server.resourcemanager.rmcontainer.RMContainerImpl: container_1778475288188_0005_01_000002 Container Transitioned from RUNNING to COMPLETED
2026-05-11 13:45:19,450 INFO org.apache.hadoop.yarn.server.resourcemanager.rmcontainer.RMContainerImpl: container_1778475288188_0005_01_000007 Container Transitioned from RUNNING to COMPLETED
2026-05-11 13:45:19,848 INFO org.apache.hadoop.yarn.server.resourcemanager.rmcontainer.RMContainerImpl: container_1778475288188_0005_01_000003 Container Transitioned from RUNNING to COMPLETED
2026-05-11 13:45:27,163 INFO org.apache.hadoop.yarn.server.resourcemanager.rmapp.attempt.RMAppAttemptImpl: Updating application attempt appattempt_1778475288188_0005_000001 with final state: FINISHING, and exit status: -1000
2026-05-11 13:45:27,163 INFO org.apache.hadoop.yarn.server.resourcemanager.rmapp.attempt.RMAppAttemptImpl: appattempt_1778475288188_0005_000001 State change from RUNNING to FINAL_SAVING on event = UNREGISTERED
2026-05-11 13:45:27,163 INFO org.apache.hadoop.yarn.server.resourcemanager.rmapp.RMAppImpl: Updating application application_1778475288188_0005 with final state: FINISHING
2026-05-11 13:45:27,163 INFO org.apache.hadoop.yarn.server.resourcemanager.recovery.RMStateStore: Updating info for app: application_1778475288188_0005
2026-05-11 13:45:27,163 INFO org.apache.hadoop.yarn.server.resourcemanager.rmapp.RMAppImpl: application_1778475288188_0005 State change from RUNNING to FINAL_SAVING on event = ATTEMPT_UNREGISTERED
2026-05-11 13:45:27,163 INFO org.apache.hadoop.yarn.server.resourcemanager.rmapp.attempt.RMAppAttemptImpl: appattempt_1778475288188_0005_000001 State change from FINAL_SAVING to FINISHING on event = ATTEMPT_UPDATE_SAVED
2026-05-11 13:45:27,166 INFO org.apache.hadoop.yarn.server.resourcemanager.rmapp.RMAppImpl: application_1778475288188_0005 State change from FINAL_SAVING to FINISHING on event = APP_UPDATE_SAVED
2026-05-11 13:45:27,170 INFO org.apache.hadoop.yarn.server.resourcemanager.rmcontainer.RMContainerImpl: container_1778475288188_0005_01_000005 Container Transitioned from RUNNING to COMPLETED
2026-05-11 13:45:28,167 INFO org.apache.hadoop.yarn.server.resourcemanager.ApplicationMasterService: application_1778475288188_0005 unregistered successfully. 
2026-05-11 13:45:33,585 INFO org.apache.hadoop.yarn.server.resourcemanager.rmcontainer.RMContainerImpl: container_1778475288188_0005_01_000001 Container Transitioned from RUNNING to COMPLETED
2026-05-11 13:45:33,585 INFO org.apache.hadoop.yarn.server.resourcemanager.ApplicationMasterService: Unregistering app attempt : appattempt_1778475288188_0005_000001
2026-05-11 13:45:33,585 INFO org.apache.hadoop.yarn.server.resourcemanager.security.AMRMTokenSecretManager: Application finished, removing password for appattempt_1778475288188_0005_000001
2026-05-11 13:45:33,585 INFO org.apache.hadoop.yarn.server.resourcemanager.rmapp.attempt.RMAppAttemptImpl: appattempt_1778475288188_0005_000001 State change from FINISHING to FINISHED on event = CONTAINER_FINISHED
2026-05-11 13:45:33,586 INFO org.apache.hadoop.yarn.server.resourcemanager.rmapp.RMAppImpl: application_1778475288188_0005 State change from FINISHING to FINISHED on event = ATTEMPT_FINISHED
2026-05-11 13:45:33,588 INFO org.apache.hadoop.yarn.server.resourcemanager.scheduler.capacity.CapacityScheduler: Application Attempt appattempt_1778475288188_0005_000001 is done. finalState=FINISHED
2026-05-11 13:45:33,590 INFO org.apache.hadoop.yarn.server.resourcemanager.scheduler.AppSchedulingInfo: Application application_1778475288188_0005 requests cleared
2026-05-11 13:45:33,590 INFO org.apache.hadoop.yarn.server.resourcemanager.scheduler.capacity.LeafQueue: Application removed - appId: application_1778475288188_0005 user: cty1576 queue: root.default #user-pending-applications: 0 #user-active-applications: 0 #queue-pending-applications: 0 #queue-active-applications: 0
2026-05-11 13:45:33,594 INFO org.apache.hadoop.yarn.server.resourcemanager.scheduler.capacity.ParentQueue: Application removed - appId: application_1778475288188_0005 user: cty1576 leaf-queue of parent: root #applications: 0
2026-05-11 13:45:33,594 INFO org.apache.hadoop.yarn.server.resourcemanager.amlauncher.AMLauncher: Cleaning master appattempt_1778475288188_0005_000001
2026-05-11 13:45:33,595 INFO org.apache.hadoop.yarn.server.resourcemanager.RMAppManager$ApplicationSummary: appId=application_1778475288188_0005,name=SELECT COUNT(DISTINCT...user_behavior_detail (Stage-1),user=cty1576,queue=default,state=FINISHED,trackingUrl=http://ubuntu:8088/proxy/application_1778475288188_0005/,appMasterHost=ubuntu,submitTime=1778478265251,startTime=1778478265252,launchTime=1778478265786,finishTime=1778478327163,finalStatus=SUCCEEDED,memorySeconds=334788,vcoreSeconds=256,preemptedMemorySeconds=0,preemptedVcoreSeconds=0,preemptedAMContainers=0,preemptedNonAMContainers=0,preemptedResources=<memory:0\, vCores:0>,applicationType=MAPREDUCE,resourceSeconds=334788 MB-seconds\, 256 vcore-seconds,preemptedResourceSeconds=0 MB-seconds\, 0 vcore-seconds,applicationTags=,applicationNodeLabel=,diagnostics=,totalAllocatedContainers=7
2026-05-11 13:45:35,956 INFO org.apache.hadoop.yarn.server.resourcemanager.ClientRMService: Allocated new applicationId: 6
2026-05-11 13:45:36,794 INFO org.apache.hadoop.yarn.server.resourcemanager.scheduler.capacity.CapacityScheduler: Application 'application_1778475288188_0006' is submitted without priority hence considering default queue/cluster priority: 0
2026-05-11 13:45:36,794 INFO org.apache.hadoop.yarn.server.resourcemanager.scheduler.capacity.CapacityScheduler: Priority '0' is acceptable in queue : default for application: application_1778475288188_0006
2026-05-11 13:45:36,794 INFO org.apache.hadoop.yarn.server.resourcemanager.ClientRMService: Application with id 6 submitted by user cty1576
2026-05-11 13:45:36,795 INFO org.apache.hadoop.yarn.server.resourcemanager.rmapp.RMAppImpl: Storing application with id application_1778475288188_0006
2026-05-11 13:45:36,795 INFO org.apache.hadoop.yarn.server.resourcemanager.rmapp.RMAppImpl: application_1778475288188_0006 State change from NEW to NEW_SAVING on event = START
2026-05-11 13:45:36,795 INFO org.apache.hadoop.yarn.server.resourcemanager.recovery.RMStateStore: Storing info for app: application_1778475288188_0006
2026-05-11 13:45:36,795 INFO org.apache.hadoop.yarn.server.resourcemanager.rmapp.RMAppImpl: application_1778475288188_0006 State change from NEW_SAVING to SUBMITTED on event = APP_NEW_SAVED
2026-05-11 13:45:36,795 INFO org.apache.hadoop.yarn.server.resourcemanager.scheduler.capacity.ParentQueue: Application added - appId: application_1778475288188_0006 user: cty1576 leaf-queue of parent: root #applications: 1
2026-05-11 13:45:36,795 INFO org.apache.hadoop.yarn.server.resourcemanager.scheduler.capacity.CapacityScheduler: Accepted application application_1778475288188_0006 from user: cty1576, in queue: default
2026-05-11 13:45:36,796 INFO org.apache.hadoop.yarn.server.resourcemanager.rmapp.RMAppImpl: application_1778475288188_0006 State change from SUBMITTED to ACCEPTED on event = APP_ACCEPTED
2026-05-11 13:45:36,796 INFO org.apache.hadoop.yarn.server.resourcemanager.ApplicationMasterService: Registering app attempt : appattempt_1778475288188_0006_000001
2026-05-11 13:45:36,796 INFO org.apache.hadoop.yarn.server.resourcemanager.rmapp.attempt.RMAppAttemptImpl: appattempt_1778475288188_0006_000001 State change from NEW to SUBMITTED on event = START
2026-05-11 13:45:36,799 WARN org.apache.hadoop.yarn.server.resourcemanager.scheduler.capacity.LeafQueue: maximum-am-resource-percent is insufficient to start a single application in queue, it is likely set too low. skipping enforcement to allow at least one application to start
2026-05-11 13:45:36,799 WARN org.apache.hadoop.yarn.server.resourcemanager.scheduler.capacity.LeafQueue: maximum-am-resource-percent is insufficient to start a single application in queue for user, it is likely set too low. skipping enforcement to allow at least one application to start
2026-05-11 13:45:36,799 INFO org.apache.hadoop.yarn.server.resourcemanager.scheduler.capacity.LeafQueue: Application application_1778475288188_0006 from user: cty1576 activated in queue: root.default
2026-05-11 13:45:36,799 INFO org.apache.hadoop.yarn.server.resourcemanager.scheduler.capacity.LeafQueue: Application added - appId: application_1778475288188_0006 user: cty1576, leaf-queue: root.default #user-pending-applications: 0 #user-active-applications: 1 #queue-pending-applications: 0 #queue-active-applications: 1 #queue-nonrunnable-applications: 0
2026-05-11 13:45:36,799 INFO org.apache.hadoop.yarn.server.resourcemanager.scheduler.capacity.CapacityScheduler: Added Application Attempt appattempt_1778475288188_0006_000001 to scheduler from user cty1576 in queue root.default
2026-05-11 13:45:36,800 INFO org.apache.hadoop.yarn.server.resourcemanager.rmapp.attempt.RMAppAttemptImpl: appattempt_1778475288188_0006_000001 State change from SUBMITTED to SCHEDULED on event = ATTEMPT_ADDED
2026-05-11 13:45:37,601 INFO org.apache.hadoop.yarn.server.resourcemanager.scheduler.capacity.allocator.AbstractContainerAllocator: assignedContainer application attempt=appattempt_1778475288188_0006_000001 container=null queue=default clusterResource=<memory:8192, vCores:8> type=OFF_SWITCH requestedPartition=
2026-05-11 13:45:37,601 INFO org.apache.hadoop.yarn.server.resourcemanager.rmcontainer.RMContainerImpl: container_1778475288188_0006_01_000001 Container Transitioned from NEW to ALLOCATED
2026-05-11 13:45:37,601 INFO org.apache.hadoop.yarn.server.resourcemanager.scheduler.common.fica.FiCaSchedulerNode: Assigned container container_1778475288188_0006_01_000001 of capacity <memory:2048, vCores:1> on host ubuntu:45565, which has 1 containers, <memory:2048, vCores:1> used and <memory:6144, vCores:7> available after allocation
2026-05-11 13:45:37,601 INFO org.apache.hadoop.yarn.server.resourcemanager.scheduler.capacity.ParentQueue: assignedContainer queue=root usedCapacity=0.25 absoluteUsedCapacity=0.25 used=<memory:2048, vCores:1> cluster=<memory:8192, vCores:8>
2026-05-11 13:45:37,602 INFO org.apache.hadoop.yarn.server.resourcemanager.rmcontainer.RMContainerImpl: container_1778475288188_0006_01_000001 Container Transitioned from ALLOCATED to ACQUIRED
2026-05-11 13:45:37,603 INFO org.apache.hadoop.yarn.server.resourcemanager.security.NMTokenSecretManagerInRM: Clear node set for appattempt_1778475288188_0006_000001
2026-05-11 13:45:37,603 INFO org.apache.hadoop.yarn.server.resourcemanager.rmapp.attempt.RMAppAttemptImpl: Storing attempt: AppId: application_1778475288188_0006 AttemptId: appattempt_1778475288188_0006_000001 MasterContainer: Container: [ContainerId: container_1778475288188_0006_01_000001, AllocationRequestId: -1, Version: 0, NodeId: ubuntu:45565, NodeHttpAddress: ubuntu:8042, Resource: <memory:2048, vCores:1>, Priority: 0, Token: Token { kind: ContainerToken, service: 127.0.1.1:45565 }, ExecutionType: GUARANTEED, ]
2026-05-11 13:45:37,603 INFO org.apache.hadoop.yarn.server.resourcemanager.rmapp.attempt.RMAppAttemptImpl: appattempt_1778475288188_0006_000001 State change from SCHEDULED to ALLOCATED_SAVING on event = CONTAINER_ALLOCATED
2026-05-11 13:45:37,603 INFO org.apache.hadoop.yarn.server.resourcemanager.rmapp.attempt.RMAppAttemptImpl: appattempt_1778475288188_0006_000001 State change from ALLOCATED_SAVING to ALLOCATED on event = ATTEMPT_NEW_SAVED
2026-05-11 13:45:37,604 INFO org.apache.hadoop.yarn.server.resourcemanager.amlauncher.AMLauncher: Launching masterappattempt_1778475288188_0006_000001
2026-05-11 13:45:37,607 INFO org.apache.hadoop.yarn.server.resourcemanager.amlauncher.AMLauncher: Setting up container Container: [ContainerId: container_1778475288188_0006_01_000001, AllocationRequestId: -1, Version: 0, NodeId: ubuntu:45565, NodeHttpAddress: ubuntu:8042, Resource: <memory:2048, vCores:1>, Priority: 0, Token: Token { kind: ContainerToken, service: 127.0.1.1:45565 }, ExecutionType: GUARANTEED, ] for AM appattempt_1778475288188_0006_000001
2026-05-11 13:45:37,607 INFO org.apache.hadoop.yarn.server.resourcemanager.security.AMRMTokenSecretManager: Create AMRMToken for ApplicationAttempt: appattempt_1778475288188_0006_000001
2026-05-11 13:45:37,607 INFO org.apache.hadoop.yarn.server.resourcemanager.security.AMRMTokenSecretManager: Creating password for appattempt_1778475288188_0006_000001
2026-05-11 13:45:37,621 INFO org.apache.hadoop.yarn.server.resourcemanager.amlauncher.AMLauncher: Done launching container Container: [ContainerId: container_1778475288188_0006_01_000001, AllocationRequestId: -1, Version: 0, NodeId: ubuntu:45565, NodeHttpAddress: ubuntu:8042, Resource: <memory:2048, vCores:1>, Priority: 0, Token: Token { kind: ContainerToken, service: 127.0.1.1:45565 }, ExecutionType: GUARANTEED, ] for AM appattempt_1778475288188_0006_000001
2026-05-11 13:45:37,622 INFO org.apache.hadoop.yarn.server.resourcemanager.rmapp.attempt.RMAppAttemptImpl: appattempt_1778475288188_0006_000001 State change from ALLOCATED to LAUNCHED on event = LAUNCHED
2026-05-11 13:45:37,622 INFO org.apache.hadoop.yarn.server.resourcemanager.rmapp.RMAppImpl: update the launch time for applicationId: application_1778475288188_0006, attemptId: appattempt_1778475288188_0006_000001launchTime: 1778478337621
2026-05-11 13:45:37,622 INFO org.apache.hadoop.yarn.server.resourcemanager.recovery.RMStateStore: Updating info for app: application_1778475288188_0006
2026-05-11 13:45:38,602 INFO org.apache.hadoop.yarn.server.resourcemanager.rmcontainer.RMContainerImpl: container_1778475288188_0006_01_000001 Container Transitioned from ACQUIRED to RUNNING
2026-05-11 13:45:41,889 INFO SecurityLogger.org.apache.hadoop.ipc.Server: Auth successful for appattempt_1778475288188_0006_000001 (auth:SIMPLE) from 127.0.0.1:59540
2026-05-11 13:45:41,891 INFO org.apache.hadoop.yarn.server.resourcemanager.DefaultAMSProcessor: AM registration appattempt_1778475288188_0006_000001
2026-05-11 13:45:41,892 INFO org.apache.hadoop.yarn.server.resourcemanager.rmapp.attempt.RMAppAttemptImpl: appattempt_1778475288188_0006_000001 State change from LAUNCHED to RUNNING on event = REGISTERED
2026-05-11 13:45:41,892 INFO org.apache.hadoop.yarn.server.resourcemanager.rmapp.RMAppImpl: application_1778475288188_0006 State change from ACCEPTED to RUNNING on event = ATTEMPT_REGISTERED
2026-05-11 13:45:43,616 INFO org.apache.hadoop.yarn.server.resourcemanager.scheduler.capacity.allocator.AbstractContainerAllocator: assignedContainer application attempt=appattempt_1778475288188_0006_000001 container=null queue=default clusterResource=<memory:8192, vCores:8> type=NODE_LOCAL requestedPartition=
2026-05-11 13:45:43,617 INFO org.apache.hadoop.yarn.server.resourcemanager.rmcontainer.RMContainerImpl: container_1778475288188_0006_01_000002 Container Transitioned from NEW to ALLOCATED
2026-05-11 13:45:43,617 INFO org.apache.hadoop.yarn.server.resourcemanager.scheduler.common.fica.FiCaSchedulerNode: Assigned container container_1778475288188_0006_01_000002 of capacity <memory:1024, vCores:1> on host ubuntu:45565, which has 2 containers, <memory:3072, vCores:2> used and <memory:5120, vCores:6> available after allocation
2026-05-11 13:45:43,617 INFO org.apache.hadoop.yarn.server.resourcemanager.scheduler.capacity.ParentQueue: assignedContainer queue=root usedCapacity=0.375 absoluteUsedCapacity=0.375 used=<memory:3072, vCores:2> cluster=<memory:8192, vCores:8>
2026-05-11 13:45:43,617 INFO org.apache.hadoop.yarn.server.resourcemanager.scheduler.capacity.allocator.AbstractContainerAllocator: assignedContainer application attempt=appattempt_1778475288188_0006_000001 container=null queue=default clusterResource=<memory:8192, vCores:8> type=NODE_LOCAL requestedPartition=
2026-05-11 13:45:43,617 INFO org.apache.hadoop.yarn.server.resourcemanager.rmcontainer.RMContainerImpl: container_1778475288188_0006_01_000003 Container Transitioned from NEW to ALLOCATED
2026-05-11 13:45:43,617 INFO org.apache.hadoop.yarn.server.resourcemanager.scheduler.common.fica.FiCaSchedulerNode: Assigned container container_1778475288188_0006_01_000003 of capacity <memory:1024, vCores:1> on host ubuntu:45565, which has 3 containers, <memory:4096, vCores:3> used and <memory:4096, vCores:5> available after allocation
2026-05-11 13:45:43,617 INFO org.apache.hadoop.yarn.server.resourcemanager.scheduler.capacity.ParentQueue: assignedContainer queue=root usedCapacity=0.5 absoluteUsedCapacity=0.5 used=<memory:4096, vCores:3> cluster=<memory:8192, vCores:8>
2026-05-11 13:45:43,618 INFO org.apache.hadoop.yarn.server.resourcemanager.scheduler.capacity.allocator.AbstractContainerAllocator: assignedContainer application attempt=appattempt_1778475288188_0006_000001 container=null queue=default clusterResource=<memory:8192, vCores:8> type=OFF_SWITCH requestedPartition=
2026-05-11 13:45:43,618 INFO org.apache.hadoop.yarn.server.resourcemanager.rmcontainer.RMContainerImpl: container_1778475288188_0006_01_000004 Container Transitioned from NEW to ALLOCATED
2026-05-11 13:45:43,618 INFO org.apache.hadoop.yarn.server.resourcemanager.scheduler.common.fica.FiCaSchedulerNode: Assigned container container_1778475288188_0006_01_000004 of capacity <memory:1024, vCores:1> on host ubuntu:45565, which has 4 containers, <memory:5120, vCores:4> used and <memory:3072, vCores:4> available after allocation
2026-05-11 13:45:43,618 INFO org.apache.hadoop.yarn.server.resourcemanager.scheduler.capacity.ParentQueue: assignedContainer queue=root usedCapacity=0.625 absoluteUsedCapacity=0.625 used=<memory:5120, vCores:4> cluster=<memory:8192, vCores:8>
2026-05-11 13:45:43,963 INFO org.apache.hadoop.yarn.server.resourcemanager.rmcontainer.RMContainerImpl: container_1778475288188_0006_01_000002 Container Transitioned from ALLOCATED to ACQUIRED
2026-05-11 13:45:43,963 INFO org.apache.hadoop.yarn.server.resourcemanager.rmcontainer.RMContainerImpl: container_1778475288188_0006_01_000003 Container Transitioned from ALLOCATED to ACQUIRED
2026-05-11 13:45:43,964 INFO org.apache.hadoop.yarn.server.resourcemanager.rmcontainer.RMContainerImpl: container_1778475288188_0006_01_000004 Container Transitioned from ALLOCATED to ACQUIRED
2026-05-11 13:45:44,615 INFO org.apache.hadoop.yarn.server.resourcemanager.rmcontainer.RMContainerImpl: container_1778475288188_0006_01_000002 Container Transitioned from ACQUIRED to RUNNING
2026-05-11 13:45:44,616 INFO org.apache.hadoop.yarn.server.resourcemanager.rmcontainer.RMContainerImpl: container_1778475288188_0006_01_000003 Container Transitioned from ACQUIRED to RUNNING
2026-05-11 13:45:44,616 INFO org.apache.hadoop.yarn.server.resourcemanager.rmcontainer.RMContainerImpl: container_1778475288188_0006_01_000004 Container Transitioned from ACQUIRED to RUNNING
2026-05-11 13:45:44,975 INFO org.apache.hadoop.yarn.server.resourcemanager.scheduler.AppSchedulingInfo: checking for deactivate of application :application_1778475288188_0006
2026-05-11 13:46:01,625 INFO org.apache.hadoop.yarn.server.resourcemanager.rmcontainer.RMContainerImpl: container_1778475288188_0006_01_000004 Container Transitioned from RUNNING to COMPLETED
2026-05-11 13:46:02,628 INFO org.apache.hadoop.yarn.server.resourcemanager.scheduler.capacity.allocator.AbstractContainerAllocator: assignedContainer application attempt=appattempt_1778475288188_0006_000001 container=null queue=default clusterResource=<memory:8192, vCores:8> type=NODE_LOCAL requestedPartition=
2026-05-11 13:46:02,629 INFO org.apache.hadoop.yarn.server.resourcemanager.rmcontainer.RMContainerImpl: container_1778475288188_0006_01_000005 Container Transitioned from NEW to ALLOCATED
2026-05-11 13:46:02,629 INFO org.apache.hadoop.yarn.server.resourcemanager.scheduler.common.fica.FiCaSchedulerNode: Assigned container container_1778475288188_0006_01_000005 of capacity <memory:1024, vCores:1> on host ubuntu:45565, which has 4 containers, <memory:5120, vCores:4> used and <memory:3072, vCores:4> available after allocation
2026-05-11 13:46:02,629 INFO org.apache.hadoop.yarn.server.resourcemanager.scheduler.capacity.ParentQueue: assignedContainer queue=root usedCapacity=0.625 absoluteUsedCapacity=0.625 used=<memory:5120, vCores:4> cluster=<memory:8192, vCores:8>
2026-05-11 13:46:03,106 INFO org.apache.hadoop.yarn.server.resourcemanager.rmcontainer.RMContainerImpl: container_1778475288188_0006_01_000005 Container Transitioned from ALLOCATED to ACQUIRED
2026-05-11 13:46:03,630 INFO org.apache.hadoop.yarn.server.resourcemanager.rmcontainer.RMContainerImpl: container_1778475288188_0006_01_000005 Container Transitioned from ACQUIRED to RUNNING
2026-05-11 13:46:03,632 INFO org.apache.hadoop.yarn.server.resourcemanager.scheduler.capacity.allocator.AbstractContainerAllocator: assignedContainer application attempt=appattempt_1778475288188_0006_000001 container=null queue=default clusterResource=<memory:8192, vCores:8> type=OFF_SWITCH requestedPartition=
2026-05-11 13:46:03,633 INFO org.apache.hadoop.yarn.server.resourcemanager.rmcontainer.RMContainerImpl: container_1778475288188_0006_01_000006 Container Transitioned from NEW to ALLOCATED
2026-05-11 13:46:03,633 INFO org.apache.hadoop.yarn.server.resourcemanager.scheduler.common.fica.FiCaSchedulerNode: Assigned container container_1778475288188_0006_01_000006 of capacity <memory:1024, vCores:1> on host ubuntu:45565, which has 5 containers, <memory:6144, vCores:5> used and <memory:2048, vCores:3> available after allocation
2026-05-11 13:46:03,633 INFO org.apache.hadoop.yarn.server.resourcemanager.scheduler.capacity.ParentQueue: assignedContainer queue=root usedCapacity=0.75 absoluteUsedCapacity=0.75 used=<memory:6144, vCores:5> cluster=<memory:8192, vCores:8>
2026-05-11 13:46:04,114 INFO org.apache.hadoop.yarn.server.resourcemanager.scheduler.AppSchedulingInfo: checking for deactivate of application :application_1778475288188_0006
2026-05-11 13:46:04,119 INFO org.apache.hadoop.yarn.server.resourcemanager.rmcontainer.RMContainerImpl: container_1778475288188_0006_01_000006 Container Transitioned from ALLOCATED to ACQUIRED
2026-05-11 13:46:04,634 INFO org.apache.hadoop.yarn.server.resourcemanager.rmcontainer.RMContainerImpl: container_1778475288188_0006_01_000006 Container Transitioned from ACQUIRED to RUNNING
2026-05-11 13:46:05,130 INFO org.apache.hadoop.yarn.server.resourcemanager.scheduler.AppSchedulingInfo: checking for deactivate of application :application_1778475288188_0006
2026-05-11 13:46:17,681 INFO org.apache.hadoop.yarn.server.resourcemanager.scheduler.capacity.allocator.AbstractContainerAllocator: assignedContainer application attempt=appattempt_1778475288188_0006_000001 container=null queue=default clusterResource=<memory:8192, vCores:8> type=NODE_LOCAL requestedPartition=
2026-05-11 13:46:17,681 INFO org.apache.hadoop.yarn.server.resourcemanager.rmcontainer.RMContainerImpl: container_1778475288188_0006_01_000007 Container Transitioned from NEW to ALLOCATED
2026-05-11 13:46:17,681 INFO org.apache.hadoop.yarn.server.resourcemanager.scheduler.common.fica.FiCaSchedulerNode: Assigned container container_1778475288188_0006_01_000007 of capacity <memory:1024, vCores:1> on host ubuntu:45565, which has 6 containers, <memory:7168, vCores:6> used and <memory:1024, vCores:2> available after allocation
2026-05-11 13:46:17,682 INFO org.apache.hadoop.yarn.server.resourcemanager.scheduler.capacity.ParentQueue: assignedContainer queue=root usedCapacity=0.875 absoluteUsedCapacity=0.875 used=<memory:7168, vCores:6> cluster=<memory:8192, vCores:8>
2026-05-11 13:46:18,214 INFO org.apache.hadoop.yarn.server.resourcemanager.rmcontainer.RMContainerImpl: container_1778475288188_0006_01_000007 Container Transitioned from ALLOCATED to ACQUIRED
2026-05-11 13:46:18,685 INFO org.apache.hadoop.yarn.server.resourcemanager.rmcontainer.RMContainerImpl: container_1778475288188_0006_01_000007 Container Transitioned from ACQUIRED to RUNNING
2026-05-11 13:46:19,231 INFO org.apache.hadoop.yarn.server.resourcemanager.scheduler.AppSchedulingInfo: checking for deactivate of application :application_1778475288188_0006
2026-05-11 13:47:04,958 INFO org.apache.hadoop.yarn.server.resourcemanager.rmcontainer.RMContainerImpl: container_1778475288188_0006_01_000005 Container Transitioned from RUNNING to COMPLETED
2026-05-11 13:47:05,317 INFO org.apache.hadoop.yarn.server.resourcemanager.rmcontainer.RMContainerImpl: container_1778475288188_0006_01_000007 Container Transitioned from RUNNING to COMPLETED
2026-05-11 13:47:05,330 INFO org.apache.hadoop.yarn.server.resourcemanager.rmcontainer.RMContainerImpl: container_1778475288188_0006_01_000002 Container Transitioned from RUNNING to COMPLETED
2026-05-11 13:47:05,747 INFO org.apache.hadoop.yarn.server.resourcemanager.rmcontainer.RMContainerImpl: container_1778475288188_0006_01_000003 Container Transitioned from RUNNING to COMPLETED
2026-05-11 13:47:17,841 INFO org.apache.hadoop.yarn.server.resourcemanager.rmcontainer.RMContainerImpl: container_1778475288188_0006_01_000006 Container Transitioned from RUNNING to COMPLETED
2026-05-11 13:47:18,424 INFO org.apache.hadoop.yarn.server.resourcemanager.rmapp.attempt.RMAppAttemptImpl: Updating application attempt appattempt_1778475288188_0006_000001 with final state: FINISHING, and exit status: -1000
2026-05-11 13:47:18,424 INFO org.apache.hadoop.yarn.server.resourcemanager.rmapp.attempt.RMAppAttemptImpl: appattempt_1778475288188_0006_000001 State change from RUNNING to FINAL_SAVING on event = UNREGISTERED
2026-05-11 13:47:18,424 INFO org.apache.hadoop.yarn.server.resourcemanager.rmapp.RMAppImpl: Updating application application_1778475288188_0006 with final state: FINISHING
2026-05-11 13:47:18,424 INFO org.apache.hadoop.yarn.server.resourcemanager.rmapp.RMAppImpl: application_1778475288188_0006 State change from RUNNING to FINAL_SAVING on event = ATTEMPT_UNREGISTERED
2026-05-11 13:47:18,424 INFO org.apache.hadoop.yarn.server.resourcemanager.recovery.RMStateStore: Updating info for app: application_1778475288188_0006
2026-05-11 13:47:18,424 INFO org.apache.hadoop.yarn.server.resourcemanager.rmapp.attempt.RMAppAttemptImpl: appattempt_1778475288188_0006_000001 State change from FINAL_SAVING to FINISHING on event = ATTEMPT_UPDATE_SAVED
2026-05-11 13:47:18,425 INFO org.apache.hadoop.yarn.server.resourcemanager.rmapp.RMAppImpl: application_1778475288188_0006 State change from FINAL_SAVING to FINISHING on event = APP_UPDATE_SAVED
2026-05-11 13:47:19,427 INFO org.apache.hadoop.yarn.server.resourcemanager.ApplicationMasterService: application_1778475288188_0006 unregistered successfully. 
2026-05-11 13:47:24,895 INFO org.apache.hadoop.yarn.server.resourcemanager.rmcontainer.RMContainerImpl: container_1778475288188_0006_01_000001 Container Transitioned from RUNNING to COMPLETED
2026-05-11 13:47:24,896 INFO org.apache.hadoop.yarn.server.resourcemanager.ApplicationMasterService: Unregistering app attempt : appattempt_1778475288188_0006_000001
2026-05-11 13:47:24,896 INFO org.apache.hadoop.yarn.server.resourcemanager.security.AMRMTokenSecretManager: Application finished, removing password for appattempt_1778475288188_0006_000001
2026-05-11 13:47:24,896 INFO org.apache.hadoop.yarn.server.resourcemanager.rmapp.attempt.RMAppAttemptImpl: appattempt_1778475288188_0006_000001 State change from FINISHING to FINISHED on event = CONTAINER_FINISHED
2026-05-11 13:47:24,901 INFO org.apache.hadoop.yarn.server.resourcemanager.rmapp.RMAppImpl: application_1778475288188_0006 State change from FINISHING to FINISHED on event = ATTEMPT_FINISHED
2026-05-11 13:47:24,901 INFO org.apache.hadoop.yarn.server.resourcemanager.scheduler.capacity.CapacityScheduler: Application Attempt appattempt_1778475288188_0006_000001 is done. finalState=FINISHED
2026-05-11 13:47:24,901 INFO org.apache.hadoop.yarn.server.resourcemanager.scheduler.AppSchedulingInfo: Application application_1778475288188_0006 requests cleared
2026-05-11 13:47:24,902 INFO org.apache.hadoop.yarn.server.resourcemanager.scheduler.capacity.LeafQueue: Application removed - appId: application_1778475288188_0006 user: cty1576 queue: root.default #user-pending-applications: 0 #user-active-applications: 0 #queue-pending-applications: 0 #queue-active-applications: 0
2026-05-11 13:47:24,903 INFO org.apache.hadoop.yarn.server.resourcemanager.RMAppManager$ApplicationSummary: appId=application_1778475288188_0006,name=SELECT COUNT(DISTINCT...user_behavior_detail (Stage-1),user=cty1576,queue=default,state=FINISHED,trackingUrl=http://ubuntu:8088/proxy/application_1778475288188_0006/,appMasterHost=ubuntu,submitTime=1778478336793,startTime=1778478336794,launchTime=1778478337621,finishTime=1778478438424,finalStatus=SUCCEEDED,memorySeconds=594548,vcoreSeconds=471,preemptedMemorySeconds=0,preemptedVcoreSeconds=0,preemptedAMContainers=0,preemptedNonAMContainers=0,preemptedResources=<memory:0\, vCores:0>,applicationType=MAPREDUCE,resourceSeconds=594548 MB-seconds\, 471 vcore-seconds,preemptedResourceSeconds=0 MB-seconds\, 0 vcore-seconds,applicationTags=,applicationNodeLabel=,diagnostics=,totalAllocatedContainers=7
2026-05-11 13:47:24,903 INFO org.apache.hadoop.yarn.server.resourcemanager.scheduler.capacity.ParentQueue: Application removed - appId: application_1778475288188_0006 user: cty1576 leaf-queue of parent: root #applications: 0
2026-05-11 13:47:24,905 INFO org.apache.hadoop.yarn.server.resourcemanager.amlauncher.AMLauncher: Cleaning master appattempt_1778475288188_0006_000001
2026-05-11 13:47:28,329 INFO org.apache.hadoop.yarn.server.resourcemanager.ClientRMService: Allocated new applicationId: 7
2026-05-11 13:47:29,561 INFO org.apache.hadoop.yarn.server.resourcemanager.scheduler.capacity.CapacityScheduler: Application 'application_1778475288188_0007' is submitted without priority hence considering default queue/cluster priority: 0
2026-05-11 13:47:29,561 INFO org.apache.hadoop.yarn.server.resourcemanager.scheduler.capacity.CapacityScheduler: Priority '0' is acceptable in queue : default for application: application_1778475288188_0007
2026-05-11 13:47:29,561 INFO org.apache.hadoop.yarn.server.resourcemanager.ClientRMService: Application with id 7 submitted by user cty1576
2026-05-11 13:47:29,562 INFO org.apache.hadoop.yarn.server.resourcemanager.rmapp.RMAppImpl: Storing application with id application_1778475288188_0007
2026-05-11 13:47:29,562 INFO org.apache.hadoop.yarn.server.resourcemanager.rmapp.RMAppImpl: application_1778475288188_0007 State change from NEW to NEW_SAVING on event = START
2026-05-11 13:47:29,562 INFO org.apache.hadoop.yarn.server.resourcemanager.recovery.RMStateStore: Storing info for app: application_1778475288188_0007
2026-05-11 13:47:29,562 INFO org.apache.hadoop.yarn.server.resourcemanager.rmapp.RMAppImpl: application_1778475288188_0007 State change from NEW_SAVING to SUBMITTED on event = APP_NEW_SAVED
2026-05-11 13:47:29,562 INFO org.apache.hadoop.yarn.server.resourcemanager.scheduler.capacity.ParentQueue: Application added - appId: application_1778475288188_0007 user: cty1576 leaf-queue of parent: root #applications: 1
2026-05-11 13:47:29,563 INFO org.apache.hadoop.yarn.server.resourcemanager.scheduler.capacity.CapacityScheduler: Accepted application application_1778475288188_0007 from user: cty1576, in queue: default
2026-05-11 13:47:29,563 INFO org.apache.hadoop.yarn.server.resourcemanager.rmapp.RMAppImpl: application_1778475288188_0007 State change from SUBMITTED to ACCEPTED on event = APP_ACCEPTED
2026-05-11 13:47:29,563 INFO org.apache.hadoop.yarn.server.resourcemanager.ApplicationMasterService: Registering app attempt : appattempt_1778475288188_0007_000001
2026-05-11 13:47:29,563 INFO org.apache.hadoop.yarn.server.resourcemanager.rmapp.attempt.RMAppAttemptImpl: appattempt_1778475288188_0007_000001 State change from NEW to SUBMITTED on event = START
2026-05-11 13:47:29,566 WARN org.apache.hadoop.yarn.server.resourcemanager.scheduler.capacity.LeafQueue: maximum-am-resource-percent is insufficient to start a single application in queue, it is likely set too low. skipping enforcement to allow at least one application to start
2026-05-11 13:47:29,566 WARN org.apache.hadoop.yarn.server.resourcemanager.scheduler.capacity.LeafQueue: maximum-am-resource-percent is insufficient to start a single application in queue for user, it is likely set too low. skipping enforcement to allow at least one application to start
2026-05-11 13:47:29,566 INFO org.apache.hadoop.yarn.server.resourcemanager.scheduler.capacity.LeafQueue: Application application_1778475288188_0007 from user: cty1576 activated in queue: root.default
2026-05-11 13:47:29,566 INFO org.apache.hadoop.yarn.server.resourcemanager.scheduler.capacity.LeafQueue: Application added - appId: application_1778475288188_0007 user: cty1576, leaf-queue: root.default #user-pending-applications: 0 #user-active-applications: 1 #queue-pending-applications: 0 #queue-active-applications: 1 #queue-nonrunnable-applications: 0
2026-05-11 13:47:29,566 INFO org.apache.hadoop.yarn.server.resourcemanager.scheduler.capacity.CapacityScheduler: Added Application Attempt appattempt_1778475288188_0007_000001 to scheduler from user cty1576 in queue root.default
2026-05-11 13:47:29,567 INFO org.apache.hadoop.yarn.server.resourcemanager.rmapp.attempt.RMAppAttemptImpl: appattempt_1778475288188_0007_000001 State change from SUBMITTED to SCHEDULED on event = ATTEMPT_ADDED
2026-05-11 13:47:29,905 INFO org.apache.hadoop.yarn.server.resourcemanager.scheduler.capacity.allocator.AbstractContainerAllocator: assignedContainer application attempt=appattempt_1778475288188_0007_000001 container=null queue=default clusterResource=<memory:8192, vCores:8> type=OFF_SWITCH requestedPartition=
2026-05-11 13:47:29,905 INFO org.apache.hadoop.yarn.server.resourcemanager.rmcontainer.RMContainerImpl: container_1778475288188_0007_01_000001 Container Transitioned from NEW to ALLOCATED
2026-05-11 13:47:29,905 INFO org.apache.hadoop.yarn.server.resourcemanager.scheduler.common.fica.FiCaSchedulerNode: Assigned container container_1778475288188_0007_01_000001 of capacity <memory:2048, vCores:1> on host ubuntu:45565, which has 1 containers, <memory:2048, vCores:1> used and <memory:6144, vCores:7> available after allocation
2026-05-11 13:47:29,905 INFO org.apache.hadoop.yarn.server.resourcemanager.scheduler.capacity.ParentQueue: assignedContainer queue=root usedCapacity=0.25 absoluteUsedCapacity=0.25 used=<memory:2048, vCores:1> cluster=<memory:8192, vCores:8>
2026-05-11 13:47:29,906 INFO org.apache.hadoop.yarn.server.resourcemanager.rmcontainer.RMContainerImpl: container_1778475288188_0007_01_000001 Container Transitioned from ALLOCATED to ACQUIRED
2026-05-11 13:47:29,907 INFO org.apache.hadoop.yarn.server.resourcemanager.security.NMTokenSecretManagerInRM: Clear node set for appattempt_1778475288188_0007_000001
2026-05-11 13:47:29,907 INFO org.apache.hadoop.yarn.server.resourcemanager.rmapp.attempt.RMAppAttemptImpl: Storing attempt: AppId: application_1778475288188_0007 AttemptId: appattempt_1778475288188_0007_000001 MasterContainer: Container: [ContainerId: container_1778475288188_0007_01_000001, AllocationRequestId: -1, Version: 0, NodeId: ubuntu:45565, NodeHttpAddress: ubuntu:8042, Resource: <memory:2048, vCores:1>, Priority: 0, Token: Token { kind: ContainerToken, service: 127.0.1.1:45565 }, ExecutionType: GUARANTEED, ]
2026-05-11 13:47:29,907 INFO org.apache.hadoop.yarn.server.resourcemanager.rmapp.attempt.RMAppAttemptImpl: appattempt_1778475288188_0007_000001 State change from SCHEDULED to ALLOCATED_SAVING on event = CONTAINER_ALLOCATED
2026-05-11 13:47:29,907 INFO org.apache.hadoop.yarn.server.resourcemanager.rmapp.attempt.RMAppAttemptImpl: appattempt_1778475288188_0007_000001 State change from ALLOCATED_SAVING to ALLOCATED on event = ATTEMPT_NEW_SAVED
2026-05-11 13:47:29,909 INFO org.apache.hadoop.yarn.server.resourcemanager.amlauncher.AMLauncher: Launching masterappattempt_1778475288188_0007_000001
2026-05-11 13:47:29,912 INFO org.apache.hadoop.yarn.server.resourcemanager.amlauncher.AMLauncher: Setting up container Container: [ContainerId: container_1778475288188_0007_01_000001, AllocationRequestId: -1, Version: 0, NodeId: ubuntu:45565, NodeHttpAddress: ubuntu:8042, Resource: <memory:2048, vCores:1>, Priority: 0, Token: Token { kind: ContainerToken, service: 127.0.1.1:45565 }, ExecutionType: GUARANTEED, ] for AM appattempt_1778475288188_0007_000001
2026-05-11 13:47:29,913 INFO org.apache.hadoop.yarn.server.resourcemanager.security.AMRMTokenSecretManager: Create AMRMToken for ApplicationAttempt: appattempt_1778475288188_0007_000001
2026-05-11 13:47:29,913 INFO org.apache.hadoop.yarn.server.resourcemanager.security.AMRMTokenSecretManager: Creating password for appattempt_1778475288188_0007_000001
2026-05-11 13:47:29,925 INFO org.apache.hadoop.yarn.server.resourcemanager.amlauncher.AMLauncher: Done launching container Container: [ContainerId: container_1778475288188_0007_01_000001, AllocationRequestId: -1, Version: 0, NodeId: ubuntu:45565, NodeHttpAddress: ubuntu:8042, Resource: <memory:2048, vCores:1>, Priority: 0, Token: Token { kind: ContainerToken, service: 127.0.1.1:45565 }, ExecutionType: GUARANTEED, ] for AM appattempt_1778475288188_0007_000001
2026-05-11 13:47:29,925 INFO org.apache.hadoop.yarn.server.resourcemanager.rmapp.attempt.RMAppAttemptImpl: appattempt_1778475288188_0007_000001 State change from ALLOCATED to LAUNCHED on event = LAUNCHED
2026-05-11 13:47:29,925 INFO org.apache.hadoop.yarn.server.resourcemanager.rmapp.RMAppImpl: update the launch time for applicationId: application_1778475288188_0007, attemptId: appattempt_1778475288188_0007_000001launchTime: 1778478449925
2026-05-11 13:47:29,927 INFO org.apache.hadoop.yarn.server.resourcemanager.recovery.RMStateStore: Updating info for app: application_1778475288188_0007
2026-05-11 13:47:30,911 INFO org.apache.hadoop.yarn.server.resourcemanager.rmcontainer.RMContainerImpl: container_1778475288188_0007_01_000001 Container Transitioned from ACQUIRED to RUNNING
2026-05-11 13:47:34,028 INFO SecurityLogger.org.apache.hadoop.ipc.Server: Auth successful for appattempt_1778475288188_0007_000001 (auth:SIMPLE) from 127.0.0.1:42082
2026-05-11 13:47:34,032 INFO org.apache.hadoop.yarn.server.resourcemanager.DefaultAMSProcessor: AM registration appattempt_1778475288188_0007_000001
2026-05-11 13:47:34,033 INFO org.apache.hadoop.yarn.server.resourcemanager.rmapp.attempt.RMAppAttemptImpl: appattempt_1778475288188_0007_000001 State change from LAUNCHED to RUNNING on event = REGISTERED
2026-05-11 13:47:34,033 INFO org.apache.hadoop.yarn.server.resourcemanager.rmapp.RMAppImpl: application_1778475288188_0007 State change from ACCEPTED to RUNNING on event = ATTEMPT_REGISTERED
2026-05-11 13:47:35,920 INFO org.apache.hadoop.yarn.server.resourcemanager.scheduler.capacity.allocator.AbstractContainerAllocator: assignedContainer application attempt=appattempt_1778475288188_0007_000001 container=null queue=default clusterResource=<memory:8192, vCores:8> type=NODE_LOCAL requestedPartition=
2026-05-11 13:47:35,921 INFO org.apache.hadoop.yarn.server.resourcemanager.rmcontainer.RMContainerImpl: container_1778475288188_0007_01_000002 Container Transitioned from NEW to ALLOCATED
2026-05-11 13:47:35,921 INFO org.apache.hadoop.yarn.server.resourcemanager.scheduler.common.fica.FiCaSchedulerNode: Assigned container container_1778475288188_0007_01_000002 of capacity <memory:1024, vCores:1> on host ubuntu:45565, which has 2 containers, <memory:3072, vCores:2> used and <memory:5120, vCores:6> available after allocation
2026-05-11 13:47:35,921 INFO org.apache.hadoop.yarn.server.resourcemanager.scheduler.capacity.ParentQueue: assignedContainer queue=root usedCapacity=0.375 absoluteUsedCapacity=0.375 used=<memory:3072, vCores:2> cluster=<memory:8192, vCores:8>
2026-05-11 13:47:35,921 INFO org.apache.hadoop.yarn.server.resourcemanager.scheduler.capacity.allocator.AbstractContainerAllocator: assignedContainer application attempt=appattempt_1778475288188_0007_000001 container=null queue=default clusterResource=<memory:8192, vCores:8> type=NODE_LOCAL requestedPartition=
2026-05-11 13:47:35,922 INFO org.apache.hadoop.yarn.server.resourcemanager.rmcontainer.RMContainerImpl: container_1778475288188_0007_01_000003 Container Transitioned from NEW to ALLOCATED
2026-05-11 13:47:35,922 INFO org.apache.hadoop.yarn.server.resourcemanager.scheduler.common.fica.FiCaSchedulerNode: Assigned container container_1778475288188_0007_01_000003 of capacity <memory:1024, vCores:1> on host ubuntu:45565, which has 3 containers, <memory:4096, vCores:3> used and <memory:4096, vCores:5> available after allocation
2026-05-11 13:47:35,922 INFO org.apache.hadoop.yarn.server.resourcemanager.scheduler.capacity.ParentQueue: assignedContainer queue=root usedCapacity=0.5 absoluteUsedCapacity=0.5 used=<memory:4096, vCores:3> cluster=<memory:8192, vCores:8>
2026-05-11 13:47:35,923 INFO org.apache.hadoop.yarn.server.resourcemanager.scheduler.capacity.allocator.AbstractContainerAllocator: assignedContainer application attempt=appattempt_1778475288188_0007_000001 container=null queue=default clusterResource=<memory:8192, vCores:8> type=OFF_SWITCH requestedPartition=
2026-05-11 13:47:35,923 INFO org.apache.hadoop.yarn.server.resourcemanager.rmcontainer.RMContainerImpl: container_1778475288188_0007_01_000004 Container Transitioned from NEW to ALLOCATED
2026-05-11 13:47:35,923 INFO org.apache.hadoop.yarn.server.resourcemanager.scheduler.common.fica.FiCaSchedulerNode: Assigned container container_1778475288188_0007_01_000004 of capacity <memory:1024, vCores:1> on host ubuntu:45565, which has 4 containers, <memory:5120, vCores:4> used and <memory:3072, vCores:4> available after allocation
2026-05-11 13:47:35,923 INFO org.apache.hadoop.yarn.server.resourcemanager.scheduler.capacity.ParentQueue: assignedContainer queue=root usedCapacity=0.625 absoluteUsedCapacity=0.625 used=<memory:5120, vCores:4> cluster=<memory:8192, vCores:8>
2026-05-11 13:47:36,126 INFO org.apache.hadoop.yarn.server.resourcemanager.rmcontainer.RMContainerImpl: container_1778475288188_0007_01_000002 Container Transitioned from ALLOCATED to ACQUIRED
2026-05-11 13:47:36,127 INFO org.apache.hadoop.yarn.server.resourcemanager.rmcontainer.RMContainerImpl: container_1778475288188_0007_01_000003 Container Transitioned from ALLOCATED to ACQUIRED
2026-05-11 13:47:36,129 INFO org.apache.hadoop.yarn.server.resourcemanager.rmcontainer.RMContainerImpl: container_1778475288188_0007_01_000004 Container Transitioned from ALLOCATED to ACQUIRED
2026-05-11 13:47:36,922 INFO org.apache.hadoop.yarn.server.resourcemanager.rmcontainer.RMContainerImpl: container_1778475288188_0007_01_000002 Container Transitioned from ACQUIRED to RUNNING
2026-05-11 13:47:36,922 INFO org.apache.hadoop.yarn.server.resourcemanager.rmcontainer.RMContainerImpl: container_1778475288188_0007_01_000003 Container Transitioned from ACQUIRED to RUNNING
2026-05-11 13:47:36,922 INFO org.apache.hadoop.yarn.server.resourcemanager.rmcontainer.RMContainerImpl: container_1778475288188_0007_01_000004 Container Transitioned from ACQUIRED to RUNNING
2026-05-11 13:47:37,146 INFO org.apache.hadoop.yarn.server.resourcemanager.scheduler.AppSchedulingInfo: checking for deactivate of application :application_1778475288188_0007
2026-05-11 13:47:48,543 INFO org.apache.hadoop.yarn.server.resourcemanager.rmcontainer.RMContainerImpl: container_1778475288188_0007_01_000004 Container Transitioned from RUNNING to COMPLETED
2026-05-11 13:47:49,547 INFO org.apache.hadoop.yarn.server.resourcemanager.scheduler.capacity.allocator.AbstractContainerAllocator: assignedContainer application attempt=appattempt_1778475288188_0007_000001 container=null queue=default clusterResource=<memory:8192, vCores:8> type=OFF_SWITCH requestedPartition=
2026-05-11 13:47:49,547 INFO org.apache.hadoop.yarn.server.resourcemanager.rmcontainer.RMContainerImpl: container_1778475288188_0007_01_000005 Container Transitioned from NEW to ALLOCATED
2026-05-11 13:47:49,547 INFO org.apache.hadoop.yarn.server.resourcemanager.scheduler.common.fica.FiCaSchedulerNode: Assigned container container_1778475288188_0007_01_000005 of capacity <memory:1024, vCores:1> on host ubuntu:45565, which has 4 containers, <memory:5120, vCores:4> used and <memory:3072, vCores:4> available after allocation
2026-05-11 13:47:49,547 INFO org.apache.hadoop.yarn.server.resourcemanager.scheduler.capacity.ParentQueue: assignedContainer queue=root usedCapacity=0.625 absoluteUsedCapacity=0.625 used=<memory:5120, vCores:4> cluster=<memory:8192, vCores:8>
2026-05-11 13:47:50,277 INFO org.apache.hadoop.yarn.server.resourcemanager.rmcontainer.RMContainerImpl: container_1778475288188_0007_01_000005 Container Transitioned from ALLOCATED to ACQUIRED
2026-05-11 13:47:50,552 INFO org.apache.hadoop.yarn.server.resourcemanager.rmcontainer.RMContainerImpl: container_1778475288188_0007_01_000005 Container Transitioned from ACQUIRED to RUNNING
2026-05-11 13:47:51,285 INFO org.apache.hadoop.yarn.server.resourcemanager.scheduler.AppSchedulingInfo: checking for deactivate of application :application_1778475288188_0007
2026-05-11 13:47:53,573 INFO org.apache.hadoop.yarn.server.resourcemanager.scheduler.capacity.allocator.AbstractContainerAllocator: assignedContainer application attempt=appattempt_1778475288188_0007_000001 container=null queue=default clusterResource=<memory:8192, vCores:8> type=NODE_LOCAL requestedPartition=
2026-05-11 13:47:53,573 INFO org.apache.hadoop.yarn.server.resourcemanager.rmcontainer.RMContainerImpl: container_1778475288188_0007_01_000006 Container Transitioned from NEW to ALLOCATED
2026-05-11 13:47:53,574 INFO org.apache.hadoop.yarn.server.resourcemanager.scheduler.common.fica.FiCaSchedulerNode: Assigned container container_1778475288188_0007_01_000006 of capacity <memory:1024, vCores:1> on host ubuntu:45565, which has 5 containers, <memory:6144, vCores:5> used and <memory:2048, vCores:3> available after allocation
2026-05-11 13:47:53,574 INFO org.apache.hadoop.yarn.server.resourcemanager.scheduler.capacity.ParentQueue: assignedContainer queue=root usedCapacity=0.75 absoluteUsedCapacity=0.75 used=<memory:6144, vCores:5> cluster=<memory:8192, vCores:8>
2026-05-11 13:47:54,325 INFO org.apache.hadoop.yarn.server.resourcemanager.rmcontainer.RMContainerImpl: container_1778475288188_0007_01_000006 Container Transitioned from ALLOCATED to ACQUIRED
2026-05-11 13:47:54,578 INFO org.apache.hadoop.yarn.server.resourcemanager.rmcontainer.RMContainerImpl: container_1778475288188_0007_01_000006 Container Transitioned from ACQUIRED to RUNNING
2026-05-11 13:47:55,349 INFO org.apache.hadoop.yarn.server.resourcemanager.scheduler.AppSchedulingInfo: checking for deactivate of application :application_1778475288188_0007
2026-05-11 13:47:57,590 INFO org.apache.hadoop.yarn.server.resourcemanager.rmcontainer.RMContainerImpl: container_1778475288188_0007_01_000006 Container Transitioned from RUNNING to COMPLETED
2026-05-11 13:47:58,010 INFO org.apache.hadoop.yarn.server.resourcemanager.rmcontainer.RMContainerImpl: container_1778475288188_0007_01_000002 Container Transitioned from RUNNING to COMPLETED
2026-05-11 13:47:58,288 INFO org.apache.hadoop.yarn.server.resourcemanager.rmcontainer.RMContainerImpl: container_1778475288188_0007_01_000003 Container Transitioned from RUNNING to COMPLETED
2026-05-11 13:47:59,250 INFO org.apache.hadoop.yarn.server.resourcemanager.rmcontainer.RMContainerImpl: container_1778475288188_0007_01_000005 Container Transitioned from RUNNING to COMPLETED
2026-05-11 13:47:59,875 INFO org.apache.hadoop.yarn.server.resourcemanager.rmapp.attempt.RMAppAttemptImpl: Updating application attempt appattempt_1778475288188_0007_000001 with final state: FINISHING, and exit status: -1000
2026-05-11 13:47:59,875 INFO org.apache.hadoop.yarn.server.resourcemanager.rmapp.attempt.RMAppAttemptImpl: appattempt_1778475288188_0007_000001 State change from RUNNING to FINAL_SAVING on event = UNREGISTERED
2026-05-11 13:47:59,875 INFO org.apache.hadoop.yarn.server.resourcemanager.rmapp.RMAppImpl: Updating application application_1778475288188_0007 with final state: FINISHING
2026-05-11 13:47:59,875 INFO org.apache.hadoop.yarn.server.resourcemanager.rmapp.RMAppImpl: application_1778475288188_0007 State change from RUNNING to FINAL_SAVING on event = ATTEMPT_UNREGISTERED
2026-05-11 13:47:59,876 INFO org.apache.hadoop.yarn.server.resourcemanager.recovery.RMStateStore: Updating info for app: application_1778475288188_0007
2026-05-11 13:47:59,876 INFO org.apache.hadoop.yarn.server.resourcemanager.rmapp.attempt.RMAppAttemptImpl: appattempt_1778475288188_0007_000001 State change from FINAL_SAVING to FINISHING on event = ATTEMPT_UPDATE_SAVED
2026-05-11 13:47:59,876 INFO org.apache.hadoop.yarn.server.resourcemanager.rmapp.RMAppImpl: application_1778475288188_0007 State change from FINAL_SAVING to FINISHING on event = APP_UPDATE_SAVED
2026-05-11 13:48:00,876 INFO org.apache.hadoop.yarn.server.resourcemanager.ApplicationMasterService: application_1778475288188_0007 unregistered successfully. 
2026-05-11 13:48:06,298 INFO org.apache.hadoop.yarn.server.resourcemanager.rmcontainer.RMContainerImpl: container_1778475288188_0007_01_000001 Container Transitioned from RUNNING to COMPLETED
2026-05-11 13:48:06,298 INFO org.apache.hadoop.yarn.server.resourcemanager.ApplicationMasterService: Unregistering app attempt : appattempt_1778475288188_0007_000001
2026-05-11 13:48:06,300 INFO org.apache.hadoop.yarn.server.resourcemanager.security.AMRMTokenSecretManager: Application finished, removing password for appattempt_1778475288188_0007_000001
2026-05-11 13:48:06,301 INFO org.apache.hadoop.yarn.server.resourcemanager.rmapp.attempt.RMAppAttemptImpl: appattempt_1778475288188_0007_000001 State change from FINISHING to FINISHED on event = CONTAINER_FINISHED
2026-05-11 13:48:06,303 INFO org.apache.hadoop.yarn.server.resourcemanager.rmapp.RMAppImpl: application_1778475288188_0007 State change from FINISHING to FINISHED on event = ATTEMPT_FINISHED
2026-05-11 13:48:06,303 INFO org.apache.hadoop.yarn.server.resourcemanager.scheduler.capacity.CapacityScheduler: Application Attempt appattempt_1778475288188_0007_000001 is done. finalState=FINISHED
2026-05-11 13:48:06,303 INFO org.apache.hadoop.yarn.server.resourcemanager.scheduler.AppSchedulingInfo: Application application_1778475288188_0007 requests cleared
2026-05-11 13:48:06,303 INFO org.apache.hadoop.yarn.server.resourcemanager.scheduler.capacity.LeafQueue: Application removed - appId: application_1778475288188_0007 user: cty1576 queue: root.default #user-pending-applications: 0 #user-active-applications: 0 #queue-pending-applications: 0 #queue-active-applications: 0
2026-05-11 13:48:06,304 INFO org.apache.hadoop.yarn.server.resourcemanager.scheduler.capacity.ParentQueue: Application removed - appId: application_1778475288188_0007 user: cty1576 leaf-queue of parent: root #applications: 0
2026-05-11 13:48:06,304 INFO org.apache.hadoop.yarn.server.resourcemanager.amlauncher.AMLauncher: Cleaning master appattempt_1778475288188_0007_000001
2026-05-11 13:48:06,305 INFO org.apache.hadoop.yarn.server.resourcemanager.RMAppManager$ApplicationSummary: appId=application_1778475288188_0007,name=SELECT COUNT(DISTINCT...user_behavior_detail (Stage-1),user=cty1576,queue=default,state=FINISHED,trackingUrl=http://ubuntu:8088/proxy/application_1778475288188_0007/,appMasterHost=ubuntu,submitTime=1778478449560,startTime=1778478449561,launchTime=1778478449925,finishTime=1778478479875,finalStatus=SUCCEEDED,memorySeconds=147028,vcoreSeconds=105,preemptedMemorySeconds=0,preemptedVcoreSeconds=0,preemptedAMContainers=0,preemptedNonAMContainers=0,preemptedResources=<memory:0\, vCores:0>,applicationType=MAPREDUCE,resourceSeconds=147028 MB-seconds\, 105 vcore-seconds,preemptedResourceSeconds=0 MB-seconds\, 0 vcore-seconds,applicationTags=,applicationNodeLabel=,diagnostics=,totalAllocatedContainers=6
2026-05-11 13:48:08,786 INFO org.apache.hadoop.yarn.server.resourcemanager.ClientRMService: Allocated new applicationId: 8
2026-05-11 13:48:09,465 INFO org.apache.hadoop.yarn.server.resourcemanager.scheduler.capacity.CapacityScheduler: Application 'application_1778475288188_0008' is submitted without priority hence considering default queue/cluster priority: 0
2026-05-11 13:48:09,465 INFO org.apache.hadoop.yarn.server.resourcemanager.scheduler.capacity.CapacityScheduler: Priority '0' is acceptable in queue : default for application: application_1778475288188_0008
2026-05-11 13:48:09,465 INFO org.apache.hadoop.yarn.server.resourcemanager.ClientRMService: Application with id 8 submitted by user cty1576
2026-05-11 13:48:09,466 INFO org.apache.hadoop.yarn.server.resourcemanager.rmapp.RMAppImpl: Storing application with id application_1778475288188_0008
2026-05-11 13:48:09,466 INFO org.apache.hadoop.yarn.server.resourcemanager.rmapp.RMAppImpl: application_1778475288188_0008 State change from NEW to NEW_SAVING on event = START
2026-05-11 13:48:09,467 INFO org.apache.hadoop.yarn.server.resourcemanager.recovery.RMStateStore: Storing info for app: application_1778475288188_0008
2026-05-11 13:48:09,467 INFO org.apache.hadoop.yarn.server.resourcemanager.rmapp.RMAppImpl: application_1778475288188_0008 State change from NEW_SAVING to SUBMITTED on event = APP_NEW_SAVED
2026-05-11 13:48:09,467 INFO org.apache.hadoop.yarn.server.resourcemanager.scheduler.capacity.ParentQueue: Application added - appId: application_1778475288188_0008 user: cty1576 leaf-queue of parent: root #applications: 1
2026-05-11 13:48:09,467 INFO org.apache.hadoop.yarn.server.resourcemanager.scheduler.capacity.CapacityScheduler: Accepted application application_1778475288188_0008 from user: cty1576, in queue: default
2026-05-11 13:48:09,468 INFO org.apache.hadoop.yarn.server.resourcemanager.rmapp.RMAppImpl: application_1778475288188_0008 State change from SUBMITTED to ACCEPTED on event = APP_ACCEPTED
2026-05-11 13:48:09,469 INFO org.apache.hadoop.yarn.server.resourcemanager.ApplicationMasterService: Registering app attempt : appattempt_1778475288188_0008_000001
2026-05-11 13:48:09,469 INFO org.apache.hadoop.yarn.server.resourcemanager.rmapp.attempt.RMAppAttemptImpl: appattempt_1778475288188_0008_000001 State change from NEW to SUBMITTED on event = START
2026-05-11 13:48:09,470 WARN org.apache.hadoop.yarn.server.resourcemanager.scheduler.capacity.LeafQueue: maximum-am-resource-percent is insufficient to start a single application in queue, it is likely set too low. skipping enforcement to allow at least one application to start
2026-05-11 13:48:09,470 WARN org.apache.hadoop.yarn.server.resourcemanager.scheduler.capacity.LeafQueue: maximum-am-resource-percent is insufficient to start a single application in queue for user, it is likely set too low. skipping enforcement to allow at least one application to start
2026-05-11 13:48:09,470 INFO org.apache.hadoop.yarn.server.resourcemanager.scheduler.capacity.LeafQueue: Application application_1778475288188_0008 from user: cty1576 activated in queue: root.default
2026-05-11 13:48:09,470 INFO org.apache.hadoop.yarn.server.resourcemanager.scheduler.capacity.LeafQueue: Application added - appId: application_1778475288188_0008 user: cty1576, leaf-queue: root.default #user-pending-applications: 0 #user-active-applications: 1 #queue-pending-applications: 0 #queue-active-applications: 1 #queue-nonrunnable-applications: 0
2026-05-11 13:48:09,470 INFO org.apache.hadoop.yarn.server.resourcemanager.scheduler.capacity.CapacityScheduler: Added Application Attempt appattempt_1778475288188_0008_000001 to scheduler from user cty1576 in queue root.default
2026-05-11 13:48:09,471 INFO org.apache.hadoop.yarn.server.resourcemanager.rmapp.attempt.RMAppAttemptImpl: appattempt_1778475288188_0008_000001 State change from SUBMITTED to SCHEDULED on event = ATTEMPT_ADDED
2026-05-11 13:48:10,319 INFO org.apache.hadoop.yarn.server.resourcemanager.scheduler.capacity.allocator.AbstractContainerAllocator: assignedContainer application attempt=appattempt_1778475288188_0008_000001 container=null queue=default clusterResource=<memory:8192, vCores:8> type=OFF_SWITCH requestedPartition=
2026-05-11 13:48:10,320 INFO org.apache.hadoop.yarn.server.resourcemanager.rmcontainer.RMContainerImpl: container_1778475288188_0008_01_000001 Container Transitioned from NEW to ALLOCATED
2026-05-11 13:48:10,320 INFO org.apache.hadoop.yarn.server.resourcemanager.scheduler.common.fica.FiCaSchedulerNode: Assigned container container_1778475288188_0008_01_000001 of capacity <memory:2048, vCores:1> on host ubuntu:45565, which has 1 containers, <memory:2048, vCores:1> used and <memory:6144, vCores:7> available after allocation
2026-05-11 13:48:10,321 INFO org.apache.hadoop.yarn.server.resourcemanager.scheduler.capacity.ParentQueue: assignedContainer queue=root usedCapacity=0.25 absoluteUsedCapacity=0.25 used=<memory:2048, vCores:1> cluster=<memory:8192, vCores:8>
2026-05-11 13:48:10,321 INFO org.apache.hadoop.yarn.server.resourcemanager.rmcontainer.RMContainerImpl: container_1778475288188_0008_01_000001 Container Transitioned from ALLOCATED to ACQUIRED
2026-05-11 13:48:10,321 INFO org.apache.hadoop.yarn.server.resourcemanager.security.NMTokenSecretManagerInRM: Clear node set for appattempt_1778475288188_0008_000001
2026-05-11 13:48:10,321 INFO org.apache.hadoop.yarn.server.resourcemanager.rmapp.attempt.RMAppAttemptImpl: Storing attempt: AppId: application_1778475288188_0008 AttemptId: appattempt_1778475288188_0008_000001 MasterContainer: Container: [ContainerId: container_1778475288188_0008_01_000001, AllocationRequestId: -1, Version: 0, NodeId: ubuntu:45565, NodeHttpAddress: ubuntu:8042, Resource: <memory:2048, vCores:1>, Priority: 0, Token: Token { kind: ContainerToken, service: 127.0.1.1:45565 }, ExecutionType: GUARANTEED, ]
2026-05-11 13:48:10,322 INFO org.apache.hadoop.yarn.server.resourcemanager.rmapp.attempt.RMAppAttemptImpl: appattempt_1778475288188_0008_000001 State change from SCHEDULED to ALLOCATED_SAVING on event = CONTAINER_ALLOCATED
2026-05-11 13:48:10,322 INFO org.apache.hadoop.yarn.server.resourcemanager.rmapp.attempt.RMAppAttemptImpl: appattempt_1778475288188_0008_000001 State change from ALLOCATED_SAVING to ALLOCATED on event = ATTEMPT_NEW_SAVED
2026-05-11 13:48:10,322 INFO org.apache.hadoop.yarn.server.resourcemanager.amlauncher.AMLauncher: Launching masterappattempt_1778475288188_0008_000001
2026-05-11 13:48:10,324 INFO org.apache.hadoop.yarn.server.resourcemanager.amlauncher.AMLauncher: Setting up container Container: [ContainerId: container_1778475288188_0008_01_000001, AllocationRequestId: -1, Version: 0, NodeId: ubuntu:45565, NodeHttpAddress: ubuntu:8042, Resource: <memory:2048, vCores:1>, Priority: 0, Token: Token { kind: ContainerToken, service: 127.0.1.1:45565 }, ExecutionType: GUARANTEED, ] for AM appattempt_1778475288188_0008_000001
2026-05-11 13:48:10,324 INFO org.apache.hadoop.yarn.server.resourcemanager.security.AMRMTokenSecretManager: Create AMRMToken for ApplicationAttempt: appattempt_1778475288188_0008_000001
2026-05-11 13:48:10,324 INFO org.apache.hadoop.yarn.server.resourcemanager.security.AMRMTokenSecretManager: Creating password for appattempt_1778475288188_0008_000001
2026-05-11 13:48:10,339 INFO org.apache.hadoop.yarn.server.resourcemanager.amlauncher.AMLauncher: Done launching container Container: [ContainerId: container_1778475288188_0008_01_000001, AllocationRequestId: -1, Version: 0, NodeId: ubuntu:45565, NodeHttpAddress: ubuntu:8042, Resource: <memory:2048, vCores:1>, Priority: 0, Token: Token { kind: ContainerToken, service: 127.0.1.1:45565 }, ExecutionType: GUARANTEED, ] for AM appattempt_1778475288188_0008_000001
2026-05-11 13:48:10,340 INFO org.apache.hadoop.yarn.server.resourcemanager.rmapp.attempt.RMAppAttemptImpl: appattempt_1778475288188_0008_000001 State change from ALLOCATED to LAUNCHED on event = LAUNCHED
2026-05-11 13:48:10,340 INFO org.apache.hadoop.yarn.server.resourcemanager.rmapp.RMAppImpl: update the launch time for applicationId: application_1778475288188_0008, attemptId: appattempt_1778475288188_0008_000001launchTime: 1778478490339
2026-05-11 13:48:10,340 INFO org.apache.hadoop.yarn.server.resourcemanager.recovery.RMStateStore: Updating info for app: application_1778475288188_0008
2026-05-11 13:48:11,320 INFO org.apache.hadoop.yarn.server.resourcemanager.rmcontainer.RMContainerImpl: container_1778475288188_0008_01_000001 Container Transitioned from ACQUIRED to RUNNING
2026-05-11 13:48:14,538 INFO SecurityLogger.org.apache.hadoop.ipc.Server: Auth successful for appattempt_1778475288188_0008_000001 (auth:SIMPLE) from 127.0.0.1:56422
2026-05-11 13:48:14,541 INFO org.apache.hadoop.yarn.server.resourcemanager.DefaultAMSProcessor: AM registration appattempt_1778475288188_0008_000001
2026-05-11 13:48:14,541 INFO org.apache.hadoop.yarn.server.resourcemanager.rmapp.attempt.RMAppAttemptImpl: appattempt_1778475288188_0008_000001 State change from LAUNCHED to RUNNING on event = REGISTERED
2026-05-11 13:48:14,541 INFO org.apache.hadoop.yarn.server.resourcemanager.rmapp.RMAppImpl: application_1778475288188_0008 State change from ACCEPTED to RUNNING on event = ATTEMPT_REGISTERED
2026-05-11 13:48:16,332 INFO org.apache.hadoop.yarn.server.resourcemanager.scheduler.capacity.allocator.AbstractContainerAllocator: assignedContainer application attempt=appattempt_1778475288188_0008_000001 container=null queue=default clusterResource=<memory:8192, vCores:8> type=NODE_LOCAL requestedPartition=
2026-05-11 13:48:16,332 INFO org.apache.hadoop.yarn.server.resourcemanager.rmcontainer.RMContainerImpl: container_1778475288188_0008_01_000002 Container Transitioned from NEW to ALLOCATED
2026-05-11 13:48:16,333 INFO org.apache.hadoop.yarn.server.resourcemanager.scheduler.common.fica.FiCaSchedulerNode: Assigned container container_1778475288188_0008_01_000002 of capacity <memory:1024, vCores:1> on host ubuntu:45565, which has 2 containers, <memory:3072, vCores:2> used and <memory:5120, vCores:6> available after allocation
2026-05-11 13:48:16,333 INFO org.apache.hadoop.yarn.server.resourcemanager.scheduler.capacity.ParentQueue: assignedContainer queue=root usedCapacity=0.375 absoluteUsedCapacity=0.375 used=<memory:3072, vCores:2> cluster=<memory:8192, vCores:8>
2026-05-11 13:48:16,335 INFO org.apache.hadoop.yarn.server.resourcemanager.scheduler.capacity.allocator.AbstractContainerAllocator: assignedContainer application attempt=appattempt_1778475288188_0008_000001 container=null queue=default clusterResource=<memory:8192, vCores:8> type=NODE_LOCAL requestedPartition=
2026-05-11 13:48:16,337 INFO org.apache.hadoop.yarn.server.resourcemanager.rmcontainer.RMContainerImpl: container_1778475288188_0008_01_000003 Container Transitioned from NEW to ALLOCATED
2026-05-11 13:48:16,337 INFO org.apache.hadoop.yarn.server.resourcemanager.scheduler.common.fica.FiCaSchedulerNode: Assigned container container_1778475288188_0008_01_000003 of capacity <memory:1024, vCores:1> on host ubuntu:45565, which has 3 containers, <memory:4096, vCores:3> used and <memory:4096, vCores:5> available after allocation
2026-05-11 13:48:16,337 INFO org.apache.hadoop.yarn.server.resourcemanager.scheduler.capacity.ParentQueue: assignedContainer queue=root usedCapacity=0.5 absoluteUsedCapacity=0.5 used=<memory:4096, vCores:3> cluster=<memory:8192, vCores:8>
2026-05-11 13:48:16,338 INFO org.apache.hadoop.yarn.server.resourcemanager.scheduler.capacity.allocator.AbstractContainerAllocator: assignedContainer application attempt=appattempt_1778475288188_0008_000001 container=null queue=default clusterResource=<memory:8192, vCores:8> type=OFF_SWITCH requestedPartition=
2026-05-11 13:48:16,338 INFO org.apache.hadoop.yarn.server.resourcemanager.rmcontainer.RMContainerImpl: container_1778475288188_0008_01_000004 Container Transitioned from NEW to ALLOCATED
2026-05-11 13:48:16,338 INFO org.apache.hadoop.yarn.server.resourcemanager.scheduler.common.fica.FiCaSchedulerNode: Assigned container container_1778475288188_0008_01_000004 of capacity <memory:1024, vCores:1> on host ubuntu:45565, which has 4 containers, <memory:5120, vCores:4> used and <memory:3072, vCores:4> available after allocation
2026-05-11 13:48:16,339 INFO org.apache.hadoop.yarn.server.resourcemanager.scheduler.capacity.ParentQueue: assignedContainer queue=root usedCapacity=0.625 absoluteUsedCapacity=0.625 used=<memory:5120, vCores:4> cluster=<memory:8192, vCores:8>
2026-05-11 13:48:16,625 INFO org.apache.hadoop.yarn.server.resourcemanager.rmcontainer.RMContainerImpl: container_1778475288188_0008_01_000002 Container Transitioned from ALLOCATED to ACQUIRED
2026-05-11 13:48:16,625 INFO org.apache.hadoop.yarn.server.resourcemanager.rmcontainer.RMContainerImpl: container_1778475288188_0008_01_000003 Container Transitioned from ALLOCATED to ACQUIRED
2026-05-11 13:48:16,626 INFO org.apache.hadoop.yarn.server.resourcemanager.rmcontainer.RMContainerImpl: container_1778475288188_0008_01_000004 Container Transitioned from ALLOCATED to ACQUIRED
2026-05-11 13:48:17,334 INFO org.apache.hadoop.yarn.server.resourcemanager.rmcontainer.RMContainerImpl: container_1778475288188_0008_01_000002 Container Transitioned from ACQUIRED to RUNNING
2026-05-11 13:48:17,334 INFO org.apache.hadoop.yarn.server.resourcemanager.rmcontainer.RMContainerImpl: container_1778475288188_0008_01_000003 Container Transitioned from ACQUIRED to RUNNING
2026-05-11 13:48:17,334 INFO org.apache.hadoop.yarn.server.resourcemanager.rmcontainer.RMContainerImpl: container_1778475288188_0008_01_000004 Container Transitioned from ACQUIRED to RUNNING
2026-05-11 13:48:17,640 INFO org.apache.hadoop.yarn.server.resourcemanager.scheduler.AppSchedulingInfo: checking for deactivate of application :application_1778475288188_0008
2026-05-11 13:48:26,646 INFO org.apache.hadoop.yarn.server.resourcemanager.rmcontainer.RMContainerImpl: container_1778475288188_0008_01_000004 Container Transitioned from RUNNING to COMPLETED
2026-05-11 13:48:28,648 INFO org.apache.hadoop.yarn.server.resourcemanager.scheduler.capacity.allocator.AbstractContainerAllocator: assignedContainer application attempt=appattempt_1778475288188_0008_000001 container=null queue=default clusterResource=<memory:8192, vCores:8> type=OFF_SWITCH requestedPartition=
2026-05-11 13:48:28,648 INFO org.apache.hadoop.yarn.server.resourcemanager.rmcontainer.RMContainerImpl: container_1778475288188_0008_01_000005 Container Transitioned from NEW to ALLOCATED
2026-05-11 13:48:28,648 INFO org.apache.hadoop.yarn.server.resourcemanager.scheduler.common.fica.FiCaSchedulerNode: Assigned container container_1778475288188_0008_01_000005 of capacity <memory:1024, vCores:1> on host ubuntu:45565, which has 4 containers, <memory:5120, vCores:4> used and <memory:3072, vCores:4> available after allocation
2026-05-11 13:48:28,649 INFO org.apache.hadoop.yarn.server.resourcemanager.scheduler.capacity.ParentQueue: assignedContainer queue=root usedCapacity=0.625 absoluteUsedCapacity=0.625 used=<memory:5120, vCores:4> cluster=<memory:8192, vCores:8>
2026-05-11 13:48:28,757 INFO org.apache.hadoop.yarn.server.resourcemanager.rmcontainer.RMContainerImpl: container_1778475288188_0008_01_000005 Container Transitioned from ALLOCATED to ACQUIRED
2026-05-11 13:48:29,651 INFO org.apache.hadoop.yarn.server.resourcemanager.rmcontainer.RMContainerImpl: container_1778475288188_0008_01_000005 Container Transitioned from ACQUIRED to RUNNING
2026-05-11 13:48:29,761 INFO org.apache.hadoop.yarn.server.resourcemanager.scheduler.AppSchedulingInfo: checking for deactivate of application :application_1778475288188_0008
2026-05-11 13:48:30,768 INFO org.apache.hadoop.yarn.server.resourcemanager.scheduler.AppSchedulingInfo: checking for deactivate of application :application_1778475288188_0008
2026-05-11 13:48:31,024 INFO org.apache.hadoop.yarn.server.resourcemanager.rmcontainer.RMContainerImpl: container_1778475288188_0008_01_000002 Container Transitioned from RUNNING to COMPLETED
2026-05-11 13:48:31,855 INFO org.apache.hadoop.yarn.server.resourcemanager.rmcontainer.RMContainerImpl: container_1778475288188_0008_01_000003 Container Transitioned from RUNNING to COMPLETED
2026-05-11 13:48:33,255 INFO org.apache.hadoop.yarn.server.resourcemanager.rmcontainer.RMContainerImpl: container_1778475288188_0008_01_000005 Container Transitioned from RUNNING to COMPLETED
2026-05-11 13:48:33,417 INFO org.apache.hadoop.yarn.server.resourcemanager.rmapp.attempt.RMAppAttemptImpl: Updating application attempt appattempt_1778475288188_0008_000001 with final state: FINISHING, and exit status: -1000
2026-05-11 13:48:33,417 INFO org.apache.hadoop.yarn.server.resourcemanager.rmapp.attempt.RMAppAttemptImpl: appattempt_1778475288188_0008_000001 State change from RUNNING to FINAL_SAVING on event = UNREGISTERED
2026-05-11 13:48:33,417 INFO org.apache.hadoop.yarn.server.resourcemanager.rmapp.RMAppImpl: Updating application application_1778475288188_0008 with final state: FINISHING
2026-05-11 13:48:33,417 INFO org.apache.hadoop.yarn.server.resourcemanager.rmapp.RMAppImpl: application_1778475288188_0008 State change from RUNNING to FINAL_SAVING on event = ATTEMPT_UNREGISTERED
2026-05-11 13:48:33,417 INFO org.apache.hadoop.yarn.server.resourcemanager.recovery.RMStateStore: Updating info for app: application_1778475288188_0008
2026-05-11 13:48:33,417 INFO org.apache.hadoop.yarn.server.resourcemanager.rmapp.attempt.RMAppAttemptImpl: appattempt_1778475288188_0008_000001 State change from FINAL_SAVING to FINISHING on event = ATTEMPT_UPDATE_SAVED
2026-05-11 13:48:33,418 INFO org.apache.hadoop.yarn.server.resourcemanager.rmapp.RMAppImpl: application_1778475288188_0008 State change from FINAL_SAVING to FINISHING on event = APP_UPDATE_SAVED
2026-05-11 13:48:34,420 INFO org.apache.hadoop.yarn.server.resourcemanager.ApplicationMasterService: application_1778475288188_0008 unregistered successfully. 
2026-05-11 13:48:39,846 INFO org.apache.hadoop.yarn.server.resourcemanager.rmcontainer.RMContainerImpl: container_1778475288188_0008_01_000001 Container Transitioned from RUNNING to COMPLETED
2026-05-11 13:48:39,847 INFO org.apache.hadoop.yarn.server.resourcemanager.ApplicationMasterService: Unregistering app attempt : appattempt_1778475288188_0008_000001
2026-05-11 13:48:39,847 INFO org.apache.hadoop.yarn.server.resourcemanager.security.AMRMTokenSecretManager: Application finished, removing password for appattempt_1778475288188_0008_000001
2026-05-11 13:48:39,847 INFO org.apache.hadoop.yarn.server.resourcemanager.rmapp.attempt.RMAppAttemptImpl: appattempt_1778475288188_0008_000001 State change from FINISHING to FINISHED on event = CONTAINER_FINISHED
2026-05-11 13:48:39,855 INFO org.apache.hadoop.yarn.server.resourcemanager.rmapp.RMAppImpl: application_1778475288188_0008 State change from FINISHING to FINISHED on event = ATTEMPT_FINISHED
2026-05-11 13:48:39,860 INFO org.apache.hadoop.yarn.server.resourcemanager.scheduler.capacity.CapacityScheduler: Application Attempt appattempt_1778475288188_0008_000001 is done. finalState=FINISHED
2026-05-11 13:48:39,860 INFO org.apache.hadoop.yarn.server.resourcemanager.scheduler.AppSchedulingInfo: Application application_1778475288188_0008 requests cleared
2026-05-11 13:48:39,860 INFO org.apache.hadoop.yarn.server.resourcemanager.scheduler.capacity.LeafQueue: Application removed - appId: application_1778475288188_0008 user: cty1576 queue: root.default #user-pending-applications: 0 #user-active-applications: 0 #queue-pending-applications: 0 #queue-active-applications: 0
2026-05-11 13:48:39,861 INFO org.apache.hadoop.yarn.server.resourcemanager.scheduler.capacity.ParentQueue: Application removed - appId: application_1778475288188_0008 user: cty1576 leaf-queue of parent: root #applications: 0
2026-05-11 13:48:39,868 INFO org.apache.hadoop.yarn.server.resourcemanager.amlauncher.AMLauncher: Cleaning master appattempt_1778475288188_0008_000001
2026-05-11 13:48:39,868 INFO org.apache.hadoop.yarn.server.resourcemanager.RMAppManager$ApplicationSummary: appId=application_1778475288188_0008,name=SELECT MIN(event_date...user_behavior_detail (Stage-1),user=cty1576,queue=default,state=FINISHED,trackingUrl=http://ubuntu:8088/proxy/application_1778475288188_0008/,appMasterHost=ubuntu,submitTime=1778478489464,startTime=1778478489465,launchTime=1778478490339,finishTime=1778478513417,finalStatus=SUCCEEDED,memorySeconds=106680,vcoreSeconds=72,preemptedMemorySeconds=0,preemptedVcoreSeconds=0,preemptedAMContainers=0,preemptedNonAMContainers=0,preemptedResources=<memory:0\, vCores:0>,applicationType=MAPREDUCE,resourceSeconds=106680 MB-seconds\, 72 vcore-seconds,preemptedResourceSeconds=0 MB-seconds\, 0 vcore-seconds,applicationTags=,applicationNodeLabel=,diagnostics=,totalAllocatedContainers=5
2026-05-11 13:48:42,515 INFO org.apache.hadoop.yarn.server.resourcemanager.ClientRMService: Allocated new applicationId: 9
2026-05-11 13:48:43,232 INFO org.apache.hadoop.yarn.server.resourcemanager.scheduler.capacity.CapacityScheduler: Application 'application_1778475288188_0009' is submitted without priority hence considering default queue/cluster priority: 0
2026-05-11 13:48:43,233 INFO org.apache.hadoop.yarn.server.resourcemanager.scheduler.capacity.CapacityScheduler: Priority '0' is acceptable in queue : default for application: application_1778475288188_0009
2026-05-11 13:48:43,235 INFO org.apache.hadoop.yarn.server.resourcemanager.ClientRMService: Application with id 9 submitted by user cty1576
2026-05-11 13:48:43,235 INFO org.apache.hadoop.yarn.server.resourcemanager.rmapp.RMAppImpl: Storing application with id application_1778475288188_0009
2026-05-11 13:48:43,235 INFO org.apache.hadoop.yarn.server.resourcemanager.rmapp.RMAppImpl: application_1778475288188_0009 State change from NEW to NEW_SAVING on event = START
2026-05-11 13:48:43,236 INFO org.apache.hadoop.yarn.server.resourcemanager.recovery.RMStateStore: Storing info for app: application_1778475288188_0009
2026-05-11 13:48:43,236 INFO org.apache.hadoop.yarn.server.resourcemanager.rmapp.RMAppImpl: application_1778475288188_0009 State change from NEW_SAVING to SUBMITTED on event = APP_NEW_SAVED
2026-05-11 13:48:43,236 INFO org.apache.hadoop.yarn.server.resourcemanager.scheduler.capacity.ParentQueue: Application added - appId: application_1778475288188_0009 user: cty1576 leaf-queue of parent: root #applications: 1
2026-05-11 13:48:43,236 INFO org.apache.hadoop.yarn.server.resourcemanager.scheduler.capacity.CapacityScheduler: Accepted application application_1778475288188_0009 from user: cty1576, in queue: default
2026-05-11 13:48:43,236 INFO org.apache.hadoop.yarn.server.resourcemanager.rmapp.RMAppImpl: application_1778475288188_0009 State change from SUBMITTED to ACCEPTED on event = APP_ACCEPTED
2026-05-11 13:48:43,236 INFO org.apache.hadoop.yarn.server.resourcemanager.ApplicationMasterService: Registering app attempt : appattempt_1778475288188_0009_000001
2026-05-11 13:48:43,236 INFO org.apache.hadoop.yarn.server.resourcemanager.rmapp.attempt.RMAppAttemptImpl: appattempt_1778475288188_0009_000001 State change from NEW to SUBMITTED on event = START
2026-05-11 13:48:43,236 WARN org.apache.hadoop.yarn.server.resourcemanager.scheduler.capacity.LeafQueue: maximum-am-resource-percent is insufficient to start a single application in queue, it is likely set too low. skipping enforcement to allow at least one application to start
2026-05-11 13:48:43,236 WARN org.apache.hadoop.yarn.server.resourcemanager.scheduler.capacity.LeafQueue: maximum-am-resource-percent is insufficient to start a single application in queue for user, it is likely set too low. skipping enforcement to allow at least one application to start
2026-05-11 13:48:43,236 INFO org.apache.hadoop.yarn.server.resourcemanager.scheduler.capacity.LeafQueue: Application application_1778475288188_0009 from user: cty1576 activated in queue: root.default
2026-05-11 13:48:43,236 INFO org.apache.hadoop.yarn.server.resourcemanager.scheduler.capacity.LeafQueue: Application added - appId: application_1778475288188_0009 user: cty1576, leaf-queue: root.default #user-pending-applications: 0 #user-active-applications: 1 #queue-pending-applications: 0 #queue-active-applications: 1 #queue-nonrunnable-applications: 0
2026-05-11 13:48:43,236 INFO org.apache.hadoop.yarn.server.resourcemanager.scheduler.capacity.CapacityScheduler: Added Application Attempt appattempt_1778475288188_0009_000001 to scheduler from user cty1576 in queue root.default
2026-05-11 13:48:43,238 INFO org.apache.hadoop.yarn.server.resourcemanager.rmapp.attempt.RMAppAttemptImpl: appattempt_1778475288188_0009_000001 State change from SUBMITTED to SCHEDULED on event = ATTEMPT_ADDED
2026-05-11 13:48:43,854 INFO org.apache.hadoop.yarn.server.resourcemanager.scheduler.capacity.allocator.AbstractContainerAllocator: assignedContainer application attempt=appattempt_1778475288188_0009_000001 container=null queue=default clusterResource=<memory:8192, vCores:8> type=OFF_SWITCH requestedPartition=
2026-05-11 13:48:43,854 INFO org.apache.hadoop.yarn.server.resourcemanager.rmcontainer.RMContainerImpl: container_1778475288188_0009_01_000001 Container Transitioned from NEW to ALLOCATED
2026-05-11 13:48:43,854 INFO org.apache.hadoop.yarn.server.resourcemanager.scheduler.common.fica.FiCaSchedulerNode: Assigned container container_1778475288188_0009_01_000001 of capacity <memory:2048, vCores:1> on host ubuntu:45565, which has 1 containers, <memory:2048, vCores:1> used and <memory:6144, vCores:7> available after allocation
2026-05-11 13:48:43,855 INFO org.apache.hadoop.yarn.server.resourcemanager.scheduler.capacity.ParentQueue: assignedContainer queue=root usedCapacity=0.25 absoluteUsedCapacity=0.25 used=<memory:2048, vCores:1> cluster=<memory:8192, vCores:8>
2026-05-11 13:48:43,855 INFO org.apache.hadoop.yarn.server.resourcemanager.rmcontainer.RMContainerImpl: container_1778475288188_0009_01_000001 Container Transitioned from ALLOCATED to ACQUIRED
2026-05-11 13:48:43,856 INFO org.apache.hadoop.yarn.server.resourcemanager.security.NMTokenSecretManagerInRM: Clear node set for appattempt_1778475288188_0009_000001
2026-05-11 13:48:43,856 INFO org.apache.hadoop.yarn.server.resourcemanager.rmapp.attempt.RMAppAttemptImpl: Storing attempt: AppId: application_1778475288188_0009 AttemptId: appattempt_1778475288188_0009_000001 MasterContainer: Container: [ContainerId: container_1778475288188_0009_01_000001, AllocationRequestId: -1, Version: 0, NodeId: ubuntu:45565, NodeHttpAddress: ubuntu:8042, Resource: <memory:2048, vCores:1>, Priority: 0, Token: Token { kind: ContainerToken, service: 127.0.1.1:45565 }, ExecutionType: GUARANTEED, ]
2026-05-11 13:48:43,856 INFO org.apache.hadoop.yarn.server.resourcemanager.rmapp.attempt.RMAppAttemptImpl: appattempt_1778475288188_0009_000001 State change from SCHEDULED to ALLOCATED_SAVING on event = CONTAINER_ALLOCATED
2026-05-11 13:48:43,856 INFO org.apache.hadoop.yarn.server.resourcemanager.rmapp.attempt.RMAppAttemptImpl: appattempt_1778475288188_0009_000001 State change from ALLOCATED_SAVING to ALLOCATED on event = ATTEMPT_NEW_SAVED
2026-05-11 13:48:43,856 INFO org.apache.hadoop.yarn.server.resourcemanager.amlauncher.AMLauncher: Launching masterappattempt_1778475288188_0009_000001
2026-05-11 13:48:43,858 INFO org.apache.hadoop.yarn.server.resourcemanager.amlauncher.AMLauncher: Setting up container Container: [ContainerId: container_1778475288188_0009_01_000001, AllocationRequestId: -1, Version: 0, NodeId: ubuntu:45565, NodeHttpAddress: ubuntu:8042, Resource: <memory:2048, vCores:1>, Priority: 0, Token: Token { kind: ContainerToken, service: 127.0.1.1:45565 }, ExecutionType: GUARANTEED, ] for AM appattempt_1778475288188_0009_000001
2026-05-11 13:48:43,858 INFO org.apache.hadoop.yarn.server.resourcemanager.security.AMRMTokenSecretManager: Create AMRMToken for ApplicationAttempt: appattempt_1778475288188_0009_000001
2026-05-11 13:48:43,858 INFO org.apache.hadoop.yarn.server.resourcemanager.security.AMRMTokenSecretManager: Creating password for appattempt_1778475288188_0009_000001
2026-05-11 13:48:43,877 INFO org.apache.hadoop.yarn.server.resourcemanager.amlauncher.AMLauncher: Done launching container Container: [ContainerId: container_1778475288188_0009_01_000001, AllocationRequestId: -1, Version: 0, NodeId: ubuntu:45565, NodeHttpAddress: ubuntu:8042, Resource: <memory:2048, vCores:1>, Priority: 0, Token: Token { kind: ContainerToken, service: 127.0.1.1:45565 }, ExecutionType: GUARANTEED, ] for AM appattempt_1778475288188_0009_000001
2026-05-11 13:48:43,877 INFO org.apache.hadoop.yarn.server.resourcemanager.rmapp.attempt.RMAppAttemptImpl: appattempt_1778475288188_0009_000001 State change from ALLOCATED to LAUNCHED on event = LAUNCHED
2026-05-11 13:48:43,877 INFO org.apache.hadoop.yarn.server.resourcemanager.rmapp.RMAppImpl: update the launch time for applicationId: application_1778475288188_0009, attemptId: appattempt_1778475288188_0009_000001launchTime: 1778478523877
2026-05-11 13:48:43,877 INFO org.apache.hadoop.yarn.server.resourcemanager.recovery.RMStateStore: Updating info for app: application_1778475288188_0009
2026-05-11 13:48:44,854 INFO org.apache.hadoop.yarn.server.resourcemanager.rmcontainer.RMContainerImpl: container_1778475288188_0009_01_000001 Container Transitioned from ACQUIRED to RUNNING
2026-05-11 13:48:48,256 INFO SecurityLogger.org.apache.hadoop.ipc.Server: Auth successful for appattempt_1778475288188_0009_000001 (auth:SIMPLE) from 127.0.0.1:46868
2026-05-11 13:48:48,259 INFO org.apache.hadoop.yarn.server.resourcemanager.DefaultAMSProcessor: AM registration appattempt_1778475288188_0009_000001
2026-05-11 13:48:48,260 INFO org.apache.hadoop.yarn.server.resourcemanager.rmapp.attempt.RMAppAttemptImpl: appattempt_1778475288188_0009_000001 State change from LAUNCHED to RUNNING on event = REGISTERED
2026-05-11 13:48:48,260 INFO org.apache.hadoop.yarn.server.resourcemanager.rmapp.RMAppImpl: application_1778475288188_0009 State change from ACCEPTED to RUNNING on event = ATTEMPT_REGISTERED
2026-05-11 13:48:49,868 INFO org.apache.hadoop.yarn.server.resourcemanager.scheduler.capacity.allocator.AbstractContainerAllocator: assignedContainer application attempt=appattempt_1778475288188_0009_000001 container=null queue=default clusterResource=<memory:8192, vCores:8> type=NODE_LOCAL requestedPartition=
2026-05-11 13:48:49,868 INFO org.apache.hadoop.yarn.server.resourcemanager.rmcontainer.RMContainerImpl: container_1778475288188_0009_01_000002 Container Transitioned from NEW to ALLOCATED
2026-05-11 13:48:49,868 INFO org.apache.hadoop.yarn.server.resourcemanager.scheduler.common.fica.FiCaSchedulerNode: Assigned container container_1778475288188_0009_01_000002 of capacity <memory:1024, vCores:1> on host ubuntu:45565, which has 2 containers, <memory:3072, vCores:2> used and <memory:5120, vCores:6> available after allocation
2026-05-11 13:48:49,868 INFO org.apache.hadoop.yarn.server.resourcemanager.scheduler.capacity.ParentQueue: assignedContainer queue=root usedCapacity=0.375 absoluteUsedCapacity=0.375 used=<memory:3072, vCores:2> cluster=<memory:8192, vCores:8>
2026-05-11 13:48:50,338 INFO org.apache.hadoop.yarn.server.resourcemanager.rmcontainer.RMContainerImpl: container_1778475288188_0009_01_000002 Container Transitioned from ALLOCATED to ACQUIRED
2026-05-11 13:48:50,870 INFO org.apache.hadoop.yarn.server.resourcemanager.rmcontainer.RMContainerImpl: container_1778475288188_0009_01_000002 Container Transitioned from ACQUIRED to RUNNING
2026-05-11 13:48:51,354 INFO org.apache.hadoop.yarn.server.resourcemanager.scheduler.AppSchedulingInfo: checking for deactivate of application :application_1778475288188_0009
2026-05-11 13:48:53,769 INFO org.apache.hadoop.yarn.server.resourcemanager.rmcontainer.RMContainerImpl: container_1778475288188_0009_01_000002 Container Transitioned from RUNNING to COMPLETED
2026-05-11 13:48:54,772 INFO org.apache.hadoop.yarn.server.resourcemanager.scheduler.capacity.allocator.AbstractContainerAllocator: assignedContainer application attempt=appattempt_1778475288188_0009_000001 container=null queue=default clusterResource=<memory:8192, vCores:8> type=OFF_SWITCH requestedPartition=
2026-05-11 13:48:54,773 INFO org.apache.hadoop.yarn.server.resourcemanager.rmcontainer.RMContainerImpl: container_1778475288188_0009_01_000003 Container Transitioned from NEW to ALLOCATED
2026-05-11 13:48:54,774 INFO org.apache.hadoop.yarn.server.resourcemanager.scheduler.common.fica.FiCaSchedulerNode: Assigned container container_1778475288188_0009_01_000003 of capacity <memory:1024, vCores:1> on host ubuntu:45565, which has 2 containers, <memory:3072, vCores:2> used and <memory:5120, vCores:6> available after allocation
2026-05-11 13:48:54,775 INFO org.apache.hadoop.yarn.server.resourcemanager.scheduler.capacity.ParentQueue: assignedContainer queue=root usedCapacity=0.375 absoluteUsedCapacity=0.375 used=<memory:3072, vCores:2> cluster=<memory:8192, vCores:8>
2026-05-11 13:48:55,406 INFO org.apache.hadoop.yarn.server.resourcemanager.rmcontainer.RMContainerImpl: container_1778475288188_0009_01_000003 Container Transitioned from ALLOCATED to ACQUIRED
2026-05-11 13:48:55,774 INFO org.apache.hadoop.yarn.server.resourcemanager.rmcontainer.RMContainerImpl: container_1778475288188_0009_01_000003 Container Transitioned from ACQUIRED to RUNNING
2026-05-11 13:48:56,411 INFO org.apache.hadoop.yarn.server.resourcemanager.scheduler.AppSchedulingInfo: checking for deactivate of application :application_1778475288188_0009
2026-05-11 13:48:58,124 INFO org.apache.hadoop.yarn.server.resourcemanager.rmcontainer.RMContainerImpl: container_1778475288188_0009_01_000003 Container Transitioned from RUNNING to COMPLETED
2026-05-11 13:48:58,130 INFO org.apache.hadoop.yarn.server.resourcemanager.rmapp.attempt.RMAppAttemptImpl: Updating application attempt appattempt_1778475288188_0009_000001 with final state: FINISHING, and exit status: -1000
2026-05-11 13:48:58,130 INFO org.apache.hadoop.yarn.server.resourcemanager.rmapp.attempt.RMAppAttemptImpl: appattempt_1778475288188_0009_000001 State change from RUNNING to FINAL_SAVING on event = UNREGISTERED
2026-05-11 13:48:58,130 INFO org.apache.hadoop.yarn.server.resourcemanager.rmapp.RMAppImpl: Updating application application_1778475288188_0009 with final state: FINISHING
2026-05-11 13:48:58,130 INFO org.apache.hadoop.yarn.server.resourcemanager.rmapp.RMAppImpl: application_1778475288188_0009 State change from RUNNING to FINAL_SAVING on event = ATTEMPT_UNREGISTERED
2026-05-11 13:48:58,130 INFO org.apache.hadoop.yarn.server.resourcemanager.recovery.RMStateStore: Updating info for app: application_1778475288188_0009
2026-05-11 13:48:58,130 INFO org.apache.hadoop.yarn.server.resourcemanager.rmapp.attempt.RMAppAttemptImpl: appattempt_1778475288188_0009_000001 State change from FINAL_SAVING to FINISHING on event = ATTEMPT_UPDATE_SAVED
2026-05-11 13:48:58,132 INFO org.apache.hadoop.yarn.server.resourcemanager.rmapp.RMAppImpl: application_1778475288188_0009 State change from FINAL_SAVING to FINISHING on event = APP_UPDATE_SAVED
2026-05-11 13:48:59,151 INFO org.apache.hadoop.yarn.server.resourcemanager.ApplicationMasterService: application_1778475288188_0009 unregistered successfully. 
2026-05-11 13:49:04,588 INFO org.apache.hadoop.yarn.server.resourcemanager.rmcontainer.RMContainerImpl: container_1778475288188_0009_01_000001 Container Transitioned from RUNNING to COMPLETED
2026-05-11 13:49:04,588 INFO org.apache.hadoop.yarn.server.resourcemanager.ApplicationMasterService: Unregistering app attempt : appattempt_1778475288188_0009_000001
2026-05-11 13:49:04,588 INFO org.apache.hadoop.yarn.server.resourcemanager.security.AMRMTokenSecretManager: Application finished, removing password for appattempt_1778475288188_0009_000001
2026-05-11 13:49:04,588 INFO org.apache.hadoop.yarn.server.resourcemanager.rmapp.attempt.RMAppAttemptImpl: appattempt_1778475288188_0009_000001 State change from FINISHING to FINISHED on event = CONTAINER_FINISHED
2026-05-11 13:49:04,589 INFO org.apache.hadoop.yarn.server.resourcemanager.rmapp.RMAppImpl: application_1778475288188_0009 State change from FINISHING to FINISHED on event = ATTEMPT_FINISHED
2026-05-11 13:49:04,589 INFO org.apache.hadoop.yarn.server.resourcemanager.RMAppManager$ApplicationSummary: appId=application_1778475288188_0009,name=SELECT * FROM ads.daily_pv_uv O...event_date (Stage-1),user=cty1576,queue=default,state=FINISHED,trackingUrl=http://ubuntu:8088/proxy/application_1778475288188_0009/,appMasterHost=ubuntu,submitTime=1778478523232,startTime=1778478523233,launchTime=1778478523877,finishTime=1778478538130,finalStatus=SUCCEEDED,memorySeconds=49889,vcoreSeconds=26,preemptedMemorySeconds=0,preemptedVcoreSeconds=0,preemptedAMContainers=0,preemptedNonAMContainers=0,preemptedResources=<memory:0\, vCores:0>,applicationType=MAPREDUCE,resourceSeconds=49889 MB-seconds\, 26 vcore-seconds,preemptedResourceSeconds=0 MB-seconds\, 0 vcore-seconds,applicationTags=,applicationNodeLabel=,diagnostics=,totalAllocatedContainers=3
2026-05-11 13:49:04,589 INFO org.apache.hadoop.yarn.server.resourcemanager.scheduler.capacity.CapacityScheduler: Application Attempt appattempt_1778475288188_0009_000001 is done. finalState=FINISHED
2026-05-11 13:49:04,589 INFO org.apache.hadoop.yarn.server.resourcemanager.scheduler.AppSchedulingInfo: Application application_1778475288188_0009 requests cleared
2026-05-11 13:49:04,590 INFO org.apache.hadoop.yarn.server.resourcemanager.scheduler.capacity.LeafQueue: Application removed - appId: application_1778475288188_0009 user: cty1576 queue: root.default #user-pending-applications: 0 #user-active-applications: 0 #queue-pending-applications: 0 #queue-active-applications: 0
2026-05-11 13:49:04,590 INFO org.apache.hadoop.yarn.server.resourcemanager.scheduler.capacity.ParentQueue: Application removed - appId: application_1778475288188_0009 user: cty1576 leaf-queue of parent: root #applications: 0
2026-05-11 13:49:04,590 INFO org.apache.hadoop.yarn.server.resourcemanager.amlauncher.AMLauncher: Cleaning master appattempt_1778475288188_0009_000001
2026-05-11 13:49:05,973 INFO org.apache.hadoop.yarn.server.resourcemanager.ClientRMService: Allocated new applicationId: 10
2026-05-11 13:49:06,766 INFO org.apache.hadoop.yarn.server.resourcemanager.scheduler.capacity.CapacityScheduler: Application 'application_1778475288188_0010' is submitted without priority hence considering default queue/cluster priority: 0
2026-05-11 13:49:06,766 INFO org.apache.hadoop.yarn.server.resourcemanager.scheduler.capacity.CapacityScheduler: Priority '0' is acceptable in queue : default for application: application_1778475288188_0010
2026-05-11 13:49:06,766 INFO org.apache.hadoop.yarn.server.resourcemanager.ClientRMService: Application with id 10 submitted by user cty1576
2026-05-11 13:49:06,769 INFO org.apache.hadoop.yarn.server.resourcemanager.rmapp.RMAppImpl: Storing application with id application_1778475288188_0010
2026-05-11 13:49:06,769 INFO org.apache.hadoop.yarn.server.resourcemanager.rmapp.RMAppImpl: application_1778475288188_0010 State change from NEW to NEW_SAVING on event = START
2026-05-11 13:49:06,769 INFO org.apache.hadoop.yarn.server.resourcemanager.recovery.RMStateStore: Storing info for app: application_1778475288188_0010
2026-05-11 13:49:06,770 INFO org.apache.hadoop.yarn.server.resourcemanager.rmapp.RMAppImpl: application_1778475288188_0010 State change from NEW_SAVING to SUBMITTED on event = APP_NEW_SAVED
2026-05-11 13:49:06,770 INFO org.apache.hadoop.yarn.server.resourcemanager.scheduler.capacity.ParentQueue: Application added - appId: application_1778475288188_0010 user: cty1576 leaf-queue of parent: root #applications: 1
2026-05-11 13:49:06,770 INFO org.apache.hadoop.yarn.server.resourcemanager.scheduler.capacity.CapacityScheduler: Accepted application application_1778475288188_0010 from user: cty1576, in queue: default
2026-05-11 13:49:06,770 INFO org.apache.hadoop.yarn.server.resourcemanager.rmapp.RMAppImpl: application_1778475288188_0010 State change from SUBMITTED to ACCEPTED on event = APP_ACCEPTED
2026-05-11 13:49:06,770 INFO org.apache.hadoop.yarn.server.resourcemanager.ApplicationMasterService: Registering app attempt : appattempt_1778475288188_0010_000001
2026-05-11 13:49:06,770 INFO org.apache.hadoop.yarn.server.resourcemanager.rmapp.attempt.RMAppAttemptImpl: appattempt_1778475288188_0010_000001 State change from NEW to SUBMITTED on event = START
2026-05-11 13:49:06,772 WARN org.apache.hadoop.yarn.server.resourcemanager.scheduler.capacity.LeafQueue: maximum-am-resource-percent is insufficient to start a single application in queue, it is likely set too low. skipping enforcement to allow at least one application to start
2026-05-11 13:49:06,772 WARN org.apache.hadoop.yarn.server.resourcemanager.scheduler.capacity.LeafQueue: maximum-am-resource-percent is insufficient to start a single application in queue for user, it is likely set too low. skipping enforcement to allow at least one application to start
2026-05-11 13:49:06,772 INFO org.apache.hadoop.yarn.server.resourcemanager.scheduler.capacity.LeafQueue: Application application_1778475288188_0010 from user: cty1576 activated in queue: root.default
2026-05-11 13:49:06,772 INFO org.apache.hadoop.yarn.server.resourcemanager.scheduler.capacity.LeafQueue: Application added - appId: application_1778475288188_0010 user: cty1576, leaf-queue: root.default #user-pending-applications: 0 #user-active-applications: 1 #queue-pending-applications: 0 #queue-active-applications: 1 #queue-nonrunnable-applications: 0
2026-05-11 13:49:06,772 INFO org.apache.hadoop.yarn.server.resourcemanager.scheduler.capacity.CapacityScheduler: Added Application Attempt appattempt_1778475288188_0010_000001 to scheduler from user cty1576 in queue root.default
2026-05-11 13:49:06,773 INFO org.apache.hadoop.yarn.server.resourcemanager.rmapp.attempt.RMAppAttemptImpl: appattempt_1778475288188_0010_000001 State change from SUBMITTED to SCHEDULED on event = ATTEMPT_ADDED
2026-05-11 13:49:07,591 INFO org.apache.hadoop.yarn.server.resourcemanager.scheduler.capacity.allocator.AbstractContainerAllocator: assignedContainer application attempt=appattempt_1778475288188_0010_000001 container=null queue=default clusterResource=<memory:8192, vCores:8> type=OFF_SWITCH requestedPartition=
2026-05-11 13:49:07,591 INFO org.apache.hadoop.yarn.server.resourcemanager.rmcontainer.RMContainerImpl: container_1778475288188_0010_01_000001 Container Transitioned from NEW to ALLOCATED
2026-05-11 13:49:07,591 INFO org.apache.hadoop.yarn.server.resourcemanager.scheduler.common.fica.FiCaSchedulerNode: Assigned container container_1778475288188_0010_01_000001 of capacity <memory:2048, vCores:1> on host ubuntu:45565, which has 1 containers, <memory:2048, vCores:1> used and <memory:6144, vCores:7> available after allocation
2026-05-11 13:49:07,591 INFO org.apache.hadoop.yarn.server.resourcemanager.scheduler.capacity.ParentQueue: assignedContainer queue=root usedCapacity=0.25 absoluteUsedCapacity=0.25 used=<memory:2048, vCores:1> cluster=<memory:8192, vCores:8>
2026-05-11 13:49:07,593 INFO org.apache.hadoop.yarn.server.resourcemanager.rmcontainer.RMContainerImpl: container_1778475288188_0010_01_000001 Container Transitioned from ALLOCATED to ACQUIRED
2026-05-11 13:49:07,593 INFO org.apache.hadoop.yarn.server.resourcemanager.security.NMTokenSecretManagerInRM: Clear node set for appattempt_1778475288188_0010_000001
2026-05-11 13:49:07,593 INFO org.apache.hadoop.yarn.server.resourcemanager.rmapp.attempt.RMAppAttemptImpl: Storing attempt: AppId: application_1778475288188_0010 AttemptId: appattempt_1778475288188_0010_000001 MasterContainer: Container: [ContainerId: container_1778475288188_0010_01_000001, AllocationRequestId: -1, Version: 0, NodeId: ubuntu:45565, NodeHttpAddress: ubuntu:8042, Resource: <memory:2048, vCores:1>, Priority: 0, Token: Token { kind: ContainerToken, service: 127.0.1.1:45565 }, ExecutionType: GUARANTEED, ]
2026-05-11 13:49:07,593 INFO org.apache.hadoop.yarn.server.resourcemanager.rmapp.attempt.RMAppAttemptImpl: appattempt_1778475288188_0010_000001 State change from SCHEDULED to ALLOCATED_SAVING on event = CONTAINER_ALLOCATED
2026-05-11 13:49:07,593 INFO org.apache.hadoop.yarn.server.resourcemanager.rmapp.attempt.RMAppAttemptImpl: appattempt_1778475288188_0010_000001 State change from ALLOCATED_SAVING to ALLOCATED on event = ATTEMPT_NEW_SAVED
2026-05-11 13:49:07,595 INFO org.apache.hadoop.yarn.server.resourcemanager.amlauncher.AMLauncher: Launching masterappattempt_1778475288188_0010_000001
2026-05-11 13:49:07,600 INFO org.apache.hadoop.yarn.server.resourcemanager.amlauncher.AMLauncher: Setting up container Container: [ContainerId: container_1778475288188_0010_01_000001, AllocationRequestId: -1, Version: 0, NodeId: ubuntu:45565, NodeHttpAddress: ubuntu:8042, Resource: <memory:2048, vCores:1>, Priority: 0, Token: Token { kind: ContainerToken, service: 127.0.1.1:45565 }, ExecutionType: GUARANTEED, ] for AM appattempt_1778475288188_0010_000001
2026-05-11 13:49:07,600 INFO org.apache.hadoop.yarn.server.resourcemanager.security.AMRMTokenSecretManager: Create AMRMToken for ApplicationAttempt: appattempt_1778475288188_0010_000001
2026-05-11 13:49:07,600 INFO org.apache.hadoop.yarn.server.resourcemanager.security.AMRMTokenSecretManager: Creating password for appattempt_1778475288188_0010_000001
2026-05-11 13:49:07,623 INFO org.apache.hadoop.yarn.server.resourcemanager.amlauncher.AMLauncher: Done launching container Container: [ContainerId: container_1778475288188_0010_01_000001, AllocationRequestId: -1, Version: 0, NodeId: ubuntu:45565, NodeHttpAddress: ubuntu:8042, Resource: <memory:2048, vCores:1>, Priority: 0, Token: Token { kind: ContainerToken, service: 127.0.1.1:45565 }, ExecutionType: GUARANTEED, ] for AM appattempt_1778475288188_0010_000001
2026-05-11 13:49:07,623 INFO org.apache.hadoop.yarn.server.resourcemanager.rmapp.attempt.RMAppAttemptImpl: appattempt_1778475288188_0010_000001 State change from ALLOCATED to LAUNCHED on event = LAUNCHED
2026-05-11 13:49:07,625 INFO org.apache.hadoop.yarn.server.resourcemanager.rmapp.RMAppImpl: update the launch time for applicationId: application_1778475288188_0010, attemptId: appattempt_1778475288188_0010_000001launchTime: 1778478547623
2026-05-11 13:49:07,625 INFO org.apache.hadoop.yarn.server.resourcemanager.recovery.RMStateStore: Updating info for app: application_1778475288188_0010
2026-05-11 13:49:08,592 INFO org.apache.hadoop.yarn.server.resourcemanager.rmcontainer.RMContainerImpl: container_1778475288188_0010_01_000001 Container Transitioned from ACQUIRED to RUNNING
2026-05-11 13:49:11,655 INFO SecurityLogger.org.apache.hadoop.ipc.Server: Auth successful for appattempt_1778475288188_0010_000001 (auth:SIMPLE) from 127.0.0.1:58176
2026-05-11 13:49:11,657 INFO org.apache.hadoop.yarn.server.resourcemanager.DefaultAMSProcessor: AM registration appattempt_1778475288188_0010_000001
2026-05-11 13:49:11,658 INFO org.apache.hadoop.yarn.server.resourcemanager.rmapp.attempt.RMAppAttemptImpl: appattempt_1778475288188_0010_000001 State change from LAUNCHED to RUNNING on event = REGISTERED
2026-05-11 13:49:11,658 INFO org.apache.hadoop.yarn.server.resourcemanager.rmapp.RMAppImpl: application_1778475288188_0010 State change from ACCEPTED to RUNNING on event = ATTEMPT_REGISTERED
2026-05-11 13:49:13,604 INFO org.apache.hadoop.yarn.server.resourcemanager.scheduler.capacity.allocator.AbstractContainerAllocator: assignedContainer application attempt=appattempt_1778475288188_0010_000001 container=null queue=default clusterResource=<memory:8192, vCores:8> type=NODE_LOCAL requestedPartition=
2026-05-11 13:49:13,605 INFO org.apache.hadoop.yarn.server.resourcemanager.rmcontainer.RMContainerImpl: container_1778475288188_0010_01_000002 Container Transitioned from NEW to ALLOCATED
2026-05-11 13:49:13,605 INFO org.apache.hadoop.yarn.server.resourcemanager.scheduler.common.fica.FiCaSchedulerNode: Assigned container container_1778475288188_0010_01_000002 of capacity <memory:1024, vCores:1> on host ubuntu:45565, which has 2 containers, <memory:3072, vCores:2> used and <memory:5120, vCores:6> available after allocation
2026-05-11 13:49:13,605 INFO org.apache.hadoop.yarn.server.resourcemanager.scheduler.capacity.ParentQueue: assignedContainer queue=root usedCapacity=0.375 absoluteUsedCapacity=0.375 used=<memory:3072, vCores:2> cluster=<memory:8192, vCores:8>
2026-05-11 13:49:13,719 INFO org.apache.hadoop.yarn.server.resourcemanager.rmcontainer.RMContainerImpl: container_1778475288188_0010_01_000002 Container Transitioned from ALLOCATED to ACQUIRED
2026-05-11 13:49:14,610 INFO org.apache.hadoop.yarn.server.resourcemanager.rmcontainer.RMContainerImpl: container_1778475288188_0010_01_000002 Container Transitioned from ACQUIRED to RUNNING
2026-05-11 13:49:14,733 INFO org.apache.hadoop.yarn.server.resourcemanager.scheduler.AppSchedulingInfo: checking for deactivate of application :application_1778475288188_0010
2026-05-11 13:49:17,779 INFO org.apache.hadoop.yarn.server.resourcemanager.rmcontainer.RMContainerImpl: container_1778475288188_0010_01_000002 Container Transitioned from RUNNING to COMPLETED
2026-05-11 13:49:18,780 INFO org.apache.hadoop.yarn.server.resourcemanager.scheduler.capacity.allocator.AbstractContainerAllocator: assignedContainer application attempt=appattempt_1778475288188_0010_000001 container=null queue=default clusterResource=<memory:8192, vCores:8> type=OFF_SWITCH requestedPartition=
2026-05-11 13:49:18,780 INFO org.apache.hadoop.yarn.server.resourcemanager.rmcontainer.RMContainerImpl: container_1778475288188_0010_01_000003 Container Transitioned from NEW to ALLOCATED
2026-05-11 13:49:18,780 INFO org.apache.hadoop.yarn.server.resourcemanager.scheduler.common.fica.FiCaSchedulerNode: Assigned container container_1778475288188_0010_01_000003 of capacity <memory:1024, vCores:1> on host ubuntu:45565, which has 2 containers, <memory:3072, vCores:2> used and <memory:5120, vCores:6> available after allocation
2026-05-11 13:49:18,781 INFO org.apache.hadoop.yarn.server.resourcemanager.scheduler.capacity.ParentQueue: assignedContainer queue=root usedCapacity=0.375 absoluteUsedCapacity=0.375 used=<memory:3072, vCores:2> cluster=<memory:8192, vCores:8>
2026-05-11 13:49:19,766 INFO org.apache.hadoop.yarn.server.resourcemanager.rmcontainer.RMContainerImpl: container_1778475288188_0010_01_000003 Container Transitioned from ALLOCATED to ACQUIRED
2026-05-11 13:49:20,772 INFO org.apache.hadoop.yarn.server.resourcemanager.scheduler.AppSchedulingInfo: checking for deactivate of application :application_1778475288188_0010
2026-05-11 13:49:20,785 INFO org.apache.hadoop.yarn.server.resourcemanager.rmcontainer.RMContainerImpl: container_1778475288188_0010_01_000003 Container Transitioned from ACQUIRED to RUNNING
2026-05-11 13:49:22,953 INFO org.apache.hadoop.yarn.server.resourcemanager.rmcontainer.RMContainerImpl: container_1778475288188_0010_01_000003 Container Transitioned from RUNNING to COMPLETED
2026-05-11 13:49:22,969 INFO org.apache.hadoop.yarn.server.resourcemanager.rmapp.attempt.RMAppAttemptImpl: Updating application attempt appattempt_1778475288188_0010_000001 with final state: FINISHING, and exit status: -1000
2026-05-11 13:49:22,969 INFO org.apache.hadoop.yarn.server.resourcemanager.rmapp.attempt.RMAppAttemptImpl: appattempt_1778475288188_0010_000001 State change from RUNNING to FINAL_SAVING on event = UNREGISTERED
2026-05-11 13:49:22,969 INFO org.apache.hadoop.yarn.server.resourcemanager.rmapp.attempt.RMAppAttemptImpl: appattempt_1778475288188_0010_000001 State change from FINAL_SAVING to FINISHING on event = ATTEMPT_UPDATE_SAVED
2026-05-11 13:49:22,970 INFO org.apache.hadoop.yarn.server.resourcemanager.rmapp.RMAppImpl: Updating application application_1778475288188_0010 with final state: FINISHING
2026-05-11 13:49:22,970 INFO org.apache.hadoop.yarn.server.resourcemanager.recovery.RMStateStore: Updating info for app: application_1778475288188_0010
2026-05-11 13:49:22,970 INFO org.apache.hadoop.yarn.server.resourcemanager.rmapp.RMAppImpl: application_1778475288188_0010 State change from RUNNING to FINAL_SAVING on event = ATTEMPT_UNREGISTERED
2026-05-11 13:49:22,970 INFO org.apache.hadoop.yarn.server.resourcemanager.rmapp.RMAppImpl: application_1778475288188_0010 State change from FINAL_SAVING to FINISHING on event = APP_UPDATE_SAVED
2026-05-11 13:49:23,978 INFO org.apache.hadoop.yarn.server.resourcemanager.ApplicationMasterService: application_1778475288188_0010 unregistered successfully. 
2026-05-11 13:49:29,400 INFO org.apache.hadoop.yarn.server.resourcemanager.rmcontainer.RMContainerImpl: container_1778475288188_0010_01_000001 Container Transitioned from RUNNING to COMPLETED
2026-05-11 13:49:29,400 INFO org.apache.hadoop.yarn.server.resourcemanager.ApplicationMasterService: Unregistering app attempt : appattempt_1778475288188_0010_000001
2026-05-11 13:49:29,400 INFO org.apache.hadoop.yarn.server.resourcemanager.security.AMRMTokenSecretManager: Application finished, removing password for appattempt_1778475288188_0010_000001
2026-05-11 13:49:29,400 INFO org.apache.hadoop.yarn.server.resourcemanager.rmapp.attempt.RMAppAttemptImpl: appattempt_1778475288188_0010_000001 State change from FINISHING to FINISHED on event = CONTAINER_FINISHED
2026-05-11 13:49:29,401 INFO org.apache.hadoop.yarn.server.resourcemanager.rmapp.RMAppImpl: application_1778475288188_0010 State change from FINISHING to FINISHED on event = ATTEMPT_FINISHED
2026-05-11 13:49:29,404 INFO org.apache.hadoop.yarn.server.resourcemanager.RMAppManager$ApplicationSummary: appId=application_1778475288188_0010,name=SELECT * FROM ads.hourly_distri...event_hour (Stage-1),user=cty1576,queue=default,state=FINISHED,trackingUrl=http://ubuntu:8088/proxy/application_1778475288188_0010/,appMasterHost=ubuntu,submitTime=1778478546765,startTime=1778478546766,launchTime=1778478547623,finishTime=1778478562970,finalStatus=SUCCEEDED,memorySeconds=53214,vcoreSeconds=29,preemptedMemorySeconds=0,preemptedVcoreSeconds=0,preemptedAMContainers=0,preemptedNonAMContainers=0,preemptedResources=<memory:0\, vCores:0>,applicationType=MAPREDUCE,resourceSeconds=53214 MB-seconds\, 29 vcore-seconds,preemptedResourceSeconds=0 MB-seconds\, 0 vcore-seconds,applicationTags=,applicationNodeLabel=,diagnostics=,totalAllocatedContainers=3
2026-05-11 13:49:29,404 INFO org.apache.hadoop.yarn.server.resourcemanager.scheduler.capacity.CapacityScheduler: Application Attempt appattempt_1778475288188_0010_000001 is done. finalState=FINISHED
2026-05-11 13:49:29,404 INFO org.apache.hadoop.yarn.server.resourcemanager.scheduler.AppSchedulingInfo: Application application_1778475288188_0010 requests cleared
2026-05-11 13:49:29,404 INFO org.apache.hadoop.yarn.server.resourcemanager.scheduler.capacity.LeafQueue: Application removed - appId: application_1778475288188_0010 user: cty1576 queue: root.default #user-pending-applications: 0 #user-active-applications: 0 #queue-pending-applications: 0 #queue-active-applications: 0
2026-05-11 13:49:29,404 INFO org.apache.hadoop.yarn.server.resourcemanager.scheduler.capacity.ParentQueue: Application removed - appId: application_1778475288188_0010 user: cty1576 leaf-queue of parent: root #applications: 0
2026-05-11 13:49:29,407 INFO org.apache.hadoop.yarn.server.resourcemanager.amlauncher.AMLauncher: Cleaning master appattempt_1778475288188_0010_000001
2026-05-11 13:50:04,171 INFO org.apache.hadoop.yarn.server.resourcemanager.ClientRMService: Allocated new applicationId: 11
2026-05-11 13:50:04,980 INFO org.apache.hadoop.yarn.server.resourcemanager.scheduler.capacity.CapacityScheduler: Application 'application_1778475288188_0011' is submitted without priority hence considering default queue/cluster priority: 0
2026-05-11 13:50:04,980 INFO org.apache.hadoop.yarn.server.resourcemanager.scheduler.capacity.CapacityScheduler: Priority '0' is acceptable in queue : default for application: application_1778475288188_0011
2026-05-11 13:50:04,980 INFO org.apache.hadoop.yarn.server.resourcemanager.ClientRMService: Application with id 11 submitted by user cty1576
2026-05-11 13:50:04,981 INFO org.apache.hadoop.yarn.server.resourcemanager.rmapp.RMAppImpl: Storing application with id application_1778475288188_0011
2026-05-11 13:50:04,981 INFO org.apache.hadoop.yarn.server.resourcemanager.rmapp.RMAppImpl: application_1778475288188_0011 State change from NEW to NEW_SAVING on event = START
2026-05-11 13:50:04,981 INFO org.apache.hadoop.yarn.server.resourcemanager.recovery.RMStateStore: Storing info for app: application_1778475288188_0011
2026-05-11 13:50:04,984 INFO org.apache.hadoop.yarn.server.resourcemanager.rmapp.RMAppImpl: application_1778475288188_0011 State change from NEW_SAVING to SUBMITTED on event = APP_NEW_SAVED
2026-05-11 13:50:04,985 INFO org.apache.hadoop.yarn.server.resourcemanager.scheduler.capacity.ParentQueue: Application added - appId: application_1778475288188_0011 user: cty1576 leaf-queue of parent: root #applications: 1
2026-05-11 13:50:04,988 INFO org.apache.hadoop.yarn.server.resourcemanager.scheduler.capacity.CapacityScheduler: Accepted application application_1778475288188_0011 from user: cty1576, in queue: default
2026-05-11 13:50:04,988 INFO org.apache.hadoop.yarn.server.resourcemanager.rmapp.RMAppImpl: application_1778475288188_0011 State change from SUBMITTED to ACCEPTED on event = APP_ACCEPTED
2026-05-11 13:50:04,988 INFO org.apache.hadoop.yarn.server.resourcemanager.ApplicationMasterService: Registering app attempt : appattempt_1778475288188_0011_000001
2026-05-11 13:50:04,989 INFO org.apache.hadoop.yarn.server.resourcemanager.rmapp.attempt.RMAppAttemptImpl: appattempt_1778475288188_0011_000001 State change from NEW to SUBMITTED on event = START
2026-05-11 13:50:04,990 WARN org.apache.hadoop.yarn.server.resourcemanager.scheduler.capacity.LeafQueue: maximum-am-resource-percent is insufficient to start a single application in queue, it is likely set too low. skipping enforcement to allow at least one application to start
2026-05-11 13:50:04,990 WARN org.apache.hadoop.yarn.server.resourcemanager.scheduler.capacity.LeafQueue: maximum-am-resource-percent is insufficient to start a single application in queue for user, it is likely set too low. skipping enforcement to allow at least one application to start
2026-05-11 13:50:04,990 INFO org.apache.hadoop.yarn.server.resourcemanager.scheduler.capacity.LeafQueue: Application application_1778475288188_0011 from user: cty1576 activated in queue: root.default
2026-05-11 13:50:04,990 INFO org.apache.hadoop.yarn.server.resourcemanager.scheduler.capacity.LeafQueue: Application added - appId: application_1778475288188_0011 user: cty1576, leaf-queue: root.default #user-pending-applications: 0 #user-active-applications: 1 #queue-pending-applications: 0 #queue-active-applications: 1 #queue-nonrunnable-applications: 0
2026-05-11 13:50:04,990 INFO org.apache.hadoop.yarn.server.resourcemanager.scheduler.capacity.CapacityScheduler: Added Application Attempt appattempt_1778475288188_0011_000001 to scheduler from user cty1576 in queue root.default
2026-05-11 13:50:04,991 INFO org.apache.hadoop.yarn.server.resourcemanager.rmapp.attempt.RMAppAttemptImpl: appattempt_1778475288188_0011_000001 State change from SUBMITTED to SCHEDULED on event = ATTEMPT_ADDED
2026-05-11 13:50:05,489 INFO org.apache.hadoop.yarn.server.resourcemanager.scheduler.capacity.allocator.AbstractContainerAllocator: assignedContainer application attempt=appattempt_1778475288188_0011_000001 container=null queue=default clusterResource=<memory:8192, vCores:8> type=OFF_SWITCH requestedPartition=
2026-05-11 13:50:05,490 INFO org.apache.hadoop.yarn.server.resourcemanager.rmcontainer.RMContainerImpl: container_1778475288188_0011_01_000001 Container Transitioned from NEW to ALLOCATED
2026-05-11 13:50:05,490 INFO org.apache.hadoop.yarn.server.resourcemanager.scheduler.common.fica.FiCaSchedulerNode: Assigned container container_1778475288188_0011_01_000001 of capacity <memory:2048, vCores:1> on host ubuntu:45565, which has 1 containers, <memory:2048, vCores:1> used and <memory:6144, vCores:7> available after allocation
2026-05-11 13:50:05,493 INFO org.apache.hadoop.yarn.server.resourcemanager.scheduler.capacity.ParentQueue: assignedContainer queue=root usedCapacity=0.25 absoluteUsedCapacity=0.25 used=<memory:2048, vCores:1> cluster=<memory:8192, vCores:8>
2026-05-11 13:50:05,495 INFO org.apache.hadoop.yarn.server.resourcemanager.rmcontainer.RMContainerImpl: container_1778475288188_0011_01_000001 Container Transitioned from ALLOCATED to ACQUIRED
2026-05-11 13:50:05,495 INFO org.apache.hadoop.yarn.server.resourcemanager.security.NMTokenSecretManagerInRM: Clear node set for appattempt_1778475288188_0011_000001
2026-05-11 13:50:05,495 INFO org.apache.hadoop.yarn.server.resourcemanager.rmapp.attempt.RMAppAttemptImpl: Storing attempt: AppId: application_1778475288188_0011 AttemptId: appattempt_1778475288188_0011_000001 MasterContainer: Container: [ContainerId: container_1778475288188_0011_01_000001, AllocationRequestId: -1, Version: 0, NodeId: ubuntu:45565, NodeHttpAddress: ubuntu:8042, Resource: <memory:2048, vCores:1>, Priority: 0, Token: Token { kind: ContainerToken, service: 127.0.1.1:45565 }, ExecutionType: GUARANTEED, ]
2026-05-11 13:50:05,495 INFO org.apache.hadoop.yarn.server.resourcemanager.rmapp.attempt.RMAppAttemptImpl: appattempt_1778475288188_0011_000001 State change from SCHEDULED to ALLOCATED_SAVING on event = CONTAINER_ALLOCATED
2026-05-11 13:50:05,495 INFO org.apache.hadoop.yarn.server.resourcemanager.rmapp.attempt.RMAppAttemptImpl: appattempt_1778475288188_0011_000001 State change from ALLOCATED_SAVING to ALLOCATED on event = ATTEMPT_NEW_SAVED
2026-05-11 13:50:05,497 INFO org.apache.hadoop.yarn.server.resourcemanager.amlauncher.AMLauncher: Launching masterappattempt_1778475288188_0011_000001
2026-05-11 13:50:05,507 INFO org.apache.hadoop.yarn.server.resourcemanager.amlauncher.AMLauncher: Setting up container Container: [ContainerId: container_1778475288188_0011_01_000001, AllocationRequestId: -1, Version: 0, NodeId: ubuntu:45565, NodeHttpAddress: ubuntu:8042, Resource: <memory:2048, vCores:1>, Priority: 0, Token: Token { kind: ContainerToken, service: 127.0.1.1:45565 }, ExecutionType: GUARANTEED, ] for AM appattempt_1778475288188_0011_000001
2026-05-11 13:50:05,508 INFO org.apache.hadoop.yarn.server.resourcemanager.security.AMRMTokenSecretManager: Create AMRMToken for ApplicationAttempt: appattempt_1778475288188_0011_000001
2026-05-11 13:50:05,508 INFO org.apache.hadoop.yarn.server.resourcemanager.security.AMRMTokenSecretManager: Creating password for appattempt_1778475288188_0011_000001
2026-05-11 13:50:05,530 INFO org.apache.hadoop.yarn.server.resourcemanager.amlauncher.AMLauncher: Done launching container Container: [ContainerId: container_1778475288188_0011_01_000001, AllocationRequestId: -1, Version: 0, NodeId: ubuntu:45565, NodeHttpAddress: ubuntu:8042, Resource: <memory:2048, vCores:1>, Priority: 0, Token: Token { kind: ContainerToken, service: 127.0.1.1:45565 }, ExecutionType: GUARANTEED, ] for AM appattempt_1778475288188_0011_000001
2026-05-11 13:50:05,530 INFO org.apache.hadoop.yarn.server.resourcemanager.rmapp.attempt.RMAppAttemptImpl: appattempt_1778475288188_0011_000001 State change from ALLOCATED to LAUNCHED on event = LAUNCHED
2026-05-11 13:50:05,530 INFO org.apache.hadoop.yarn.server.resourcemanager.rmapp.RMAppImpl: update the launch time for applicationId: application_1778475288188_0011, attemptId: appattempt_1778475288188_0011_000001launchTime: 1778478605530
2026-05-11 13:50:05,531 INFO org.apache.hadoop.yarn.server.resourcemanager.recovery.RMStateStore: Updating info for app: application_1778475288188_0011
2026-05-11 13:50:06,491 INFO org.apache.hadoop.yarn.server.resourcemanager.rmcontainer.RMContainerImpl: container_1778475288188_0011_01_000001 Container Transitioned from ACQUIRED to RUNNING
2026-05-11 13:50:09,780 INFO SecurityLogger.org.apache.hadoop.ipc.Server: Auth successful for appattempt_1778475288188_0011_000001 (auth:SIMPLE) from 127.0.0.1:43170
2026-05-11 13:50:09,783 INFO org.apache.hadoop.yarn.server.resourcemanager.DefaultAMSProcessor: AM registration appattempt_1778475288188_0011_000001
2026-05-11 13:50:09,783 INFO org.apache.hadoop.yarn.server.resourcemanager.rmapp.attempt.RMAppAttemptImpl: appattempt_1778475288188_0011_000001 State change from LAUNCHED to RUNNING on event = REGISTERED
2026-05-11 13:50:09,784 INFO org.apache.hadoop.yarn.server.resourcemanager.rmapp.RMAppImpl: application_1778475288188_0011 State change from ACCEPTED to RUNNING on event = ATTEMPT_REGISTERED
2026-05-11 13:50:11,504 INFO org.apache.hadoop.yarn.server.resourcemanager.scheduler.capacity.allocator.AbstractContainerAllocator: assignedContainer application attempt=appattempt_1778475288188_0011_000001 container=null queue=default clusterResource=<memory:8192, vCores:8> type=NODE_LOCAL requestedPartition=
2026-05-11 13:50:11,505 INFO org.apache.hadoop.yarn.server.resourcemanager.rmcontainer.RMContainerImpl: container_1778475288188_0011_01_000002 Container Transitioned from NEW to ALLOCATED
2026-05-11 13:50:11,505 INFO org.apache.hadoop.yarn.server.resourcemanager.scheduler.common.fica.FiCaSchedulerNode: Assigned container container_1778475288188_0011_01_000002 of capacity <memory:1024, vCores:1> on host ubuntu:45565, which has 2 containers, <memory:3072, vCores:2> used and <memory:5120, vCores:6> available after allocation
2026-05-11 13:50:11,505 INFO org.apache.hadoop.yarn.server.resourcemanager.scheduler.capacity.ParentQueue: assignedContainer queue=root usedCapacity=0.375 absoluteUsedCapacity=0.375 used=<memory:3072, vCores:2> cluster=<memory:8192, vCores:8>
2026-05-11 13:50:11,850 INFO org.apache.hadoop.yarn.server.resourcemanager.rmcontainer.RMContainerImpl: container_1778475288188_0011_01_000002 Container Transitioned from ALLOCATED to ACQUIRED
2026-05-11 13:50:12,505 INFO org.apache.hadoop.yarn.server.resourcemanager.rmcontainer.RMContainerImpl: container_1778475288188_0011_01_000002 Container Transitioned from ACQUIRED to RUNNING
2026-05-11 13:50:12,865 INFO org.apache.hadoop.yarn.server.resourcemanager.scheduler.AppSchedulingInfo: checking for deactivate of application :application_1778475288188_0011
2026-05-11 13:50:14,977 INFO org.apache.hadoop.yarn.server.resourcemanager.rmcontainer.RMContainerImpl: container_1778475288188_0011_01_000002 Container Transitioned from RUNNING to COMPLETED
2026-05-11 13:50:15,976 INFO org.apache.hadoop.yarn.server.resourcemanager.scheduler.capacity.allocator.AbstractContainerAllocator: assignedContainer application attempt=appattempt_1778475288188_0011_000001 container=null queue=default clusterResource=<memory:8192, vCores:8> type=OFF_SWITCH requestedPartition=
2026-05-11 13:50:15,977 INFO org.apache.hadoop.yarn.server.resourcemanager.rmcontainer.RMContainerImpl: container_1778475288188_0011_01_000003 Container Transitioned from NEW to ALLOCATED
2026-05-11 13:50:15,977 INFO org.apache.hadoop.yarn.server.resourcemanager.scheduler.common.fica.FiCaSchedulerNode: Assigned container container_1778475288188_0011_01_000003 of capacity <memory:1024, vCores:1> on host ubuntu:45565, which has 2 containers, <memory:3072, vCores:2> used and <memory:5120, vCores:6> available after allocation
2026-05-11 13:50:15,978 INFO org.apache.hadoop.yarn.server.resourcemanager.scheduler.capacity.ParentQueue: assignedContainer queue=root usedCapacity=0.375 absoluteUsedCapacity=0.375 used=<memory:3072, vCores:2> cluster=<memory:8192, vCores:8>
2026-05-11 13:50:16,884 INFO org.apache.hadoop.yarn.server.resourcemanager.rmcontainer.RMContainerImpl: container_1778475288188_0011_01_000003 Container Transitioned from ALLOCATED to ACQUIRED
2026-05-11 13:50:16,976 INFO org.apache.hadoop.yarn.server.resourcemanager.rmcontainer.RMContainerImpl: container_1778475288188_0011_01_000003 Container Transitioned from ACQUIRED to RUNNING
2026-05-11 13:50:17,898 INFO org.apache.hadoop.yarn.server.resourcemanager.scheduler.AppSchedulingInfo: checking for deactivate of application :application_1778475288188_0011
2026-05-11 13:50:19,875 INFO org.apache.hadoop.yarn.server.resourcemanager.rmcontainer.RMContainerImpl: container_1778475288188_0011_01_000003 Container Transitioned from RUNNING to COMPLETED
2026-05-11 13:50:19,877 INFO org.apache.hadoop.yarn.server.resourcemanager.rmapp.attempt.RMAppAttemptImpl: Updating application attempt appattempt_1778475288188_0011_000001 with final state: FINISHING, and exit status: -1000
2026-05-11 13:50:19,877 INFO org.apache.hadoop.yarn.server.resourcemanager.rmapp.attempt.RMAppAttemptImpl: appattempt_1778475288188_0011_000001 State change from RUNNING to FINAL_SAVING on event = UNREGISTERED
2026-05-11 13:50:19,878 INFO org.apache.hadoop.yarn.server.resourcemanager.rmapp.RMAppImpl: Updating application application_1778475288188_0011 with final state: FINISHING
2026-05-11 13:50:19,878 INFO org.apache.hadoop.yarn.server.resourcemanager.recovery.RMStateStore: Updating info for app: application_1778475288188_0011
2026-05-11 13:50:19,878 INFO org.apache.hadoop.yarn.server.resourcemanager.rmapp.RMAppImpl: application_1778475288188_0011 State change from RUNNING to FINAL_SAVING on event = ATTEMPT_UNREGISTERED
2026-05-11 13:50:19,878 INFO org.apache.hadoop.yarn.server.resourcemanager.rmapp.attempt.RMAppAttemptImpl: appattempt_1778475288188_0011_000001 State change from FINAL_SAVING to FINISHING on event = ATTEMPT_UPDATE_SAVED
2026-05-11 13:50:19,878 INFO org.apache.hadoop.yarn.server.resourcemanager.rmapp.RMAppImpl: application_1778475288188_0011 State change from FINAL_SAVING to FINISHING on event = APP_UPDATE_SAVED
2026-05-11 13:50:20,882 INFO org.apache.hadoop.yarn.server.resourcemanager.ApplicationMasterService: application_1778475288188_0011 unregistered successfully. 
2026-05-11 13:50:26,350 INFO org.apache.hadoop.yarn.server.resourcemanager.ApplicationMasterService: Unregistering app attempt : appattempt_1778475288188_0011_000001
2026-05-11 13:50:26,350 INFO org.apache.hadoop.yarn.server.resourcemanager.security.AMRMTokenSecretManager: Application finished, removing password for appattempt_1778475288188_0011_000001
2026-05-11 13:50:26,350 INFO org.apache.hadoop.yarn.server.resourcemanager.rmapp.attempt.RMAppAttemptImpl: appattempt_1778475288188_0011_000001 State change from FINISHING to FINISHED on event = CONTAINER_FINISHED
2026-05-11 13:50:26,350 INFO org.apache.hadoop.yarn.server.resourcemanager.rmcontainer.RMContainerImpl: container_1778475288188_0011_01_000001 Container Transitioned from RUNNING to COMPLETED
2026-05-11 13:50:26,354 INFO org.apache.hadoop.yarn.server.resourcemanager.rmapp.RMAppImpl: application_1778475288188_0011 State change from FINISHING to FINISHED on event = ATTEMPT_FINISHED
2026-05-11 13:50:26,358 INFO org.apache.hadoop.yarn.server.resourcemanager.scheduler.capacity.CapacityScheduler: Application Attempt appattempt_1778475288188_0011_000001 is done. finalState=FINISHED
2026-05-11 13:50:26,358 INFO org.apache.hadoop.yarn.server.resourcemanager.scheduler.AppSchedulingInfo: Application application_1778475288188_0011 requests cleared
2026-05-11 13:50:26,358 INFO org.apache.hadoop.yarn.server.resourcemanager.scheduler.capacity.LeafQueue: Application removed - appId: application_1778475288188_0011 user: cty1576 queue: root.default #user-pending-applications: 0 #user-active-applications: 0 #queue-pending-applications: 0 #queue-active-applications: 0
2026-05-11 13:50:26,359 INFO org.apache.hadoop.yarn.server.resourcemanager.scheduler.capacity.ParentQueue: Application removed - appId: application_1778475288188_0011 user: cty1576 leaf-queue of parent: root #applications: 0
2026-05-11 13:50:26,359 INFO org.apache.hadoop.yarn.server.resourcemanager.amlauncher.AMLauncher: Cleaning master appattempt_1778475288188_0011_000001
2026-05-11 13:50:26,358 INFO org.apache.hadoop.yarn.server.resourcemanager.RMAppManager$ApplicationSummary: appId=application_1778475288188_0011,name=SELECT * FROM ads.rfm_summary ORDER B...DESC (Stage-1),user=cty1576,queue=default,state=FINISHED,trackingUrl=http://ubuntu:8088/proxy/application_1778475288188_0011/,appMasterHost=ubuntu,submitTime=1778478604980,startTime=1778478604980,launchTime=1778478605530,finishTime=1778478619878,finalStatus=SUCCEEDED,memorySeconds=50268,vcoreSeconds=26,preemptedMemorySeconds=0,preemptedVcoreSeconds=0,preemptedAMContainers=0,preemptedNonAMContainers=0,preemptedResources=<memory:0\, vCores:0>,applicationType=MAPREDUCE,resourceSeconds=50268 MB-seconds\, 26 vcore-seconds,preemptedResourceSeconds=0 MB-seconds\, 0 vcore-seconds,applicationTags=,applicationNodeLabel=,diagnostics=,totalAllocatedContainers=3
2026-05-11 13:50:28,676 INFO org.apache.hadoop.yarn.server.resourcemanager.ClientRMService: Allocated new applicationId: 12
2026-05-11 13:50:29,437 INFO org.apache.hadoop.yarn.server.resourcemanager.scheduler.capacity.CapacityScheduler: Application 'application_1778475288188_0012' is submitted without priority hence considering default queue/cluster priority: 0
2026-05-11 13:50:29,439 INFO org.apache.hadoop.yarn.server.resourcemanager.scheduler.capacity.CapacityScheduler: Priority '0' is acceptable in queue : default for application: application_1778475288188_0012
2026-05-11 13:50:29,441 INFO org.apache.hadoop.yarn.server.resourcemanager.ClientRMService: Application with id 12 submitted by user cty1576
2026-05-11 13:50:29,441 INFO org.apache.hadoop.yarn.server.resourcemanager.rmapp.RMAppImpl: Storing application with id application_1778475288188_0012
2026-05-11 13:50:29,442 INFO org.apache.hadoop.yarn.server.resourcemanager.recovery.RMStateStore: Storing info for app: application_1778475288188_0012
2026-05-11 13:50:29,445 INFO org.apache.hadoop.yarn.server.resourcemanager.rmapp.RMAppImpl: application_1778475288188_0012 State change from NEW to NEW_SAVING on event = START
2026-05-11 13:50:29,446 INFO org.apache.hadoop.yarn.server.resourcemanager.rmapp.RMAppImpl: application_1778475288188_0012 State change from NEW_SAVING to SUBMITTED on event = APP_NEW_SAVED
2026-05-11 13:50:29,446 INFO org.apache.hadoop.yarn.server.resourcemanager.scheduler.capacity.ParentQueue: Application added - appId: application_1778475288188_0012 user: cty1576 leaf-queue of parent: root #applications: 1
2026-05-11 13:50:29,446 INFO org.apache.hadoop.yarn.server.resourcemanager.scheduler.capacity.CapacityScheduler: Accepted application application_1778475288188_0012 from user: cty1576, in queue: default
2026-05-11 13:50:29,447 INFO org.apache.hadoop.yarn.server.resourcemanager.rmapp.RMAppImpl: application_1778475288188_0012 State change from SUBMITTED to ACCEPTED on event = APP_ACCEPTED
2026-05-11 13:50:29,447 INFO org.apache.hadoop.yarn.server.resourcemanager.ApplicationMasterService: Registering app attempt : appattempt_1778475288188_0012_000001
2026-05-11 13:50:29,447 INFO org.apache.hadoop.yarn.server.resourcemanager.rmapp.attempt.RMAppAttemptImpl: appattempt_1778475288188_0012_000001 State change from NEW to SUBMITTED on event = START
2026-05-11 13:50:29,447 WARN org.apache.hadoop.yarn.server.resourcemanager.scheduler.capacity.LeafQueue: maximum-am-resource-percent is insufficient to start a single application in queue, it is likely set too low. skipping enforcement to allow at least one application to start
2026-05-11 13:50:29,447 WARN org.apache.hadoop.yarn.server.resourcemanager.scheduler.capacity.LeafQueue: maximum-am-resource-percent is insufficient to start a single application in queue for user, it is likely set too low. skipping enforcement to allow at least one application to start
2026-05-11 13:50:29,447 INFO org.apache.hadoop.yarn.server.resourcemanager.scheduler.capacity.LeafQueue: Application application_1778475288188_0012 from user: cty1576 activated in queue: root.default
2026-05-11 13:50:29,447 INFO org.apache.hadoop.yarn.server.resourcemanager.scheduler.capacity.LeafQueue: Application added - appId: application_1778475288188_0012 user: cty1576, leaf-queue: root.default #user-pending-applications: 0 #user-active-applications: 1 #queue-pending-applications: 0 #queue-active-applications: 1 #queue-nonrunnable-applications: 0
2026-05-11 13:50:29,448 INFO org.apache.hadoop.yarn.server.resourcemanager.scheduler.capacity.CapacityScheduler: Added Application Attempt appattempt_1778475288188_0012_000001 to scheduler from user cty1576 in queue root.default
2026-05-11 13:50:29,449 INFO org.apache.hadoop.yarn.server.resourcemanager.rmapp.attempt.RMAppAttemptImpl: appattempt_1778475288188_0012_000001 State change from SUBMITTED to SCHEDULED on event = ATTEMPT_ADDED
2026-05-11 13:50:30,360 INFO org.apache.hadoop.yarn.server.resourcemanager.scheduler.capacity.allocator.AbstractContainerAllocator: assignedContainer application attempt=appattempt_1778475288188_0012_000001 container=null queue=default clusterResource=<memory:8192, vCores:8> type=OFF_SWITCH requestedPartition=
2026-05-11 13:50:30,361 INFO org.apache.hadoop.yarn.server.resourcemanager.rmcontainer.RMContainerImpl: container_1778475288188_0012_01_000001 Container Transitioned from NEW to ALLOCATED
2026-05-11 13:50:30,361 INFO org.apache.hadoop.yarn.server.resourcemanager.scheduler.common.fica.FiCaSchedulerNode: Assigned container container_1778475288188_0012_01_000001 of capacity <memory:2048, vCores:1> on host ubuntu:45565, which has 1 containers, <memory:2048, vCores:1> used and <memory:6144, vCores:7> available after allocation
2026-05-11 13:50:30,361 INFO org.apache.hadoop.yarn.server.resourcemanager.scheduler.capacity.ParentQueue: assignedContainer queue=root usedCapacity=0.25 absoluteUsedCapacity=0.25 used=<memory:2048, vCores:1> cluster=<memory:8192, vCores:8>
2026-05-11 13:50:30,362 INFO org.apache.hadoop.yarn.server.resourcemanager.rmcontainer.RMContainerImpl: container_1778475288188_0012_01_000001 Container Transitioned from ALLOCATED to ACQUIRED
2026-05-11 13:50:30,362 INFO org.apache.hadoop.yarn.server.resourcemanager.security.NMTokenSecretManagerInRM: Clear node set for appattempt_1778475288188_0012_000001
2026-05-11 13:50:30,362 INFO org.apache.hadoop.yarn.server.resourcemanager.rmapp.attempt.RMAppAttemptImpl: Storing attempt: AppId: application_1778475288188_0012 AttemptId: appattempt_1778475288188_0012_000001 MasterContainer: Container: [ContainerId: container_1778475288188_0012_01_000001, AllocationRequestId: -1, Version: 0, NodeId: ubuntu:45565, NodeHttpAddress: ubuntu:8042, Resource: <memory:2048, vCores:1>, Priority: 0, Token: Token { kind: ContainerToken, service: 127.0.1.1:45565 }, ExecutionType: GUARANTEED, ]
2026-05-11 13:50:30,362 INFO org.apache.hadoop.yarn.server.resourcemanager.rmapp.attempt.RMAppAttemptImpl: appattempt_1778475288188_0012_000001 State change from SCHEDULED to ALLOCATED_SAVING on event = CONTAINER_ALLOCATED
2026-05-11 13:50:30,363 INFO org.apache.hadoop.yarn.server.resourcemanager.rmapp.attempt.RMAppAttemptImpl: appattempt_1778475288188_0012_000001 State change from ALLOCATED_SAVING to ALLOCATED on event = ATTEMPT_NEW_SAVED
2026-05-11 13:50:30,363 INFO org.apache.hadoop.yarn.server.resourcemanager.amlauncher.AMLauncher: Launching masterappattempt_1778475288188_0012_000001
2026-05-11 13:50:30,367 INFO org.apache.hadoop.yarn.server.resourcemanager.amlauncher.AMLauncher: Setting up container Container: [ContainerId: container_1778475288188_0012_01_000001, AllocationRequestId: -1, Version: 0, NodeId: ubuntu:45565, NodeHttpAddress: ubuntu:8042, Resource: <memory:2048, vCores:1>, Priority: 0, Token: Token { kind: ContainerToken, service: 127.0.1.1:45565 }, ExecutionType: GUARANTEED, ] for AM appattempt_1778475288188_0012_000001
2026-05-11 13:50:30,367 INFO org.apache.hadoop.yarn.server.resourcemanager.security.AMRMTokenSecretManager: Create AMRMToken for ApplicationAttempt: appattempt_1778475288188_0012_000001
2026-05-11 13:50:30,367 INFO org.apache.hadoop.yarn.server.resourcemanager.security.AMRMTokenSecretManager: Creating password for appattempt_1778475288188_0012_000001
2026-05-11 13:50:30,387 INFO org.apache.hadoop.yarn.server.resourcemanager.amlauncher.AMLauncher: Done launching container Container: [ContainerId: container_1778475288188_0012_01_000001, AllocationRequestId: -1, Version: 0, NodeId: ubuntu:45565, NodeHttpAddress: ubuntu:8042, Resource: <memory:2048, vCores:1>, Priority: 0, Token: Token { kind: ContainerToken, service: 127.0.1.1:45565 }, ExecutionType: GUARANTEED, ] for AM appattempt_1778475288188_0012_000001
2026-05-11 13:50:30,387 INFO org.apache.hadoop.yarn.server.resourcemanager.rmapp.attempt.RMAppAttemptImpl: appattempt_1778475288188_0012_000001 State change from ALLOCATED to LAUNCHED on event = LAUNCHED
2026-05-11 13:50:30,387 INFO org.apache.hadoop.yarn.server.resourcemanager.rmapp.RMAppImpl: update the launch time for applicationId: application_1778475288188_0012, attemptId: appattempt_1778475288188_0012_000001launchTime: 1778478630387
2026-05-11 13:50:30,387 INFO org.apache.hadoop.yarn.server.resourcemanager.recovery.RMStateStore: Updating info for app: application_1778475288188_0012
2026-05-11 13:50:31,363 INFO org.apache.hadoop.yarn.server.resourcemanager.rmcontainer.RMContainerImpl: container_1778475288188_0012_01_000001 Container Transitioned from ACQUIRED to RUNNING
2026-05-11 13:50:34,500 INFO SecurityLogger.org.apache.hadoop.ipc.Server: Auth successful for appattempt_1778475288188_0012_000001 (auth:SIMPLE) from 127.0.0.1:50788
2026-05-11 13:50:34,508 INFO org.apache.hadoop.yarn.server.resourcemanager.DefaultAMSProcessor: AM registration appattempt_1778475288188_0012_000001
2026-05-11 13:50:34,508 INFO org.apache.hadoop.yarn.server.resourcemanager.rmapp.attempt.RMAppAttemptImpl: appattempt_1778475288188_0012_000001 State change from LAUNCHED to RUNNING on event = REGISTERED
2026-05-11 13:50:34,508 INFO org.apache.hadoop.yarn.server.resourcemanager.rmapp.RMAppImpl: application_1778475288188_0012 State change from ACCEPTED to RUNNING on event = ATTEMPT_REGISTERED
2026-05-11 13:50:36,373 INFO org.apache.hadoop.yarn.server.resourcemanager.scheduler.capacity.allocator.AbstractContainerAllocator: assignedContainer application attempt=appattempt_1778475288188_0012_000001 container=null queue=default clusterResource=<memory:8192, vCores:8> type=NODE_LOCAL requestedPartition=
2026-05-11 13:50:36,374 INFO org.apache.hadoop.yarn.server.resourcemanager.rmcontainer.RMContainerImpl: container_1778475288188_0012_01_000002 Container Transitioned from NEW to ALLOCATED
2026-05-11 13:50:36,374 INFO org.apache.hadoop.yarn.server.resourcemanager.scheduler.common.fica.FiCaSchedulerNode: Assigned container container_1778475288188_0012_01_000002 of capacity <memory:1024, vCores:1> on host ubuntu:45565, which has 2 containers, <memory:3072, vCores:2> used and <memory:5120, vCores:6> available after allocation
2026-05-11 13:50:36,375 INFO org.apache.hadoop.yarn.server.resourcemanager.scheduler.capacity.ParentQueue: assignedContainer queue=root usedCapacity=0.375 absoluteUsedCapacity=0.375 used=<memory:3072, vCores:2> cluster=<memory:8192, vCores:8>
2026-05-11 13:50:36,561 INFO org.apache.hadoop.yarn.server.resourcemanager.rmcontainer.RMContainerImpl: container_1778475288188_0012_01_000002 Container Transitioned from ALLOCATED to ACQUIRED
2026-05-11 13:50:37,377 INFO org.apache.hadoop.yarn.server.resourcemanager.rmcontainer.RMContainerImpl: container_1778475288188_0012_01_000002 Container Transitioned from ACQUIRED to RUNNING
2026-05-11 13:50:37,576 INFO org.apache.hadoop.yarn.server.resourcemanager.scheduler.AppSchedulingInfo: checking for deactivate of application :application_1778475288188_0012
2026-05-11 13:50:39,866 INFO org.apache.hadoop.yarn.server.resourcemanager.rmcontainer.RMContainerImpl: container_1778475288188_0012_01_000002 Container Transitioned from RUNNING to COMPLETED
2026-05-11 13:50:40,867 INFO org.apache.hadoop.yarn.server.resourcemanager.scheduler.capacity.allocator.AbstractContainerAllocator: assignedContainer application attempt=appattempt_1778475288188_0012_000001 container=null queue=default clusterResource=<memory:8192, vCores:8> type=OFF_SWITCH requestedPartition=
2026-05-11 13:50:40,868 INFO org.apache.hadoop.yarn.server.resourcemanager.rmcontainer.RMContainerImpl: container_1778475288188_0012_01_000003 Container Transitioned from NEW to ALLOCATED
2026-05-11 13:50:40,868 INFO org.apache.hadoop.yarn.server.resourcemanager.scheduler.common.fica.FiCaSchedulerNode: Assigned container container_1778475288188_0012_01_000003 of capacity <memory:1024, vCores:1> on host ubuntu:45565, which has 2 containers, <memory:3072, vCores:2> used and <memory:5120, vCores:6> available after allocation
2026-05-11 13:50:40,868 INFO org.apache.hadoop.yarn.server.resourcemanager.scheduler.capacity.ParentQueue: assignedContainer queue=root usedCapacity=0.375 absoluteUsedCapacity=0.375 used=<memory:3072, vCores:2> cluster=<memory:8192, vCores:8>
2026-05-11 13:50:41,596 INFO org.apache.hadoop.yarn.server.resourcemanager.rmcontainer.RMContainerImpl: container_1778475288188_0012_01_000003 Container Transitioned from ALLOCATED to ACQUIRED
2026-05-11 13:50:41,872 INFO org.apache.hadoop.yarn.server.resourcemanager.rmcontainer.RMContainerImpl: container_1778475288188_0012_01_000003 Container Transitioned from ACQUIRED to RUNNING
2026-05-11 13:50:42,611 INFO org.apache.hadoop.yarn.server.resourcemanager.scheduler.AppSchedulingInfo: checking for deactivate of application :application_1778475288188_0012
2026-05-11 13:50:44,415 INFO org.apache.hadoop.yarn.server.resourcemanager.rmcontainer.RMContainerImpl: container_1778475288188_0012_01_000003 Container Transitioned from RUNNING to COMPLETED
2026-05-11 13:50:44,679 INFO org.apache.hadoop.yarn.server.resourcemanager.rmapp.attempt.RMAppAttemptImpl: Updating application attempt appattempt_1778475288188_0012_000001 with final state: FINISHING, and exit status: -1000
2026-05-11 13:50:44,679 INFO org.apache.hadoop.yarn.server.resourcemanager.rmapp.attempt.RMAppAttemptImpl: appattempt_1778475288188_0012_000001 State change from RUNNING to FINAL_SAVING on event = UNREGISTERED
2026-05-11 13:50:44,679 INFO org.apache.hadoop.yarn.server.resourcemanager.rmapp.RMAppImpl: Updating application application_1778475288188_0012 with final state: FINISHING
2026-05-11 13:50:44,679 INFO org.apache.hadoop.yarn.server.resourcemanager.rmapp.RMAppImpl: application_1778475288188_0012 State change from RUNNING to FINAL_SAVING on event = ATTEMPT_UNREGISTERED
2026-05-11 13:50:44,679 INFO org.apache.hadoop.yarn.server.resourcemanager.recovery.RMStateStore: Updating info for app: application_1778475288188_0012
2026-05-11 13:50:44,679 INFO org.apache.hadoop.yarn.server.resourcemanager.rmapp.attempt.RMAppAttemptImpl: appattempt_1778475288188_0012_000001 State change from FINAL_SAVING to FINISHING on event = ATTEMPT_UPDATE_SAVED
2026-05-11 13:50:44,679 INFO org.apache.hadoop.yarn.server.resourcemanager.rmapp.RMAppImpl: application_1778475288188_0012 State change from FINAL_SAVING to FINISHING on event = APP_UPDATE_SAVED
2026-05-11 13:50:45,680 INFO org.apache.hadoop.yarn.server.resourcemanager.ApplicationMasterService: application_1778475288188_0012 unregistered successfully. 
2026-05-11 13:50:51,073 INFO org.apache.hadoop.yarn.server.resourcemanager.rmcontainer.RMContainerImpl: container_1778475288188_0012_01_000001 Container Transitioned from RUNNING to COMPLETED
2026-05-11 13:50:51,074 INFO org.apache.hadoop.yarn.server.resourcemanager.ApplicationMasterService: Unregistering app attempt : appattempt_1778475288188_0012_000001
2026-05-11 13:50:51,074 INFO org.apache.hadoop.yarn.server.resourcemanager.security.AMRMTokenSecretManager: Application finished, removing password for appattempt_1778475288188_0012_000001
2026-05-11 13:50:51,074 INFO org.apache.hadoop.yarn.server.resourcemanager.rmapp.attempt.RMAppAttemptImpl: appattempt_1778475288188_0012_000001 State change from FINISHING to FINISHED on event = CONTAINER_FINISHED
2026-05-11 13:50:51,077 INFO org.apache.hadoop.yarn.server.resourcemanager.rmapp.RMAppImpl: application_1778475288188_0012 State change from FINISHING to FINISHED on event = ATTEMPT_FINISHED
2026-05-11 13:50:51,079 INFO org.apache.hadoop.yarn.server.resourcemanager.scheduler.capacity.CapacityScheduler: Application Attempt appattempt_1778475288188_0012_000001 is done. finalState=FINISHED
2026-05-11 13:50:51,079 INFO org.apache.hadoop.yarn.server.resourcemanager.scheduler.AppSchedulingInfo: Application application_1778475288188_0012 requests cleared
2026-05-11 13:50:51,079 INFO org.apache.hadoop.yarn.server.resourcemanager.scheduler.capacity.LeafQueue: Application removed - appId: application_1778475288188_0012 user: cty1576 queue: root.default #user-pending-applications: 0 #user-active-applications: 0 #queue-pending-applications: 0 #queue-active-applications: 0
2026-05-11 13:50:51,079 INFO org.apache.hadoop.yarn.server.resourcemanager.scheduler.capacity.ParentQueue: Application removed - appId: application_1778475288188_0012 user: cty1576 leaf-queue of parent: root #applications: 0
2026-05-11 13:50:51,079 INFO org.apache.hadoop.yarn.server.resourcemanager.RMAppManager$ApplicationSummary: appId=application_1778475288188_0012,name=SELECT * FROM ads.user_path ORDER BY pa...20 (Stage-1),user=cty1576,queue=default,state=FINISHED,trackingUrl=http://ubuntu:8088/proxy/application_1778475288188_0012/,appMasterHost=ubuntu,submitTime=1778478629437,startTime=1778478629440,launchTime=1778478630387,finishTime=1778478644679,finalStatus=SUCCEEDED,memorySeconds=49629,vcoreSeconds=26,preemptedMemorySeconds=0,preemptedVcoreSeconds=0,preemptedAMContainers=0,preemptedNonAMContainers=0,preemptedResources=<memory:0\, vCores:0>,applicationType=MAPREDUCE,resourceSeconds=49629 MB-seconds\, 26 vcore-seconds,preemptedResourceSeconds=0 MB-seconds\, 0 vcore-seconds,applicationTags=,applicationNodeLabel=,diagnostics=,totalAllocatedContainers=3
2026-05-11 13:50:51,085 INFO org.apache.hadoop.yarn.server.resourcemanager.amlauncher.AMLauncher: Cleaning master appattempt_1778475288188_0012_000001
2026-05-11 13:50:52,955 INFO org.apache.hadoop.yarn.server.resourcemanager.ClientRMService: Allocated new applicationId: 13
2026-05-11 13:50:54,489 INFO org.apache.hadoop.yarn.server.resourcemanager.scheduler.capacity.CapacityScheduler: Application 'application_1778475288188_0013' is submitted without priority hence considering default queue/cluster priority: 0
2026-05-11 13:50:54,489 INFO org.apache.hadoop.yarn.server.resourcemanager.scheduler.capacity.CapacityScheduler: Priority '0' is acceptable in queue : default for application: application_1778475288188_0013
2026-05-11 13:50:54,489 INFO org.apache.hadoop.yarn.server.resourcemanager.ClientRMService: Application with id 13 submitted by user cty1576
2026-05-11 13:50:54,490 INFO org.apache.hadoop.yarn.server.resourcemanager.rmapp.RMAppImpl: Storing application with id application_1778475288188_0013
2026-05-11 13:50:54,490 INFO org.apache.hadoop.yarn.server.resourcemanager.recovery.RMStateStore: Storing info for app: application_1778475288188_0013
2026-05-11 13:50:54,490 INFO org.apache.hadoop.yarn.server.resourcemanager.rmapp.RMAppImpl: application_1778475288188_0013 State change from NEW to NEW_SAVING on event = START
2026-05-11 13:50:54,490 INFO org.apache.hadoop.yarn.server.resourcemanager.rmapp.RMAppImpl: application_1778475288188_0013 State change from NEW_SAVING to SUBMITTED on event = APP_NEW_SAVED
2026-05-11 13:50:54,491 INFO org.apache.hadoop.yarn.server.resourcemanager.scheduler.capacity.ParentQueue: Application added - appId: application_1778475288188_0013 user: cty1576 leaf-queue of parent: root #applications: 1
2026-05-11 13:50:54,491 INFO org.apache.hadoop.yarn.server.resourcemanager.scheduler.capacity.CapacityScheduler: Accepted application application_1778475288188_0013 from user: cty1576, in queue: default
2026-05-11 13:50:54,492 INFO org.apache.hadoop.yarn.server.resourcemanager.rmapp.RMAppImpl: application_1778475288188_0013 State change from SUBMITTED to ACCEPTED on event = APP_ACCEPTED
2026-05-11 13:50:54,492 INFO org.apache.hadoop.yarn.server.resourcemanager.ApplicationMasterService: Registering app attempt : appattempt_1778475288188_0013_000001
2026-05-11 13:50:54,492 INFO org.apache.hadoop.yarn.server.resourcemanager.rmapp.attempt.RMAppAttemptImpl: appattempt_1778475288188_0013_000001 State change from NEW to SUBMITTED on event = START
2026-05-11 13:50:54,493 WARN org.apache.hadoop.yarn.server.resourcemanager.scheduler.capacity.LeafQueue: maximum-am-resource-percent is insufficient to start a single application in queue, it is likely set too low. skipping enforcement to allow at least one application to start
2026-05-11 13:50:54,493 WARN org.apache.hadoop.yarn.server.resourcemanager.scheduler.capacity.LeafQueue: maximum-am-resource-percent is insufficient to start a single application in queue for user, it is likely set too low. skipping enforcement to allow at least one application to start
2026-05-11 13:50:54,493 INFO org.apache.hadoop.yarn.server.resourcemanager.scheduler.capacity.LeafQueue: Application application_1778475288188_0013 from user: cty1576 activated in queue: root.default
2026-05-11 13:50:54,493 INFO org.apache.hadoop.yarn.server.resourcemanager.scheduler.capacity.LeafQueue: Application added - appId: application_1778475288188_0013 user: cty1576, leaf-queue: root.default #user-pending-applications: 0 #user-active-applications: 1 #queue-pending-applications: 0 #queue-active-applications: 1 #queue-nonrunnable-applications: 0
2026-05-11 13:50:54,493 INFO org.apache.hadoop.yarn.server.resourcemanager.scheduler.capacity.CapacityScheduler: Added Application Attempt appattempt_1778475288188_0013_000001 to scheduler from user cty1576 in queue root.default
2026-05-11 13:50:54,494 INFO org.apache.hadoop.yarn.server.resourcemanager.rmapp.attempt.RMAppAttemptImpl: appattempt_1778475288188_0013_000001 State change from SUBMITTED to SCHEDULED on event = ATTEMPT_ADDED
2026-05-11 13:50:55,081 INFO org.apache.hadoop.yarn.server.resourcemanager.scheduler.capacity.allocator.AbstractContainerAllocator: assignedContainer application attempt=appattempt_1778475288188_0013_000001 container=null queue=default clusterResource=<memory:8192, vCores:8> type=OFF_SWITCH requestedPartition=
2026-05-11 13:50:55,082 INFO org.apache.hadoop.yarn.server.resourcemanager.rmcontainer.RMContainerImpl: container_1778475288188_0013_01_000001 Container Transitioned from NEW to ALLOCATED
2026-05-11 13:50:55,082 INFO org.apache.hadoop.yarn.server.resourcemanager.scheduler.common.fica.FiCaSchedulerNode: Assigned container container_1778475288188_0013_01_000001 of capacity <memory:2048, vCores:1> on host ubuntu:45565, which has 1 containers, <memory:2048, vCores:1> used and <memory:6144, vCores:7> available after allocation
2026-05-11 13:50:55,082 INFO org.apache.hadoop.yarn.server.resourcemanager.scheduler.capacity.ParentQueue: assignedContainer queue=root usedCapacity=0.25 absoluteUsedCapacity=0.25 used=<memory:2048, vCores:1> cluster=<memory:8192, vCores:8>
2026-05-11 13:50:55,089 INFO org.apache.hadoop.yarn.server.resourcemanager.rmcontainer.RMContainerImpl: container_1778475288188_0013_01_000001 Container Transitioned from ALLOCATED to ACQUIRED
2026-05-11 13:50:55,091 INFO org.apache.hadoop.yarn.server.resourcemanager.security.NMTokenSecretManagerInRM: Clear node set for appattempt_1778475288188_0013_000001
2026-05-11 13:50:55,092 INFO org.apache.hadoop.yarn.server.resourcemanager.rmapp.attempt.RMAppAttemptImpl: Storing attempt: AppId: application_1778475288188_0013 AttemptId: appattempt_1778475288188_0013_000001 MasterContainer: Container: [ContainerId: container_1778475288188_0013_01_000001, AllocationRequestId: -1, Version: 0, NodeId: ubuntu:45565, NodeHttpAddress: ubuntu:8042, Resource: <memory:2048, vCores:1>, Priority: 0, Token: Token { kind: ContainerToken, service: 127.0.1.1:45565 }, ExecutionType: GUARANTEED, ]
2026-05-11 13:50:55,092 INFO org.apache.hadoop.yarn.server.resourcemanager.rmapp.attempt.RMAppAttemptImpl: appattempt_1778475288188_0013_000001 State change from SCHEDULED to ALLOCATED_SAVING on event = CONTAINER_ALLOCATED
2026-05-11 13:50:55,092 INFO org.apache.hadoop.yarn.server.resourcemanager.rmapp.attempt.RMAppAttemptImpl: appattempt_1778475288188_0013_000001 State change from ALLOCATED_SAVING to ALLOCATED on event = ATTEMPT_NEW_SAVED
2026-05-11 13:50:55,094 INFO org.apache.hadoop.yarn.server.resourcemanager.amlauncher.AMLauncher: Launching masterappattempt_1778475288188_0013_000001
2026-05-11 13:50:55,099 INFO org.apache.hadoop.yarn.server.resourcemanager.amlauncher.AMLauncher: Setting up container Container: [ContainerId: container_1778475288188_0013_01_000001, AllocationRequestId: -1, Version: 0, NodeId: ubuntu:45565, NodeHttpAddress: ubuntu:8042, Resource: <memory:2048, vCores:1>, Priority: 0, Token: Token { kind: ContainerToken, service: 127.0.1.1:45565 }, ExecutionType: GUARANTEED, ] for AM appattempt_1778475288188_0013_000001
2026-05-11 13:50:55,099 INFO org.apache.hadoop.yarn.server.resourcemanager.security.AMRMTokenSecretManager: Create AMRMToken for ApplicationAttempt: appattempt_1778475288188_0013_000001
2026-05-11 13:50:55,099 INFO org.apache.hadoop.yarn.server.resourcemanager.security.AMRMTokenSecretManager: Creating password for appattempt_1778475288188_0013_000001
2026-05-11 13:50:55,123 INFO org.apache.hadoop.yarn.server.resourcemanager.amlauncher.AMLauncher: Done launching container Container: [ContainerId: container_1778475288188_0013_01_000001, AllocationRequestId: -1, Version: 0, NodeId: ubuntu:45565, NodeHttpAddress: ubuntu:8042, Resource: <memory:2048, vCores:1>, Priority: 0, Token: Token { kind: ContainerToken, service: 127.0.1.1:45565 }, ExecutionType: GUARANTEED, ] for AM appattempt_1778475288188_0013_000001
2026-05-11 13:50:55,123 INFO org.apache.hadoop.yarn.server.resourcemanager.rmapp.attempt.RMAppAttemptImpl: appattempt_1778475288188_0013_000001 State change from ALLOCATED to LAUNCHED on event = LAUNCHED
2026-05-11 13:50:55,123 INFO org.apache.hadoop.yarn.server.resourcemanager.rmapp.RMAppImpl: update the launch time for applicationId: application_1778475288188_0013, attemptId: appattempt_1778475288188_0013_000001launchTime: 1778478655123
2026-05-11 13:50:55,123 INFO org.apache.hadoop.yarn.server.resourcemanager.recovery.RMStateStore: Updating info for app: application_1778475288188_0013
2026-05-11 13:50:56,082 INFO org.apache.hadoop.yarn.server.resourcemanager.rmcontainer.RMContainerImpl: container_1778475288188_0013_01_000001 Container Transitioned from ACQUIRED to RUNNING
2026-05-11 13:50:59,009 INFO SecurityLogger.org.apache.hadoop.ipc.Server: Auth successful for appattempt_1778475288188_0013_000001 (auth:SIMPLE) from 127.0.0.1:38180
2026-05-11 13:50:59,014 INFO org.apache.hadoop.yarn.server.resourcemanager.DefaultAMSProcessor: AM registration appattempt_1778475288188_0013_000001
2026-05-11 13:50:59,014 INFO org.apache.hadoop.yarn.server.resourcemanager.rmapp.attempt.RMAppAttemptImpl: appattempt_1778475288188_0013_000001 State change from LAUNCHED to RUNNING on event = REGISTERED
2026-05-11 13:50:59,016 INFO org.apache.hadoop.yarn.server.resourcemanager.rmapp.RMAppImpl: application_1778475288188_0013 State change from ACCEPTED to RUNNING on event = ATTEMPT_REGISTERED
2026-05-11 13:51:00,092 INFO org.apache.hadoop.yarn.server.resourcemanager.scheduler.capacity.allocator.AbstractContainerAllocator: assignedContainer application attempt=appattempt_1778475288188_0013_000001 container=null queue=default clusterResource=<memory:8192, vCores:8> type=NODE_LOCAL requestedPartition=
2026-05-11 13:51:00,093 INFO org.apache.hadoop.yarn.server.resourcemanager.rmcontainer.RMContainerImpl: container_1778475288188_0013_01_000002 Container Transitioned from NEW to ALLOCATED
2026-05-11 13:51:00,093 INFO org.apache.hadoop.yarn.server.resourcemanager.scheduler.common.fica.FiCaSchedulerNode: Assigned container container_1778475288188_0013_01_000002 of capacity <memory:1024, vCores:1> on host ubuntu:45565, which has 2 containers, <memory:3072, vCores:2> used and <memory:5120, vCores:6> available after allocation
2026-05-11 13:51:00,093 INFO org.apache.hadoop.yarn.server.resourcemanager.scheduler.capacity.ParentQueue: assignedContainer queue=root usedCapacity=0.375 absoluteUsedCapacity=0.375 used=<memory:3072, vCores:2> cluster=<memory:8192, vCores:8>
2026-05-11 13:51:01,068 INFO org.apache.hadoop.yarn.server.resourcemanager.rmcontainer.RMContainerImpl: container_1778475288188_0013_01_000002 Container Transitioned from ALLOCATED to ACQUIRED
2026-05-11 13:51:02,086 INFO org.apache.hadoop.yarn.server.resourcemanager.scheduler.AppSchedulingInfo: checking for deactivate of application :application_1778475288188_0013
2026-05-11 13:51:02,096 INFO org.apache.hadoop.yarn.server.resourcemanager.rmcontainer.RMContainerImpl: container_1778475288188_0013_01_000002 Container Transitioned from ACQUIRED to RUNNING
2026-05-11 13:51:04,231 INFO org.apache.hadoop.yarn.server.resourcemanager.rmcontainer.RMContainerImpl: container_1778475288188_0013_01_000002 Container Transitioned from RUNNING to COMPLETED
2026-05-11 13:51:05,234 INFO org.apache.hadoop.yarn.server.resourcemanager.scheduler.capacity.allocator.AbstractContainerAllocator: assignedContainer application attempt=appattempt_1778475288188_0013_000001 container=null queue=default clusterResource=<memory:8192, vCores:8> type=OFF_SWITCH requestedPartition=
2026-05-11 13:51:05,237 INFO org.apache.hadoop.yarn.server.resourcemanager.rmcontainer.RMContainerImpl: container_1778475288188_0013_01_000003 Container Transitioned from NEW to ALLOCATED
2026-05-11 13:51:05,237 INFO org.apache.hadoop.yarn.server.resourcemanager.scheduler.common.fica.FiCaSchedulerNode: Assigned container container_1778475288188_0013_01_000003 of capacity <memory:1024, vCores:1> on host ubuntu:45565, which has 2 containers, <memory:3072, vCores:2> used and <memory:5120, vCores:6> available after allocation
2026-05-11 13:51:05,237 INFO org.apache.hadoop.yarn.server.resourcemanager.scheduler.capacity.ParentQueue: assignedContainer queue=root usedCapacity=0.375 absoluteUsedCapacity=0.375 used=<memory:3072, vCores:2> cluster=<memory:8192, vCores:8>
2026-05-11 13:51:06,111 INFO org.apache.hadoop.yarn.server.resourcemanager.rmcontainer.RMContainerImpl: container_1778475288188_0013_01_000003 Container Transitioned from ALLOCATED to ACQUIRED
2026-05-11 13:51:06,234 INFO org.apache.hadoop.yarn.server.resourcemanager.rmcontainer.RMContainerImpl: container_1778475288188_0013_01_000003 Container Transitioned from ACQUIRED to RUNNING
2026-05-11 13:51:07,119 INFO org.apache.hadoop.yarn.server.resourcemanager.scheduler.AppSchedulingInfo: checking for deactivate of application :application_1778475288188_0013
2026-05-11 13:51:08,598 INFO org.apache.hadoop.yarn.server.resourcemanager.rmcontainer.RMContainerImpl: container_1778475288188_0013_01_000003 Container Transitioned from RUNNING to COMPLETED
2026-05-11 13:51:08,607 INFO org.apache.hadoop.yarn.server.resourcemanager.rmapp.attempt.RMAppAttemptImpl: Updating application attempt appattempt_1778475288188_0013_000001 with final state: FINISHING, and exit status: -1000
2026-05-11 13:51:08,608 INFO org.apache.hadoop.yarn.server.resourcemanager.rmapp.attempt.RMAppAttemptImpl: appattempt_1778475288188_0013_000001 State change from RUNNING to FINAL_SAVING on event = UNREGISTERED
2026-05-11 13:51:08,608 INFO org.apache.hadoop.yarn.server.resourcemanager.rmapp.attempt.RMAppAttemptImpl: appattempt_1778475288188_0013_000001 State change from FINAL_SAVING to FINISHING on event = ATTEMPT_UPDATE_SAVED
2026-05-11 13:51:08,608 INFO org.apache.hadoop.yarn.server.resourcemanager.rmapp.RMAppImpl: Updating application application_1778475288188_0013 with final state: FINISHING
2026-05-11 13:51:08,608 INFO org.apache.hadoop.yarn.server.resourcemanager.recovery.RMStateStore: Updating info for app: application_1778475288188_0013
2026-05-11 13:51:08,608 INFO org.apache.hadoop.yarn.server.resourcemanager.rmapp.RMAppImpl: application_1778475288188_0013 State change from RUNNING to FINAL_SAVING on event = ATTEMPT_UNREGISTERED
2026-05-11 13:51:08,608 INFO org.apache.hadoop.yarn.server.resourcemanager.rmapp.RMAppImpl: application_1778475288188_0013 State change from FINAL_SAVING to FINISHING on event = APP_UPDATE_SAVED
2026-05-11 13:51:09,610 INFO org.apache.hadoop.yarn.server.resourcemanager.ApplicationMasterService: application_1778475288188_0013 unregistered successfully. 
2026-05-11 13:51:14,998 INFO org.apache.hadoop.yarn.server.resourcemanager.rmcontainer.RMContainerImpl: container_1778475288188_0013_01_000001 Container Transitioned from RUNNING to COMPLETED
2026-05-11 13:51:14,999 INFO org.apache.hadoop.yarn.server.resourcemanager.ApplicationMasterService: Unregistering app attempt : appattempt_1778475288188_0013_000001
2026-05-11 13:51:14,999 INFO org.apache.hadoop.yarn.server.resourcemanager.security.AMRMTokenSecretManager: Application finished, removing password for appattempt_1778475288188_0013_000001
2026-05-11 13:51:14,999 INFO org.apache.hadoop.yarn.server.resourcemanager.rmapp.attempt.RMAppAttemptImpl: appattempt_1778475288188_0013_000001 State change from FINISHING to FINISHED on event = CONTAINER_FINISHED
2026-05-11 13:51:15,002 INFO org.apache.hadoop.yarn.server.resourcemanager.rmapp.RMAppImpl: application_1778475288188_0013 State change from FINISHING to FINISHED on event = ATTEMPT_FINISHED
2026-05-11 13:51:15,002 INFO org.apache.hadoop.yarn.server.resourcemanager.scheduler.capacity.CapacityScheduler: Application Attempt appattempt_1778475288188_0013_000001 is done. finalState=FINISHED
2026-05-11 13:51:15,002 INFO org.apache.hadoop.yarn.server.resourcemanager.scheduler.AppSchedulingInfo: Application application_1778475288188_0013 requests cleared
2026-05-11 13:51:15,002 INFO org.apache.hadoop.yarn.server.resourcemanager.scheduler.capacity.LeafQueue: Application removed - appId: application_1778475288188_0013 user: cty1576 queue: root.default #user-pending-applications: 0 #user-active-applications: 0 #queue-pending-applications: 0 #queue-active-applications: 0
2026-05-11 13:51:15,002 INFO org.apache.hadoop.yarn.server.resourcemanager.scheduler.capacity.ParentQueue: Application removed - appId: application_1778475288188_0013 user: cty1576 leaf-queue of parent: root #applications: 0
2026-05-11 13:51:15,003 INFO org.apache.hadoop.yarn.server.resourcemanager.RMAppManager$ApplicationSummary: appId=application_1778475288188_0013,name=SELECT * FROM ads.heatmap_hour_dow ORDE...30 (Stage-1),user=cty1576,queue=default,state=FINISHED,trackingUrl=http://ubuntu:8088/proxy/application_1778475288188_0013/,appMasterHost=ubuntu,submitTime=1778478654489,startTime=1778478654489,launchTime=1778478655123,finishTime=1778478668608,finalStatus=SUCCEEDED,memorySeconds=48472,vcoreSeconds=26,preemptedMemorySeconds=0,preemptedVcoreSeconds=0,preemptedAMContainers=0,preemptedNonAMContainers=0,preemptedResources=<memory:0\, vCores:0>,applicationType=MAPREDUCE,resourceSeconds=48472 MB-seconds\, 26 vcore-seconds,preemptedResourceSeconds=0 MB-seconds\, 0 vcore-seconds,applicationTags=,applicationNodeLabel=,diagnostics=,totalAllocatedContainers=3
2026-05-11 13:51:15,003 INFO org.apache.hadoop.yarn.server.resourcemanager.amlauncher.AMLauncher: Cleaning master appattempt_1778475288188_0013_000001
2026-05-11 13:51:16,834 INFO org.apache.hadoop.yarn.server.resourcemanager.ClientRMService: Allocated new applicationId: 14
2026-05-11 13:51:17,855 INFO org.apache.hadoop.yarn.server.resourcemanager.scheduler.capacity.CapacityScheduler: Application 'application_1778475288188_0014' is submitted without priority hence considering default queue/cluster priority: 0
2026-05-11 13:51:17,855 INFO org.apache.hadoop.yarn.server.resourcemanager.scheduler.capacity.CapacityScheduler: Priority '0' is acceptable in queue : default for application: application_1778475288188_0014
2026-05-11 13:51:17,855 INFO org.apache.hadoop.yarn.server.resourcemanager.ClientRMService: Application with id 14 submitted by user cty1576
2026-05-11 13:51:17,856 INFO org.apache.hadoop.yarn.server.resourcemanager.rmapp.RMAppImpl: Storing application with id application_1778475288188_0014
2026-05-11 13:51:17,856 INFO org.apache.hadoop.yarn.server.resourcemanager.rmapp.RMAppImpl: application_1778475288188_0014 State change from NEW to NEW_SAVING on event = START
2026-05-11 13:51:17,856 INFO org.apache.hadoop.yarn.server.resourcemanager.recovery.RMStateStore: Storing info for app: application_1778475288188_0014
2026-05-11 13:51:17,856 INFO org.apache.hadoop.yarn.server.resourcemanager.rmapp.RMAppImpl: application_1778475288188_0014 State change from NEW_SAVING to SUBMITTED on event = APP_NEW_SAVED
2026-05-11 13:51:17,857 INFO org.apache.hadoop.yarn.server.resourcemanager.scheduler.capacity.ParentQueue: Application added - appId: application_1778475288188_0014 user: cty1576 leaf-queue of parent: root #applications: 1
2026-05-11 13:51:17,857 INFO org.apache.hadoop.yarn.server.resourcemanager.scheduler.capacity.CapacityScheduler: Accepted application application_1778475288188_0014 from user: cty1576, in queue: default
2026-05-11 13:51:17,858 INFO org.apache.hadoop.yarn.server.resourcemanager.rmapp.RMAppImpl: application_1778475288188_0014 State change from SUBMITTED to ACCEPTED on event = APP_ACCEPTED
2026-05-11 13:51:17,858 INFO org.apache.hadoop.yarn.server.resourcemanager.ApplicationMasterService: Registering app attempt : appattempt_1778475288188_0014_000001
2026-05-11 13:51:17,858 INFO org.apache.hadoop.yarn.server.resourcemanager.rmapp.attempt.RMAppAttemptImpl: appattempt_1778475288188_0014_000001 State change from NEW to SUBMITTED on event = START
2026-05-11 13:51:17,858 WARN org.apache.hadoop.yarn.server.resourcemanager.scheduler.capacity.LeafQueue: maximum-am-resource-percent is insufficient to start a single application in queue, it is likely set too low. skipping enforcement to allow at least one application to start
2026-05-11 13:51:17,858 WARN org.apache.hadoop.yarn.server.resourcemanager.scheduler.capacity.LeafQueue: maximum-am-resource-percent is insufficient to start a single application in queue for user, it is likely set too low. skipping enforcement to allow at least one application to start
2026-05-11 13:51:17,859 INFO org.apache.hadoop.yarn.server.resourcemanager.scheduler.capacity.LeafQueue: Application application_1778475288188_0014 from user: cty1576 activated in queue: root.default
2026-05-11 13:51:17,859 INFO org.apache.hadoop.yarn.server.resourcemanager.scheduler.capacity.LeafQueue: Application added - appId: application_1778475288188_0014 user: cty1576, leaf-queue: root.default #user-pending-applications: 0 #user-active-applications: 1 #queue-pending-applications: 0 #queue-active-applications: 1 #queue-nonrunnable-applications: 0
2026-05-11 13:51:17,859 INFO org.apache.hadoop.yarn.server.resourcemanager.scheduler.capacity.CapacityScheduler: Added Application Attempt appattempt_1778475288188_0014_000001 to scheduler from user cty1576 in queue root.default
2026-05-11 13:51:17,860 INFO org.apache.hadoop.yarn.server.resourcemanager.rmapp.attempt.RMAppAttemptImpl: appattempt_1778475288188_0014_000001 State change from SUBMITTED to SCHEDULED on event = ATTEMPT_ADDED
2026-05-11 13:51:18,005 INFO org.apache.hadoop.yarn.server.resourcemanager.scheduler.capacity.allocator.AbstractContainerAllocator: assignedContainer application attempt=appattempt_1778475288188_0014_000001 container=null queue=default clusterResource=<memory:8192, vCores:8> type=OFF_SWITCH requestedPartition=
2026-05-11 13:51:18,005 INFO org.apache.hadoop.yarn.server.resourcemanager.rmcontainer.RMContainerImpl: container_1778475288188_0014_01_000001 Container Transitioned from NEW to ALLOCATED
2026-05-11 13:51:18,006 INFO org.apache.hadoop.yarn.server.resourcemanager.scheduler.common.fica.FiCaSchedulerNode: Assigned container container_1778475288188_0014_01_000001 of capacity <memory:2048, vCores:1> on host ubuntu:45565, which has 1 containers, <memory:2048, vCores:1> used and <memory:6144, vCores:7> available after allocation
2026-05-11 13:51:18,006 INFO org.apache.hadoop.yarn.server.resourcemanager.scheduler.capacity.ParentQueue: assignedContainer queue=root usedCapacity=0.25 absoluteUsedCapacity=0.25 used=<memory:2048, vCores:1> cluster=<memory:8192, vCores:8>
2026-05-11 13:51:18,008 INFO org.apache.hadoop.yarn.server.resourcemanager.rmcontainer.RMContainerImpl: container_1778475288188_0014_01_000001 Container Transitioned from ALLOCATED to ACQUIRED
2026-05-11 13:51:18,008 INFO org.apache.hadoop.yarn.server.resourcemanager.security.NMTokenSecretManagerInRM: Clear node set for appattempt_1778475288188_0014_000001
2026-05-11 13:51:18,008 INFO org.apache.hadoop.yarn.server.resourcemanager.rmapp.attempt.RMAppAttemptImpl: Storing attempt: AppId: application_1778475288188_0014 AttemptId: appattempt_1778475288188_0014_000001 MasterContainer: Container: [ContainerId: container_1778475288188_0014_01_000001, AllocationRequestId: -1, Version: 0, NodeId: ubuntu:45565, NodeHttpAddress: ubuntu:8042, Resource: <memory:2048, vCores:1>, Priority: 0, Token: Token { kind: ContainerToken, service: 127.0.1.1:45565 }, ExecutionType: GUARANTEED, ]
2026-05-11 13:51:18,009 INFO org.apache.hadoop.yarn.server.resourcemanager.rmapp.attempt.RMAppAttemptImpl: appattempt_1778475288188_0014_000001 State change from SCHEDULED to ALLOCATED_SAVING on event = CONTAINER_ALLOCATED
2026-05-11 13:51:18,009 INFO org.apache.hadoop.yarn.server.resourcemanager.rmapp.attempt.RMAppAttemptImpl: appattempt_1778475288188_0014_000001 State change from ALLOCATED_SAVING to ALLOCATED on event = ATTEMPT_NEW_SAVED
2026-05-11 13:51:18,009 INFO org.apache.hadoop.yarn.server.resourcemanager.amlauncher.AMLauncher: Launching masterappattempt_1778475288188_0014_000001
2026-05-11 13:51:18,014 INFO org.apache.hadoop.yarn.server.resourcemanager.amlauncher.AMLauncher: Setting up container Container: [ContainerId: container_1778475288188_0014_01_000001, AllocationRequestId: -1, Version: 0, NodeId: ubuntu:45565, NodeHttpAddress: ubuntu:8042, Resource: <memory:2048, vCores:1>, Priority: 0, Token: Token { kind: ContainerToken, service: 127.0.1.1:45565 }, ExecutionType: GUARANTEED, ] for AM appattempt_1778475288188_0014_000001
2026-05-11 13:51:18,015 INFO org.apache.hadoop.yarn.server.resourcemanager.security.AMRMTokenSecretManager: Create AMRMToken for ApplicationAttempt: appattempt_1778475288188_0014_000001
2026-05-11 13:51:18,015 INFO org.apache.hadoop.yarn.server.resourcemanager.security.AMRMTokenSecretManager: Creating password for appattempt_1778475288188_0014_000001
2026-05-11 13:51:18,041 INFO org.apache.hadoop.yarn.server.resourcemanager.amlauncher.AMLauncher: Done launching container Container: [ContainerId: container_1778475288188_0014_01_000001, AllocationRequestId: -1, Version: 0, NodeId: ubuntu:45565, NodeHttpAddress: ubuntu:8042, Resource: <memory:2048, vCores:1>, Priority: 0, Token: Token { kind: ContainerToken, service: 127.0.1.1:45565 }, ExecutionType: GUARANTEED, ] for AM appattempt_1778475288188_0014_000001
2026-05-11 13:51:18,041 INFO org.apache.hadoop.yarn.server.resourcemanager.rmapp.attempt.RMAppAttemptImpl: appattempt_1778475288188_0014_000001 State change from ALLOCATED to LAUNCHED on event = LAUNCHED
2026-05-11 13:51:18,041 INFO org.apache.hadoop.yarn.server.resourcemanager.rmapp.RMAppImpl: update the launch time for applicationId: application_1778475288188_0014, attemptId: appattempt_1778475288188_0014_000001launchTime: 1778478678041
2026-05-11 13:51:18,041 INFO org.apache.hadoop.yarn.server.resourcemanager.recovery.RMStateStore: Updating info for app: application_1778475288188_0014
2026-05-11 13:51:19,006 INFO org.apache.hadoop.yarn.server.resourcemanager.rmcontainer.RMContainerImpl: container_1778475288188_0014_01_000001 Container Transitioned from ACQUIRED to RUNNING
2026-05-11 13:51:21,635 INFO SecurityLogger.org.apache.hadoop.ipc.Server: Auth successful for appattempt_1778475288188_0014_000001 (auth:SIMPLE) from 127.0.0.1:46116
2026-05-11 13:51:21,639 INFO org.apache.hadoop.yarn.server.resourcemanager.DefaultAMSProcessor: AM registration appattempt_1778475288188_0014_000001
2026-05-11 13:51:21,639 INFO org.apache.hadoop.yarn.server.resourcemanager.rmapp.attempt.RMAppAttemptImpl: appattempt_1778475288188_0014_000001 State change from LAUNCHED to RUNNING on event = REGISTERED
2026-05-11 13:51:21,639 INFO org.apache.hadoop.yarn.server.resourcemanager.rmapp.RMAppImpl: application_1778475288188_0014 State change from ACCEPTED to RUNNING on event = ATTEMPT_REGISTERED
2026-05-11 13:51:23,018 INFO org.apache.hadoop.yarn.server.resourcemanager.scheduler.capacity.allocator.AbstractContainerAllocator: assignedContainer application attempt=appattempt_1778475288188_0014_000001 container=null queue=default clusterResource=<memory:8192, vCores:8> type=NODE_LOCAL requestedPartition=
2026-05-11 13:51:23,020 INFO org.apache.hadoop.yarn.server.resourcemanager.rmcontainer.RMContainerImpl: container_1778475288188_0014_01_000002 Container Transitioned from NEW to ALLOCATED
2026-05-11 13:51:23,020 INFO org.apache.hadoop.yarn.server.resourcemanager.scheduler.common.fica.FiCaSchedulerNode: Assigned container container_1778475288188_0014_01_000002 of capacity <memory:1024, vCores:1> on host ubuntu:45565, which has 2 containers, <memory:3072, vCores:2> used and <memory:5120, vCores:6> available after allocation
2026-05-11 13:51:23,020 INFO org.apache.hadoop.yarn.server.resourcemanager.scheduler.capacity.ParentQueue: assignedContainer queue=root usedCapacity=0.375 absoluteUsedCapacity=0.375 used=<memory:3072, vCores:2> cluster=<memory:8192, vCores:8>
2026-05-11 13:51:23,686 INFO org.apache.hadoop.yarn.server.resourcemanager.rmcontainer.RMContainerImpl: container_1778475288188_0014_01_000002 Container Transitioned from ALLOCATED to ACQUIRED
2026-05-11 13:51:24,018 INFO org.apache.hadoop.yarn.server.resourcemanager.rmcontainer.RMContainerImpl: container_1778475288188_0014_01_000002 Container Transitioned from ACQUIRED to RUNNING
2026-05-11 13:51:24,704 INFO org.apache.hadoop.yarn.server.resourcemanager.scheduler.AppSchedulingInfo: checking for deactivate of application :application_1778475288188_0014
2026-05-11 13:51:26,722 INFO org.apache.hadoop.yarn.server.resourcemanager.rmcontainer.RMContainerImpl: container_1778475288188_0014_01_000002 Container Transitioned from RUNNING to COMPLETED
2026-05-11 13:51:27,728 INFO org.apache.hadoop.yarn.server.resourcemanager.scheduler.capacity.allocator.AbstractContainerAllocator: assignedContainer application attempt=appattempt_1778475288188_0014_000001 container=null queue=default clusterResource=<memory:8192, vCores:8> type=OFF_SWITCH requestedPartition=
2026-05-11 13:51:27,729 INFO org.apache.hadoop.yarn.server.resourcemanager.rmcontainer.RMContainerImpl: container_1778475288188_0014_01_000003 Container Transitioned from NEW to ALLOCATED
2026-05-11 13:51:27,729 INFO org.apache.hadoop.yarn.server.resourcemanager.scheduler.common.fica.FiCaSchedulerNode: Assigned container container_1778475288188_0014_01_000003 of capacity <memory:1024, vCores:1> on host ubuntu:45565, which has 2 containers, <memory:3072, vCores:2> used and <memory:5120, vCores:6> available after allocation
2026-05-11 13:51:27,729 INFO org.apache.hadoop.yarn.server.resourcemanager.scheduler.capacity.ParentQueue: assignedContainer queue=root usedCapacity=0.375 absoluteUsedCapacity=0.375 used=<memory:3072, vCores:2> cluster=<memory:8192, vCores:8>
2026-05-11 13:51:28,731 INFO org.apache.hadoop.yarn.server.resourcemanager.rmcontainer.RMContainerImpl: container_1778475288188_0014_01_000003 Container Transitioned from ALLOCATED to ACQUIRED
2026-05-11 13:51:29,731 INFO org.apache.hadoop.yarn.server.resourcemanager.rmcontainer.RMContainerImpl: container_1778475288188_0014_01_000003 Container Transitioned from ACQUIRED to RUNNING
2026-05-11 13:51:29,738 INFO org.apache.hadoop.yarn.server.resourcemanager.scheduler.AppSchedulingInfo: checking for deactivate of application :application_1778475288188_0014
2026-05-11 13:51:31,237 INFO org.apache.hadoop.yarn.server.resourcemanager.rmapp.attempt.RMAppAttemptImpl: Updating application attempt appattempt_1778475288188_0014_000001 with final state: FINISHING, and exit status: -1000
2026-05-11 13:51:31,237 INFO org.apache.hadoop.yarn.server.resourcemanager.rmapp.attempt.RMAppAttemptImpl: appattempt_1778475288188_0014_000001 State change from RUNNING to FINAL_SAVING on event = UNREGISTERED
2026-05-11 13:51:31,237 INFO org.apache.hadoop.yarn.server.resourcemanager.rmapp.RMAppImpl: Updating application application_1778475288188_0014 with final state: FINISHING
2026-05-11 13:51:31,238 INFO org.apache.hadoop.yarn.server.resourcemanager.recovery.RMStateStore: Updating info for app: application_1778475288188_0014
2026-05-11 13:51:31,238 INFO org.apache.hadoop.yarn.server.resourcemanager.rmapp.RMAppImpl: application_1778475288188_0014 State change from RUNNING to FINAL_SAVING on event = ATTEMPT_UNREGISTERED
2026-05-11 13:51:31,238 INFO org.apache.hadoop.yarn.server.resourcemanager.rmapp.attempt.RMAppAttemptImpl: appattempt_1778475288188_0014_000001 State change from FINAL_SAVING to FINISHING on event = ATTEMPT_UPDATE_SAVED
2026-05-11 13:51:31,238 INFO org.apache.hadoop.yarn.server.resourcemanager.rmapp.RMAppImpl: application_1778475288188_0014 State change from FINAL_SAVING to FINISHING on event = APP_UPDATE_SAVED
2026-05-11 13:51:31,244 INFO org.apache.hadoop.yarn.server.resourcemanager.rmcontainer.RMContainerImpl: container_1778475288188_0014_01_000003 Container Transitioned from RUNNING to COMPLETED
2026-05-11 13:51:32,240 INFO org.apache.hadoop.yarn.server.resourcemanager.ApplicationMasterService: application_1778475288188_0014 unregistered successfully. 
2026-05-11 13:51:37,657 INFO org.apache.hadoop.yarn.server.resourcemanager.rmcontainer.RMContainerImpl: container_1778475288188_0014_01_000001 Container Transitioned from RUNNING to COMPLETED
2026-05-11 13:51:37,657 INFO org.apache.hadoop.yarn.server.resourcemanager.ApplicationMasterService: Unregistering app attempt : appattempt_1778475288188_0014_000001
2026-05-11 13:51:37,657 INFO org.apache.hadoop.yarn.server.resourcemanager.security.AMRMTokenSecretManager: Application finished, removing password for appattempt_1778475288188_0014_000001
2026-05-11 13:51:37,657 INFO org.apache.hadoop.yarn.server.resourcemanager.rmapp.attempt.RMAppAttemptImpl: appattempt_1778475288188_0014_000001 State change from FINISHING to FINISHED on event = CONTAINER_FINISHED
2026-05-11 13:51:37,658 INFO org.apache.hadoop.yarn.server.resourcemanager.rmapp.RMAppImpl: application_1778475288188_0014 State change from FINISHING to FINISHED on event = ATTEMPT_FINISHED
2026-05-11 13:51:37,659 INFO org.apache.hadoop.yarn.server.resourcemanager.RMAppManager$ApplicationSummary: appId=application_1778475288188_0014,name=SELECT * FROM ads.repurchase_...bucket_order (Stage-1),user=cty1576,queue=default,state=FINISHED,trackingUrl=http://ubuntu:8088/proxy/application_1778475288188_0014/,appMasterHost=ubuntu,submitTime=1778478677853,startTime=1778478677855,launchTime=1778478678041,finishTime=1778478691237,finalStatus=SUCCEEDED,memorySeconds=47641,vcoreSeconds=25,preemptedMemorySeconds=0,preemptedVcoreSeconds=0,preemptedAMContainers=0,preemptedNonAMContainers=0,preemptedResources=<memory:0\, vCores:0>,applicationType=MAPREDUCE,resourceSeconds=47641 MB-seconds\, 25 vcore-seconds,preemptedResourceSeconds=0 MB-seconds\, 0 vcore-seconds,applicationTags=,applicationNodeLabel=,diagnostics=,totalAllocatedContainers=3
2026-05-11 13:51:37,659 INFO org.apache.hadoop.yarn.server.resourcemanager.scheduler.capacity.CapacityScheduler: Application Attempt appattempt_1778475288188_0014_000001 is done. finalState=FINISHED
2026-05-11 13:51:37,659 INFO org.apache.hadoop.yarn.server.resourcemanager.scheduler.AppSchedulingInfo: Application application_1778475288188_0014 requests cleared
2026-05-11 13:51:37,659 INFO org.apache.hadoop.yarn.server.resourcemanager.scheduler.capacity.LeafQueue: Application removed - appId: application_1778475288188_0014 user: cty1576 queue: root.default #user-pending-applications: 0 #user-active-applications: 0 #queue-pending-applications: 0 #queue-active-applications: 0
2026-05-11 13:51:37,659 INFO org.apache.hadoop.yarn.server.resourcemanager.scheduler.capacity.ParentQueue: Application removed - appId: application_1778475288188_0014 user: cty1576 leaf-queue of parent: root #applications: 0
2026-05-11 13:51:37,660 INFO org.apache.hadoop.yarn.server.resourcemanager.amlauncher.AMLauncher: Cleaning master appattempt_1778475288188_0014_000001
2026-05-11 13:51:39,170 INFO org.apache.hadoop.yarn.server.resourcemanager.ClientRMService: Allocated new applicationId: 15
2026-05-11 13:51:40,377 INFO org.apache.hadoop.yarn.server.resourcemanager.scheduler.capacity.CapacityScheduler: Application 'application_1778475288188_0015' is submitted without priority hence considering default queue/cluster priority: 0
2026-05-11 13:51:40,377 INFO org.apache.hadoop.yarn.server.resourcemanager.scheduler.capacity.CapacityScheduler: Priority '0' is acceptable in queue : default for application: application_1778475288188_0015
2026-05-11 13:51:40,377 INFO org.apache.hadoop.yarn.server.resourcemanager.ClientRMService: Application with id 15 submitted by user cty1576
2026-05-11 13:51:40,378 INFO org.apache.hadoop.yarn.server.resourcemanager.rmapp.RMAppImpl: Storing application with id application_1778475288188_0015
2026-05-11 13:51:40,378 INFO org.apache.hadoop.yarn.server.resourcemanager.rmapp.RMAppImpl: application_1778475288188_0015 State change from NEW to NEW_SAVING on event = START
2026-05-11 13:51:40,378 INFO org.apache.hadoop.yarn.server.resourcemanager.recovery.RMStateStore: Storing info for app: application_1778475288188_0015
2026-05-11 13:51:40,378 INFO org.apache.hadoop.yarn.server.resourcemanager.rmapp.RMAppImpl: application_1778475288188_0015 State change from NEW_SAVING to SUBMITTED on event = APP_NEW_SAVED
2026-05-11 13:51:40,378 INFO org.apache.hadoop.yarn.server.resourcemanager.scheduler.capacity.ParentQueue: Application added - appId: application_1778475288188_0015 user: cty1576 leaf-queue of parent: root #applications: 1
2026-05-11 13:51:40,379 INFO org.apache.hadoop.yarn.server.resourcemanager.scheduler.capacity.CapacityScheduler: Accepted application application_1778475288188_0015 from user: cty1576, in queue: default
2026-05-11 13:51:40,381 INFO org.apache.hadoop.yarn.server.resourcemanager.rmapp.RMAppImpl: application_1778475288188_0015 State change from SUBMITTED to ACCEPTED on event = APP_ACCEPTED
2026-05-11 13:51:40,381 INFO org.apache.hadoop.yarn.server.resourcemanager.ApplicationMasterService: Registering app attempt : appattempt_1778475288188_0015_000001
2026-05-11 13:51:40,381 INFO org.apache.hadoop.yarn.server.resourcemanager.rmapp.attempt.RMAppAttemptImpl: appattempt_1778475288188_0015_000001 State change from NEW to SUBMITTED on event = START
2026-05-11 13:51:40,383 WARN org.apache.hadoop.yarn.server.resourcemanager.scheduler.capacity.LeafQueue: maximum-am-resource-percent is insufficient to start a single application in queue, it is likely set too low. skipping enforcement to allow at least one application to start
2026-05-11 13:51:40,384 WARN org.apache.hadoop.yarn.server.resourcemanager.scheduler.capacity.LeafQueue: maximum-am-resource-percent is insufficient to start a single application in queue for user, it is likely set too low. skipping enforcement to allow at least one application to start
2026-05-11 13:51:40,384 INFO org.apache.hadoop.yarn.server.resourcemanager.scheduler.capacity.LeafQueue: Application application_1778475288188_0015 from user: cty1576 activated in queue: root.default
2026-05-11 13:51:40,384 INFO org.apache.hadoop.yarn.server.resourcemanager.scheduler.capacity.LeafQueue: Application added - appId: application_1778475288188_0015 user: cty1576, leaf-queue: root.default #user-pending-applications: 0 #user-active-applications: 1 #queue-pending-applications: 0 #queue-active-applications: 1 #queue-nonrunnable-applications: 0
2026-05-11 13:51:40,384 INFO org.apache.hadoop.yarn.server.resourcemanager.scheduler.capacity.CapacityScheduler: Added Application Attempt appattempt_1778475288188_0015_000001 to scheduler from user cty1576 in queue root.default
2026-05-11 13:51:40,385 INFO org.apache.hadoop.yarn.server.resourcemanager.rmapp.attempt.RMAppAttemptImpl: appattempt_1778475288188_0015_000001 State change from SUBMITTED to SCHEDULED on event = ATTEMPT_ADDED
2026-05-11 13:51:40,671 INFO org.apache.hadoop.yarn.server.resourcemanager.scheduler.capacity.allocator.AbstractContainerAllocator: assignedContainer application attempt=appattempt_1778475288188_0015_000001 container=null queue=default clusterResource=<memory:8192, vCores:8> type=OFF_SWITCH requestedPartition=
2026-05-11 13:51:40,672 INFO org.apache.hadoop.yarn.server.resourcemanager.rmcontainer.RMContainerImpl: container_1778475288188_0015_01_000001 Container Transitioned from NEW to ALLOCATED
2026-05-11 13:51:40,672 INFO org.apache.hadoop.yarn.server.resourcemanager.scheduler.common.fica.FiCaSchedulerNode: Assigned container container_1778475288188_0015_01_000001 of capacity <memory:2048, vCores:1> on host ubuntu:45565, which has 1 containers, <memory:2048, vCores:1> used and <memory:6144, vCores:7> available after allocation
2026-05-11 13:51:40,674 INFO org.apache.hadoop.yarn.server.resourcemanager.scheduler.capacity.ParentQueue: assignedContainer queue=root usedCapacity=0.25 absoluteUsedCapacity=0.25 used=<memory:2048, vCores:1> cluster=<memory:8192, vCores:8>
2026-05-11 13:51:40,675 INFO org.apache.hadoop.yarn.server.resourcemanager.rmcontainer.RMContainerImpl: container_1778475288188_0015_01_000001 Container Transitioned from ALLOCATED to ACQUIRED
2026-05-11 13:51:40,675 INFO org.apache.hadoop.yarn.server.resourcemanager.security.NMTokenSecretManagerInRM: Clear node set for appattempt_1778475288188_0015_000001
2026-05-11 13:51:40,675 INFO org.apache.hadoop.yarn.server.resourcemanager.rmapp.attempt.RMAppAttemptImpl: Storing attempt: AppId: application_1778475288188_0015 AttemptId: appattempt_1778475288188_0015_000001 MasterContainer: Container: [ContainerId: container_1778475288188_0015_01_000001, AllocationRequestId: -1, Version: 0, NodeId: ubuntu:45565, NodeHttpAddress: ubuntu:8042, Resource: <memory:2048, vCores:1>, Priority: 0, Token: Token { kind: ContainerToken, service: 127.0.1.1:45565 }, ExecutionType: GUARANTEED, ]
2026-05-11 13:51:40,676 INFO org.apache.hadoop.yarn.server.resourcemanager.rmapp.attempt.RMAppAttemptImpl: appattempt_1778475288188_0015_000001 State change from SCHEDULED to ALLOCATED_SAVING on event = CONTAINER_ALLOCATED
2026-05-11 13:51:40,676 INFO org.apache.hadoop.yarn.server.resourcemanager.rmapp.attempt.RMAppAttemptImpl: appattempt_1778475288188_0015_000001 State change from ALLOCATED_SAVING to ALLOCATED on event = ATTEMPT_NEW_SAVED
2026-05-11 13:51:40,677 INFO org.apache.hadoop.yarn.server.resourcemanager.amlauncher.AMLauncher: Launching masterappattempt_1778475288188_0015_000001
2026-05-11 13:51:40,685 INFO org.apache.hadoop.yarn.server.resourcemanager.amlauncher.AMLauncher: Setting up container Container: [ContainerId: container_1778475288188_0015_01_000001, AllocationRequestId: -1, Version: 0, NodeId: ubuntu:45565, NodeHttpAddress: ubuntu:8042, Resource: <memory:2048, vCores:1>, Priority: 0, Token: Token { kind: ContainerToken, service: 127.0.1.1:45565 }, ExecutionType: GUARANTEED, ] for AM appattempt_1778475288188_0015_000001
2026-05-11 13:51:40,685 INFO org.apache.hadoop.yarn.server.resourcemanager.security.AMRMTokenSecretManager: Create AMRMToken for ApplicationAttempt: appattempt_1778475288188_0015_000001
2026-05-11 13:51:40,685 INFO org.apache.hadoop.yarn.server.resourcemanager.security.AMRMTokenSecretManager: Creating password for appattempt_1778475288188_0015_000001
2026-05-11 13:51:40,705 INFO org.apache.hadoop.yarn.server.resourcemanager.amlauncher.AMLauncher: Done launching container Container: [ContainerId: container_1778475288188_0015_01_000001, AllocationRequestId: -1, Version: 0, NodeId: ubuntu:45565, NodeHttpAddress: ubuntu:8042, Resource: <memory:2048, vCores:1>, Priority: 0, Token: Token { kind: ContainerToken, service: 127.0.1.1:45565 }, ExecutionType: GUARANTEED, ] for AM appattempt_1778475288188_0015_000001
2026-05-11 13:51:40,706 INFO org.apache.hadoop.yarn.server.resourcemanager.rmapp.attempt.RMAppAttemptImpl: appattempt_1778475288188_0015_000001 State change from ALLOCATED to LAUNCHED on event = LAUNCHED
2026-05-11 13:51:40,706 INFO org.apache.hadoop.yarn.server.resourcemanager.rmapp.RMAppImpl: update the launch time for applicationId: application_1778475288188_0015, attemptId: appattempt_1778475288188_0015_000001launchTime: 1778478700706
2026-05-11 13:51:40,706 INFO org.apache.hadoop.yarn.server.resourcemanager.recovery.RMStateStore: Updating info for app: application_1778475288188_0015
2026-05-11 13:51:41,674 INFO org.apache.hadoop.yarn.server.resourcemanager.rmcontainer.RMContainerImpl: container_1778475288188_0015_01_000001 Container Transitioned from ACQUIRED to RUNNING
2026-05-11 13:51:44,977 INFO SecurityLogger.org.apache.hadoop.ipc.Server: Auth successful for appattempt_1778475288188_0015_000001 (auth:SIMPLE) from 127.0.0.1:56768
2026-05-11 13:51:44,979 INFO org.apache.hadoop.yarn.server.resourcemanager.DefaultAMSProcessor: AM registration appattempt_1778475288188_0015_000001
2026-05-11 13:51:44,980 INFO org.apache.hadoop.yarn.server.resourcemanager.rmapp.attempt.RMAppAttemptImpl: appattempt_1778475288188_0015_000001 State change from LAUNCHED to RUNNING on event = REGISTERED
2026-05-11 13:51:44,980 INFO org.apache.hadoop.yarn.server.resourcemanager.rmapp.RMAppImpl: application_1778475288188_0015 State change from ACCEPTED to RUNNING on event = ATTEMPT_REGISTERED
2026-05-11 13:51:46,689 INFO org.apache.hadoop.yarn.server.resourcemanager.scheduler.capacity.allocator.AbstractContainerAllocator: assignedContainer application attempt=appattempt_1778475288188_0015_000001 container=null queue=default clusterResource=<memory:8192, vCores:8> type=NODE_LOCAL requestedPartition=
2026-05-11 13:51:46,690 INFO org.apache.hadoop.yarn.server.resourcemanager.rmcontainer.RMContainerImpl: container_1778475288188_0015_01_000002 Container Transitioned from NEW to ALLOCATED
2026-05-11 13:51:46,690 INFO org.apache.hadoop.yarn.server.resourcemanager.scheduler.common.fica.FiCaSchedulerNode: Assigned container container_1778475288188_0015_01_000002 of capacity <memory:1024, vCores:1> on host ubuntu:45565, which has 2 containers, <memory:3072, vCores:2> used and <memory:5120, vCores:6> available after allocation
2026-05-11 13:51:46,690 INFO org.apache.hadoop.yarn.server.resourcemanager.scheduler.capacity.ParentQueue: assignedContainer queue=root usedCapacity=0.375 absoluteUsedCapacity=0.375 used=<memory:3072, vCores:2> cluster=<memory:8192, vCores:8>
2026-05-11 13:51:47,091 INFO org.apache.hadoop.yarn.server.resourcemanager.rmcontainer.RMContainerImpl: container_1778475288188_0015_01_000002 Container Transitioned from ALLOCATED to ACQUIRED
2026-05-11 13:51:47,690 INFO org.apache.hadoop.yarn.server.resourcemanager.rmcontainer.RMContainerImpl: container_1778475288188_0015_01_000002 Container Transitioned from ACQUIRED to RUNNING
2026-05-11 13:51:48,103 INFO org.apache.hadoop.yarn.server.resourcemanager.scheduler.AppSchedulingInfo: checking for deactivate of application :application_1778475288188_0015
2026-05-11 13:51:50,536 INFO org.apache.hadoop.yarn.server.resourcemanager.rmcontainer.RMContainerImpl: container_1778475288188_0015_01_000002 Container Transitioned from RUNNING to COMPLETED
2026-05-11 13:51:52,542 INFO org.apache.hadoop.yarn.server.resourcemanager.scheduler.capacity.allocator.AbstractContainerAllocator: assignedContainer application attempt=appattempt_1778475288188_0015_000001 container=null queue=default clusterResource=<memory:8192, vCores:8> type=OFF_SWITCH requestedPartition=
2026-05-11 13:51:52,543 INFO org.apache.hadoop.yarn.server.resourcemanager.rmcontainer.RMContainerImpl: container_1778475288188_0015_01_000003 Container Transitioned from NEW to ALLOCATED
2026-05-11 13:51:52,543 INFO org.apache.hadoop.yarn.server.resourcemanager.scheduler.common.fica.FiCaSchedulerNode: Assigned container container_1778475288188_0015_01_000003 of capacity <memory:1024, vCores:1> on host ubuntu:45565, which has 2 containers, <memory:3072, vCores:2> used and <memory:5120, vCores:6> available after allocation
2026-05-11 13:51:52,544 INFO org.apache.hadoop.yarn.server.resourcemanager.scheduler.capacity.ParentQueue: assignedContainer queue=root usedCapacity=0.375 absoluteUsedCapacity=0.375 used=<memory:3072, vCores:2> cluster=<memory:8192, vCores:8>
2026-05-11 13:51:53,158 INFO org.apache.hadoop.yarn.server.resourcemanager.rmcontainer.RMContainerImpl: container_1778475288188_0015_01_000003 Container Transitioned from ALLOCATED to ACQUIRED
2026-05-11 13:51:53,546 INFO org.apache.hadoop.yarn.server.resourcemanager.rmcontainer.RMContainerImpl: container_1778475288188_0015_01_000003 Container Transitioned from ACQUIRED to RUNNING
2026-05-11 13:51:54,162 INFO org.apache.hadoop.yarn.server.resourcemanager.scheduler.AppSchedulingInfo: checking for deactivate of application :application_1778475288188_0015
2026-05-11 13:51:56,045 INFO org.apache.hadoop.yarn.server.resourcemanager.rmapp.attempt.RMAppAttemptImpl: Updating application attempt appattempt_1778475288188_0015_000001 with final state: FINISHING, and exit status: -1000
2026-05-11 13:51:56,046 INFO org.apache.hadoop.yarn.server.resourcemanager.rmapp.attempt.RMAppAttemptImpl: appattempt_1778475288188_0015_000001 State change from RUNNING to FINAL_SAVING on event = UNREGISTERED
2026-05-11 13:51:56,046 INFO org.apache.hadoop.yarn.server.resourcemanager.rmapp.RMAppImpl: Updating application application_1778475288188_0015 with final state: FINISHING
2026-05-11 13:51:56,046 INFO org.apache.hadoop.yarn.server.resourcemanager.recovery.RMStateStore: Updating info for app: application_1778475288188_0015
2026-05-11 13:51:56,047 INFO org.apache.hadoop.yarn.server.resourcemanager.rmapp.RMAppImpl: application_1778475288188_0015 State change from RUNNING to FINAL_SAVING on event = ATTEMPT_UNREGISTERED
2026-05-11 13:51:56,047 INFO org.apache.hadoop.yarn.server.resourcemanager.rmapp.attempt.RMAppAttemptImpl: appattempt_1778475288188_0015_000001 State change from FINAL_SAVING to FINISHING on event = ATTEMPT_UPDATE_SAVED
2026-05-11 13:51:56,047 INFO org.apache.hadoop.yarn.server.resourcemanager.rmapp.RMAppImpl: application_1778475288188_0015 State change from FINAL_SAVING to FINISHING on event = APP_UPDATE_SAVED
2026-05-11 13:51:56,060 INFO org.apache.hadoop.yarn.server.resourcemanager.rmcontainer.RMContainerImpl: container_1778475288188_0015_01_000003 Container Transitioned from RUNNING to COMPLETED
2026-05-11 13:51:57,058 INFO org.apache.hadoop.yarn.server.resourcemanager.ApplicationMasterService: application_1778475288188_0015 unregistered successfully. 
